Workbook

Sheet Executive_Summary
A1: DAEWOO × SHOOTORDER — Deep Performance Analysis | MTD 1–28 Oct 2026
A2: Auto-generated from your daily Campaign Performance Report. Figures in INR. Every rate in the detail tabs is a live formula.
A4: MTD spend | B4: CRM leads | C4: CPL | D4: Qualified leads | E4: Qualified % | F4: CPQL | G4: Meetings (mapped) | H4: Lead→Meeting % | I4: Cost per Meeting
A5: =Funnel_Campaign!C12 -> 1215764.3 | B5: =Funnel_Campaign!G12 -> 1693 | C5: =Funnel_Campaign!J12 -> 718.11239 | D5: =Funnel_Campaign!H12 -> 417 | E5: =Funnel_Campaign!K12 -> 0.24630833 | F5: =Funnel_Campaign!L12 -> 2915.5018 | G5: =Funnel_Campaign!I12 -> 92 | H5: =Funnel_Campaign!M12 -> 0.054341406 | I5: =Funnel_Campaign!O12 -> 13214.829
A7: THE FUNNEL IN ONE LINE
A8: ₹1,215,764 spend → 1,693 CRM leads (CPL ₹718) → 417 qualified (24.6%, CPQL ₹2,916) → 92 meetings (5.4% of leads) → ₹13,215 per meeting. Won/revenue is not in the data, so ROAS cannot be measured.
A10: KEY FINDINGS
A11: 1 | B11: CPL is the wrong yardstick — cost per meeting is the real one.
B12: 'META_CustomData_MOFU_STOCKIST_Leadgen' costs ₹996 per lead vs ₹557 for 'Andromeda_CBO_Signature Store_FICO_Daewoo_SO', but qualifies 37.1% vs 20.1% and converts 32.5% of qualified leads to meetings vs 12.8%. Cost per meeting: ₹8,262 vs ₹21,705.
A13: 2 | B13: Spend and results are mismatched.
B14: 'Andromeda_CBO_Signature Store_FICO_Daewoo_SO' takes 55.3% of spend and delivers 33.7% of meetings. 'META_CustomData_MOFU_STOCKIST_Leadgen' takes 27.9% of spend and delivers 44.6% of meetings.
A15: 3 | B15: Lead quality fell across the month (mature leads only).
B16: Qualified %: 1–6 Oct: 36.1% → 7–12 Oct: 33.1% → 13–18 Oct: 27.7% → 19–25 Oct: 22.1%. Unreachable share moved from 27.7% to 52.9%. Daily lead volume averaged 33/day in the first week vs 97/day in the last mature week.
A17: 4 | B17: Best-performing ad(s) to scale.
B18: 'Stockist_Reel' in 'LAL_1%_Client Data_Stockist': 23 meetings at ₹8,323 each on ₹191,426 spend. Account average across ads is ₹14,826 per meeting.
A19: 5 | B19: Largest drag among ads.
B20: 'Signature_Store_160_Glass_SO' in 'HHI Pan India With Exclusions Signature Stores_FICO': ₹230,022 spent for 10 meeting(s) (₹23,002 each); 3 ad(s) are flagged REDUCE / fix on Funnel_Ad.
A21: 6 | B21: Contactability is a leak.
B22: 38.2% of leads are DNP / not reachable / invalid and 8.3% are junk, so 46.4% never become a real conversation; 16.6% are still open.
A23: 7 | B23: Don't judge the last 2 days (12.0% qualified) yet.
B24: 75.0% of leads from the last 2 days are still unworked in the CRM. Judge a cohort after ~3 days.
A25: 8 | B25: Budget pacing: Andromeda_CBO_Signature Store_FICO_Daewoo_SO.
B26: Averaging ₹24,031/day vs ₹45,289 daily budget (53.1%). Under-delivering — raised recently or limited by audience/bid; confirm with a daily export.
A27: 9 | B27: Zero-spend campaigns still delivered meetings.
B28: 10 of 92 meetings (10.9%) came from campaigns with no spend this month — older leads converting, so cost per meeting is lagged and blended.
A30: TOP ACTIONS (full list in Action_Plan)
A31: 1 | B31: Scale 'Stockist_Reel' in 'LAL_1%_Client Data_Stockist' by ~20% every 3 days; clone the creative into other ad sets.
A32: 2 | B32: Pause or replace 'Signature_Store_160_Glass_SO' in 'HHI Pan India With Exclusions Signature Stores_FICO'; reallocate its budget to the scale list.
A33: 3 | B33: Pause or replace 'Signature Store_SO' in 'HHI Pan India With Exclusions Signature Stores_FICO'; reallocate its budget to the scale list.
A34: 4 | B34: Pause or replace 'Signature_Store_OCT_SO' in 'LAL_1%_Client Data_Signature Store FICO'; reallocate its budget to the scale list.
A35: 5 | B35: Speed-to-lead SLA: first call within 15 min in working hours, 3 attempts across day-parts, WhatsApp follow-up on DNP.
A36: 6 | B36: Add 1–2 qualifying questions to the instant form on the campaigns with the highest junk / unreachable share.

Sheet Funnel_Campaign
A1: Campaign-wise full-funnel scorecard — MTD 1–28 Oct 2026
A2: Spend/reach/clicks from Meta; leads, qualified, meetings from CRM via LeadChain. All rates are live formulas.
A4: Campaign | B4: Delivery | C4: Spend (₹) | D4: Impressions | E4: Reach | F4: Link clicks | G4: CRM leads | H4: Qualified | I4: Meetings | J4: CPL (₹ per CRM lead) | K4: Qualified % | L4: CPQL (₹) | M4: Lead→Meeting % | N4: Qualified→Meeting % | O4: Cost per Meeting (₹) | P4: CTR | Q4: CPC (₹) | R4: CPM (₹) | S4: Frequency | T4: % of spend | U4: % of meetings | V4: Efficiency index (acct cost/mtg ÷ row)
A5: Andromeda_CBO_Signature Store_FICO_Daewoo_SO | B5: active | C5: 672858.87 | D5: 4576967 | E5: 1850403 | F5: 22823 | G5: 1208 | H5: 243 | I5: 31 | J5: =IFERROR(C5/G5,"n/a") -> 557.00238 | K5: =IFERROR(H5/G5,"n/a") -> 0.20115894 | L5: =IFERROR(C5/H5,"n/a") -> 2768.9665 | M5: =IFERROR(I5/G5,"n/a") -> 0.025662252 | N5: =IFERROR(I5/H5,"n/a") -> 0.12757202 | O5: =IF(AND(I5>0,C5>0),C5/I5,"n/a") -> 21705.125 | P5: =IFERROR(F5/D5,"n/a") -> 0.00498649 | Q5: =IFERROR(C5/F5,"n/a") -> 29.481614 | R5: =IFERROR(C5/D5*1000,"n/a") -> 147.00977 | S5: =IF(E5="","n/a",IFERROR(D5/E5,"n/a")) -> 2.4734974 | T5: =IFERROR(C5/$C$12,"n/a") -> 0.55344518 | U5: =IFERROR(I5/$I$12,"n/a") -> 0.33695652 | V5: =IFERROR(IF(AND(I5>0,C5>0),($O$12)/(C5/I5),"n/a"),"n/a") -> 0.60883451
A6: META_CustomData_MOFU_STOCKIST_Leadgen | B6: active | C6: 338747.09 | D6: 862709 | E6: 367607 | F6: 5066 | G6: 340 | H6: 126 | I6: 41 | J6: =IFERROR(C6/G6,"n/a") -> 996.31497 | K6: =IFERROR(H6/G6,"n/a") -> 0.37058824 | L6: =IFERROR(C6/H6,"n/a") -> 2688.469 | M6: =IFERROR(I6/G6,"n/a") -> 0.12058824 | N6: =IFERROR(I6/H6,"n/a") -> 0.32539683 | O6: =IF(AND(I6>0,C6>0),C6/I6,"n/a") -> 8262.1241 | P6: =IFERROR(F6/D6,"n/a") -> 0.0058722002 | Q6: =IFERROR(C6/F6,"n/a") -> 66.866777 | R6: =IFERROR(C6/D6*1000,"n/a") -> 392.6551 | S6: =IF(E6="","n/a",IFERROR(D6/E6,"n/a")) -> 2.3468242 | T6: =IFERROR(C6/$C$12,"n/a") -> 0.27862892 | U6: =IFERROR(I6/$I$12,"n/a") -> 0.44565217 | V6: =IFERROR(IF(AND(I6>0,C6>0),($O$12)/(C6/I6),"n/a"),"n/a") -> 1.5994469
A7: META_CustomData_MOFU_Leadgen – Signature FICO | B7: active | C7: 194123.34 | D7: 390794 | E7: 221625 | F7: 2781 | G7: 139 | H7: 46 | I7: 9 | J7: =IFERROR(C7/G7,"n/a") -> 1396.5708 | K7: =IFERROR(H7/G7,"n/a") -> 0.33093525 | L7: =IFERROR(C7/H7,"n/a") -> 4220.0726 | M7: =IFERROR(I7/G7,"n/a") -> 0.064748201 | N7: =IFERROR(I7/H7,"n/a") -> 0.19565217 | O7: =IF(AND(I7>0,C7>0),C7/I7,"n/a") -> 21569.26 | P7: =IFERROR(F7/D7,"n/a") -> 0.0071162812 | Q7: =IFERROR(C7/F7,"n/a") -> 69.80343 | R7: =IFERROR(C7/D7*1000,"n/a") -> 496.74084 | S7: =IF(E7="","n/a",IFERROR(D7/E7,"n/a")) -> 1.7633119 | T7: =IFERROR(C7/$C$12,"n/a") -> 0.15967186 | U7: =IFERROR(I7/$I$12,"n/a") -> 0.097826087 | V7: =IFERROR(IF(AND(I7>0,C7>0),($O$12)/(C7/I7),"n/a"),"n/a") -> 0.61266956
A8: META_RMKT_Engage_ABO_SO | B8: active | C8: 7213.35 | D8: 19452 | E8: 2134 | F8: 84 | G8: 0 | H8: 0 | I8: 0 | J8: =IFERROR(C8/G8,"n/a") -> n/a | K8: =IFERROR(H8/G8,"n/a") -> n/a | L8: =IFERROR(C8/H8,"n/a") -> n/a | M8: =IFERROR(I8/G8,"n/a") -> n/a | N8: =IFERROR(I8/H8,"n/a") -> n/a | O8: =IF(AND(I8>0,C8>0),C8/I8,"n/a") -> n/a | P8: =IFERROR(F8/D8,"n/a") -> 0.004318322 | Q8: =IFERROR(C8/F8,"n/a") -> 85.873214 | R8: =IFERROR(C8/D8*1000,"n/a") -> 370.82819 | S8: =IF(E8="","n/a",IFERROR(D8/E8,"n/a")) -> 9.1152765 | T8: =IFERROR(C8/$C$12,"n/a") -> 0.0059331814 | U8: =IFERROR(I8/$I$12,"n/a") -> 0 | V8: =IFERROR(IF(AND(I8>0,C8>0),($O$12)/(C8/I8),"n/a"),"n/a") -> n/a
A9: META_RMKT_Socials Pages_CBO_SO | B9: active | C9: 2821.62 | D9: 10131 | E9: 4306 | F9: 116 | G9: 6 | H9: 2 | I9: 1 | J9: =IFERROR(C9/G9,"n/a") -> 470.27 | K9: =IFERROR(H9/G9,"n/a") -> 0.33333333 | L9: =IFERROR(C9/H9,"n/a") -> 1410.81 | M9: =IFERROR(I9/G9,"n/a") -> 0.16666667 | N9: =IFERROR(I9/H9,"n/a") -> 0.5 | O9: =IF(AND(I9>0,C9>0),C9/I9,"n/a") -> 2821.62 | P9: =IFERROR(F9/D9,"n/a") -> 0.011450005 | Q9: =IFERROR(C9/F9,"n/a") -> 24.32431 | R9: =IFERROR(C9/D9*1000,"n/a") -> 278.51347 | S9: =IF(E9="","n/a",IFERROR(D9/E9,"n/a")) -> 2.3527636 | T9: =IFERROR(C9/$C$12,"n/a") -> 0.0023208611 | U9: =IFERROR(I9/$I$12,"n/a") -> 0.010869565 | V9: =IFERROR(IF(AND(I9>0,C9>0),($O$12)/(C9/I9),"n/a"),"n/a") -> 4.6834191
A10: Andromeda_ABO_Stockist_Daewoo_SO | B10: inactive | C10: 0 | D10: 0 | E10: 0 | F10: 0 | G10: 0 | H10: 0 | I10: 1 | J10: =IFERROR(C10/G10,"n/a") -> n/a | K10: =IFERROR(H10/G10,"n/a") -> n/a | L10: =IFERROR(C10/H10,"n/a") -> n/a | M10: =IFERROR(I10/G10,"n/a") -> n/a | N10: =IFERROR(I10/H10,"n/a") -> n/a | O10: =IF(AND(I10>0,C10>0),C10/I10,"n/a") -> n/a | P10: =IFERROR(F10/D10,"n/a") -> n/a | Q10: =IFERROR(C10/F10,"n/a") -> n/a | R10: =IFERROR(C10/D10*1000,"n/a") -> n/a | S10: =IF(E10="","n/a",IFERROR(D10/E10,"n/a")) -> n/a | T10: =IFERROR(C10/$C$12,"n/a") -> 0 | U10: =IFERROR(I10/$I$12,"n/a") -> 0.010869565 | V10: =IFERROR(IF(AND(I10>0,C10>0),($O$12)/(C10/I10),"n/a"),"n/a") -> n/a
A11: CRM Custom List_CBO_SO | B11: inactive | C11: 0 | D11: 0 | E11: 0 | F11: 0 | G11: 0 | H11: 0 | I11: 9 | J11: =IFERROR(C11/G11,"n/a") -> n/a | K11: =IFERROR(H11/G11,"n/a") -> n/a | L11: =IFERROR(C11/H11,"n/a") -> n/a | M11: =IFERROR(I11/G11,"n/a") -> n/a | N11: =IFERROR(I11/H11,"n/a") -> n/a | O11: =IF(AND(I11>0,C11>0),C11/I11,"n/a") -> n/a | P11: =IFERROR(F11/D11,"n/a") -> n/a | Q11: =IFERROR(C11/F11,"n/a") -> n/a | R11: =IFERROR(C11/D11*1000,"n/a") -> n/a | S11: =IF(E11="","n/a",IFERROR(D11/E11,"n/a")) -> n/a | T11: =IFERROR(C11/$C$12,"n/a") -> 0 | U11: =IFERROR(I11/$I$12,"n/a") -> 0.097826087 | V11: =IFERROR(IF(AND(I11>0,C11>0),($O$12)/(C11/I11),"n/a"),"n/a") -> n/a
A12: TOTAL | C12: =SUM(C5:C11) -> 1215764.3 | D12: =SUM(D5:D11) -> 5860053 | F12: =SUM(F5:F11) -> 30870 | G12: =SUM(G5:G11) -> 1693 | H12: =SUM(H5:H11) -> 417 | I12: =SUM(I5:I11) -> 92 | J12: =IFERROR(C12/G12,"n/a") -> 718.11239 | K12: =IFERROR(H12/G12,"n/a") -> 0.24630833 | L12: =IFERROR(C12/H12,"n/a") -> 2915.5018 | M12: =IFERROR(I12/G12,"n/a") -> 0.054341406 | N12: =IFERROR(I12/H12,"n/a") -> 0.2206235 | O12: =IF(AND(I12>0,C12>0),C12/I12,"n/a") -> 13214.829 | P12: =IFERROR(F12/D12,"n/a") -> 0.0052678704 | Q12: =IFERROR(C12/F12,"n/a") -> 39.383358 | R12: =IFERROR(C12/D12*1000,"n/a") -> 207.46643 | S12: ="n/a" -> n/a | T12: =IFERROR(C12/$C$12,"n/a") -> 1 | U12: =IFERROR(I12/$I$12,"n/a") -> 1 | V12: 1
A15: Is the best campaign really better than the weakest? (two-proportion z-test on Qualified %)
A16: Weakest: Andromeda_CBO_Signature Store_FICO_Daewoo_SO — qualified % | B16: =H5/G5 -> 0.20115894
A17: Best: META_CustomData_MOFU_STOCKIST_Leadgen — qualified % | B17: =H6/G6 -> 0.37058824
A18: Pooled % | B18: =(H5+H6)/(G5+G6) -> 0.23837209
A19: z-score | B19: =(B17-B16)/SQRT(B18*(1-B18)*(1/G5+1/G6)) -> 6.4770436
A20: Verdict | B20: =IF(ABS(B19)>=1.96,"Statistically significant (95%) — gap is real, not noise","Not significant — could be noise") -> Statistically significant (95%) — gap is real, not noise
A21: Weakest qualified→meeting % | B21: =I5/H5 -> 0.12757202
A22: Best qualified→meeting % | B22: =I6/H6 -> 0.32539683

Sheet Funnel_AdSet
A1: Ad set-wise full-funnel scorecard — MTD 1–28 Oct 2026
A2: Frequency = impressions ÷ reach as reported by Meta for the period.
A4: Ad set | B4: Parent campaign | C4: Delivery | D4: Spend (₹) | E4: Impressions | F4: Reach | G4: Link clicks | H4: CRM leads | I4: Qualified | J4: Meetings | K4: CPL (₹ per CRM lead) | L4: Qualified % | M4: CPQL (₹) | N4: Lead→Meeting % | O4: Qualified→Meeting % | P4: Cost per Meeting (₹) | Q4: CTR | R4: CPC (₹) | S4: CPM (₹) | T4: Frequency | U4: % of spend | V4: % of meetings | W4: Efficiency index (acct cost/mtg ÷ row)
A5: HHI Pan India With Exclusions Signature Stores_FICO | B5: Andromeda_CBO_Signature Store_FICO_Daewoo_SO | C5: active | D5: 443840.57 | E5: 2999156 | F5: 1180535 | G5: 15324 | H5: 860 | I5: 167 | J5: 15 | K5: =IFERROR(D5/H5,"n/a") -> 516.09369 | L5: =IFERROR(I5/H5,"n/a") -> 0.19418605 | M5: =IFERROR(D5/I5,"n/a") -> 2657.728 | N5: =IFERROR(J5/H5,"n/a") -> 0.01744186 | O5: =IFERROR(J5/I5,"n/a") -> 0.089820359 | P5: =IF(AND(J5>0,D5>0),D5/J5,"n/a") -> 29589.371 | Q5: =IFERROR(G5/E5,"n/a") -> 0.0051094375 | R5: =IFERROR(D5/G5,"n/a") -> 28.963754 | S5: =IFERROR(D5/E5*1000,"n/a") -> 147.98849 | T5: =IF(F5="","n/a",IFERROR(E5/F5,"n/a")) -> 2.5405058 | U5: =IFERROR(D5/$D$16,"n/a") -> 0.36507124 | V5: =IFERROR(J5/$J$16,"n/a") -> 0.16304348 | W5: =IFERROR(IF(AND(J5>0,D5>0),($P$16)/(D5/J5),"n/a"),"n/a") -> 0.44660729
A6: LAL_1%_Client Data_Stockist | B6: META_CustomData_MOFU_STOCKIST_Leadgen | C6: active | D6: 330784.95 | E6: 856408 | F6: 366715 | G6: 5006 | H6: 325 | I6: 115 | J6: 35 | K6: =IFERROR(D6/H6,"n/a") -> 1017.7998 | L6: =IFERROR(I6/H6,"n/a") -> 0.35384615 | M6: =IFERROR(D6/I6,"n/a") -> 2876.3909 | N6: =IFERROR(J6/H6,"n/a") -> 0.10769231 | O6: =IFERROR(J6/I6,"n/a") -> 0.30434783 | P6: =IF(AND(J6>0,D6>0),D6/J6,"n/a") -> 9450.9986 | Q6: =IFERROR(G6/E6,"n/a") -> 0.0058453447 | R6: =IFERROR(D6/G6,"n/a") -> 66.077697 | S6: =IFERROR(D6/E6*1000,"n/a") -> 386.24692 | T6: =IF(F6="","n/a",IFERROR(E6/F6,"n/a")) -> 2.3353503 | U6: =IFERROR(D6/$D$16,"n/a") -> 0.27207984 | V6: =IFERROR(J6/$J$16,"n/a") -> 0.38043478 | W6: =IFERROR(IF(AND(J6>0,D6>0),($P$16)/(D6/J6),"n/a"),"n/a") -> 1.3982469
A7: Business Interest Signature Stores_FICO | B7: Andromeda_CBO_Signature Store_FICO_Daewoo_SO | C7: active | D7: 229018.3 | E7: 1577811 | F7: 790322 | G7: 7499 | H7: 348 | I7: 76 | J7: 16 | K7: =IFERROR(D7/H7,"n/a") -> 658.09856 | L7: =IFERROR(I7/H7,"n/a") -> 0.2183908 | M7: =IFERROR(D7/I7,"n/a") -> 3013.3987 | N7: =IFERROR(J7/H7,"n/a") -> 0.045977011 | O7: =IFERROR(J7/I7,"n/a") -> 0.21052632 | P7: =IF(AND(J7>0,D7>0),D7/J7,"n/a") -> 14313.644 | Q7: =IFERROR(G7/E7,"n/a") -> 0.0047527872 | R7: =IFERROR(D7/G7,"n/a") -> 30.539845 | S7: =IFERROR(D7/E7*1000,"n/a") -> 145.14939 | T7: =IF(F7="","n/a",IFERROR(E7/F7,"n/a")) -> 1.9964154 | U7: =IFERROR(D7/$D$16,"n/a") -> 0.18837394 | V7: =IFERROR(J7/$J$16,"n/a") -> 0.17391304 | W7: =IFERROR(IF(AND(J7>0,D7>0),($P$16)/(D7/J7),"n/a"),"n/a") -> 0.92323305
A8: LAL_1%_Client Data_Signature Store FICO | B8: META_CustomData_MOFU_Leadgen – Signature FICO | C8: active | D8: 194123.34 | E8: 390794 | F8: 221625 | G8: 2781 | H8: 139 | I8: 46 | J8: 9 | K8: =IFERROR(D8/H8,"n/a") -> 1396.5708 | L8: =IFERROR(I8/H8,"n/a") -> 0.33093525 | M8: =IFERROR(D8/I8,"n/a") -> 4220.0726 | N8: =IFERROR(J8/H8,"n/a") -> 0.064748201 | O8: =IFERROR(J8/I8,"n/a") -> 0.19565217 | P8: =IF(AND(J8>0,D8>0),D8/J8,"n/a") -> 21569.26 | Q8: =IFERROR(G8/E8,"n/a") -> 0.0071162812 | R8: =IFERROR(D8/G8,"n/a") -> 69.80343 | S8: =IFERROR(D8/E8*1000,"n/a") -> 496.74084 | T8: =IF(F8="","n/a",IFERROR(E8/F8,"n/a")) -> 1.7633119 | U8: =IFERROR(D8/$D$16,"n/a") -> 0.15967186 | V8: =IFERROR(J8/$J$16,"n/a") -> 0.097826087 | W8: =IFERROR(IF(AND(J8>0,D8>0),($P$16)/(D8/J8),"n/a"),"n/a") -> 0.61266956
A9: Client Custom Data_Stockist | B9: META_CustomData_MOFU_STOCKIST_Leadgen | C9: active | D9: 7962.14 | E9: 6301 | F9: 2549 | G9: 60 | H9: 15 | I9: 11 | J9: 6 | K9: =IFERROR(D9/H9,"n/a") -> 530.80933 | L9: =IFERROR(I9/H9,"n/a") -> 0.73333333 | M9: =IFERROR(D9/I9,"n/a") -> 723.83091 | N9: =IFERROR(J9/H9,"n/a") -> 0.4 | O9: =IFERROR(J9/I9,"n/a") -> 0.54545455 | P9: =IF(AND(J9>0,D9>0),D9/J9,"n/a") -> 1327.0233 | Q9: =IFERROR(G9/E9,"n/a") -> 0.009522298 | R9: =IFERROR(D9/G9,"n/a") -> 132.70233 | S9: =IFERROR(D9/E9*1000,"n/a") -> 1263.6312 | T9: =IF(F9="","n/a",IFERROR(E9/F9,"n/a")) -> 2.4719498 | U9: =IFERROR(D9/$D$16,"n/a") -> 0.0065490821 | V9: =IFERROR(J9/$J$16,"n/a") -> 0.065217391 | W9: =IFERROR(IF(AND(J9>0,D9>0),($P$16)/(D9/J9),"n/a"),"n/a") -> 9.9582492
A10: Socials Pages_SO | B10: META_RMKT_Socials Pages_CBO_SO | C10: active | D10: 2821.62 | E10: 10131 | F10: 4306 | G10: 116 | H10: 6 | I10: 2 | J10: 1 | K10: =IFERROR(D10/H10,"n/a") -> 470.27 | L10: =IFERROR(I10/H10,"n/a") -> 0.33333333 | M10: =IFERROR(D10/I10,"n/a") -> 1410.81 | N10: =IFERROR(J10/H10,"n/a") -> 0.16666667 | O10: =IFERROR(J10/I10,"n/a") -> 0.5 | P10: =IF(AND(J10>0,D10>0),D10/J10,"n/a") -> 2821.62 | Q10: =IFERROR(G10/E10,"n/a") -> 0.011450005 | R10: =IFERROR(D10/G10,"n/a") -> 24.32431 | S10: =IFERROR(D10/E10*1000,"n/a") -> 278.51347 | T10: =IF(F10="","n/a",IFERROR(E10/F10,"n/a")) -> 2.3527636 | U10: =IFERROR(D10/$D$16,"n/a") -> 0.0023208611 | V10: =IFERROR(J10/$J$16,"n/a") -> 0.010869565 | W10: =IFERROR(IF(AND(J10>0,D10>0),($P$16)/(D10/J10),"n/a"),"n/a") -> 4.6834191
A11: IG Page Engagements | B11: META_RMKT_Engage_ABO_SO | C11: active | D11: 2801.24 | E11: 7539 | F11: 1185 | G11: 48 | H11: 0 | I11: 0 | J11: 0 | K11: =IFERROR(D11/H11,"n/a") -> n/a | L11: =IFERROR(I11/H11,"n/a") -> n/a | M11: =IFERROR(D11/I11,"n/a") -> n/a | N11: =IFERROR(J11/H11,"n/a") -> n/a | O11: =IFERROR(J11/I11,"n/a") -> n/a | P11: =IF(AND(J11>0,D11>0),D11/J11,"n/a") -> n/a | Q11: =IFERROR(G11/E11,"n/a") -> 0.0063668922 | R11: =IFERROR(D11/G11,"n/a") -> 58.359167 | S11: =IFERROR(D11/E11*1000,"n/a") -> 371.56652 | T11: =IF(F11="","n/a",IFERROR(E11/F11,"n/a")) -> 6.3620253 | U11: =IFERROR(D11/$D$16,"n/a") -> 0.002304098 | V11: =IFERROR(J11/$J$16,"n/a") -> 0 | W11: =IFERROR(IF(AND(J11>0,D11>0),($P$16)/(D11/J11),"n/a"),"n/a") -> n/a
A12: FB Page Engagements | B12: META_RMKT_Engage_ABO_SO | C12: active | D12: 2793.17 | E12: 10146 | F12: 1442 | G12: 31 | H12: 0 | I12: 0 | J12: 0 | K12: =IFERROR(D12/H12,"n/a") -> n/a | L12: =IFERROR(I12/H12,"n/a") -> n/a | M12: =IFERROR(D12/I12,"n/a") -> n/a | N12: =IFERROR(J12/H12,"n/a") -> n/a | O12: =IFERROR(J12/I12,"n/a") -> n/a | P12: =IF(AND(J12>0,D12>0),D12/J12,"n/a") -> n/a | Q12: =IFERROR(G12/E12,"n/a") -> 0.0030553913 | R12: =IFERROR(D12/G12,"n/a") -> 90.102258 | S12: =IFERROR(D12/E12*1000,"n/a") -> 275.29765 | T12: =IF(F12="","n/a",IFERROR(E12/F12,"n/a")) -> 7.036061 | U12: =IFERROR(D12/$D$16,"n/a") -> 0.0022974602 | V12: =IFERROR(J12/$J$16,"n/a") -> 0 | W12: =IFERROR(IF(AND(J12>0,D12>0),($P$16)/(D12/J12),"n/a"),"n/a") -> n/a
A13: CRM_Engagements_Positive | B13: META_RMKT_Engage_ABO_SO | C13: active | D13: 1618.94 | E13: 1767 | F13: 104 | G13: 5 | H13: 0 | I13: 0 | J13: 0 | K13: =IFERROR(D13/H13,"n/a") -> n/a | L13: =IFERROR(I13/H13,"n/a") -> n/a | M13: =IFERROR(D13/I13,"n/a") -> n/a | N13: =IFERROR(J13/H13,"n/a") -> n/a | O13: =IFERROR(J13/I13,"n/a") -> n/a | P13: =IF(AND(J13>0,D13>0),D13/J13,"n/a") -> n/a | Q13: =IFERROR(G13/E13,"n/a") -> 0.0028296548 | R13: =IFERROR(D13/G13,"n/a") -> 323.788 | S13: =IFERROR(D13/E13*1000,"n/a") -> 916.20826 | T13: =IF(F13="","n/a",IFERROR(E13/F13,"n/a")) -> 16.990385 | U13: =IFERROR(D13/$D$16,"n/a") -> 0.0013316233 | V13: =IFERROR(J13/$J$16,"n/a") -> 0 | W13: =IFERROR(IF(AND(J13>0,D13>0),($P$16)/(D13/J13),"n/a"),"n/a") -> n/a
A14: New Stockist Audience Owners | B14: Andromeda_ABO_Stockist_Daewoo_SO | C14: not_delivering | D14: 0 | E14: 0 | F14: 0 | G14: 0 | H14: 0 | I14: 0 | J14: 1 | K14: =IFERROR(D14/H14,"n/a") -> n/a | L14: =IFERROR(I14/H14,"n/a") -> n/a | M14: =IFERROR(D14/I14,"n/a") -> n/a | N14: =IFERROR(J14/H14,"n/a") -> n/a | O14: =IFERROR(J14/I14,"n/a") -> n/a | P14: =IF(AND(J14>0,D14>0),D14/J14,"n/a") -> n/a | Q14: =IFERROR(G14/E14,"n/a") -> n/a | R14: =IFERROR(D14/G14,"n/a") -> n/a | S14: =IFERROR(D14/E14*1000,"n/a") -> n/a | T14: =IF(F14="","n/a",IFERROR(E14/F14,"n/a")) -> n/a | U14: =IFERROR(D14/$D$16,"n/a") -> 0 | V14: =IFERROR(J14/$J$16,"n/a") -> 0.010869565 | W14: =IFERROR(IF(AND(J14>0,D14>0),($P$16)/(D14/J14),"n/a"),"n/a") -> n/a
A15: Qualified LAL All Models | B15: CRM Custom List_CBO_SO | C15: not_delivering | D15: 0 | E15: 0 | F15: 0 | G15: 0 | H15: 0 | I15: 0 | J15: 9 | K15: =IFERROR(D15/H15,"n/a") -> n/a | L15: =IFERROR(I15/H15,"n/a") -> n/a | M15: =IFERROR(D15/I15,"n/a") -> n/a | N15: =IFERROR(J15/H15,"n/a") -> n/a | O15: =IFERROR(J15/I15,"n/a") -> n/a | P15: =IF(AND(J15>0,D15>0),D15/J15,"n/a") -> n/a | Q15: =IFERROR(G15/E15,"n/a") -> n/a | R15: =IFERROR(D15/G15,"n/a") -> n/a | S15: =IFERROR(D15/E15*1000,"n/a") -> n/a | T15: =IF(F15="","n/a",IFERROR(E15/F15,"n/a")) -> n/a | U15: =IFERROR(D15/$D$16,"n/a") -> 0 | V15: =IFERROR(J15/$J$16,"n/a") -> 0.097826087 | W15: =IFERROR(IF(AND(J15>0,D15>0),($P$16)/(D15/J15),"n/a"),"n/a") -> n/a
A16: TOTAL | D16: =SUM(D5:D15) -> 1215764.3 | E16: =SUM(E5:E15) -> 5860053 | G16: =SUM(G5:G15) -> 30870 | H16: =SUM(H5:H15) -> 1693 | I16: =SUM(I5:I15) -> 417 | J16: =SUM(J5:J15) -> 92 | K16: =IFERROR(D16/H16,"n/a") -> 718.11239 | L16: =IFERROR(I16/H16,"n/a") -> 0.24630833 | M16: =IFERROR(D16/I16,"n/a") -> 2915.5018 | N16: =IFERROR(J16/H16,"n/a") -> 0.054341406 | O16: =IFERROR(J16/I16,"n/a") -> 0.2206235 | P16: =IF(AND(J16>0,D16>0),D16/J16,"n/a") -> 13214.829 | Q16: =IFERROR(G16/E16,"n/a") -> 0.0052678704 | R16: =IFERROR(D16/G16,"n/a") -> 39.383358 | S16: =IFERROR(D16/E16*1000,"n/a") -> 207.46643 | T16: ="n/a" -> n/a | U16: =IFERROR(D16/$D$16,"n/a") -> 1 | V16: =IFERROR(J16/$J$16,"n/a") -> 1 | W16: 1

Sheet Funnel_Ad
A1: Ad-wise scorecard with verdicts — MTD 1–28 Oct 2026
A2: Each row is Ad set × Ad. Edit the blue thresholds to change verdicts.
A3: Min spend to judge an ad (₹) | B3: 25000
A4: 'Scale' if cost/meeting ≤ this × account average | B4: 0.75
A5: 'Reduce/fix' if cost/meeting ≥ this × account average | B5: 1.5
A6: Min meetings to call 'Scale' | B6: 5
A8: Ad | B8: Ad set | C8: Parent campaign | D8: Delivery | E8: Spend (₹) | F8: Impressions | G8: Reach | H8: Link clicks | I8: CRM leads | J8: Qualified | K8: Meetings | L8: CPL (₹ per CRM lead) | M8: Qualified % | N8: CPQL (₹) | O8: Lead→Meeting % | P8: Qualified→Meeting % | Q8: Cost per Meeting (₹) | R8: CTR | S8: CPC (₹) | T8: CPM (₹) | U8: Frequency | V8: % of spend | W8: % of meetings | X8: Efficiency index (acct cost/mtg ÷ row) | Y8: Qualified % — 95% low | Z8: Qualified % — 95% high | AA8: Sample confidence | AB8: Verdict | AC8: Meta Quality rank | AD8: Meta Engagement rank | AE8: Meta Conversion rank
A9: Signature_Store_160_Glass_SO | B9: HHI Pan India With Exclusions Signature Stores_FICO | C9: Andromeda_CBO_Signature Store_FICO_Daewoo_SO | D9: active | E9: 230022.44 | F9: 1860027 | G9: 874490 | H9: 8247 | I9: 421 | J9: 92 | K9: 10 | L9: =IFERROR(E9/I9,"n/a") -> 546.37159 | M9: =IFERROR(J9/I9,"n/a") -> 0.21852732 | N9: =IFERROR(E9/J9,"n/a") -> 2500.2439 | O9: =IFERROR(K9/I9,"n/a") -> 0.023752969 | P9: =IFERROR(K9/J9,"n/a") -> 0.10869565 | Q9: =IF(AND(K9>0,E9>0),E9/K9,"n/a") -> 23002.244 | R9: =IFERROR(H9/F9,"n/a") -> 0.0044338066 | S9: =IFERROR(E9/H9,"n/a") -> 27.89165 | T9: =IFERROR(E9/F9*1000,"n/a") -> 123.66618 | U9: =IF(G9="","n/a",IFERROR(F9/G9,"n/a")) -> 2.1269849 | V9: =IFERROR(E9/$E$31,"n/a") -> 0.18919987 | W9: =IFERROR(K9/$K$31,"n/a") -> 0.12195122 | X9: =IFERROR(IF(AND(K9>0,E9>0),($Q$31)/(E9/K9),"n/a"),"n/a") -> 0.64456292 | Y9: =IF(I9=0,"n/a",((J9/I9)+1.96^2/(2*I9)-1.96*SQRT((J9/I9)*(1-(J9/I9))/I9+1.96^2/(4*I9^2)))/(1+1.96^2/I9)) -> 0.18169381 | Z9: =IF(I9=0,"n/a",((J9/I9)+1.96^2/(2*I9)+1.96*SQRT((J9/I9)*(1-(J9/I9))/I9+1.96^2/(4*I9^2)))/(1+1.96^2/I9)) -> 0.26045121 | AA9: =IF(I9>=100,"High",IF(I9>=40,"Medium","Low")) -> High | AB9: =IF(I9=0,"n/a (not a lead-gen ad)",IF(E9<$B$3,"Too early (low spend)",IF(K9=0,"Pause / fix — no meetings",IF(AND(Q9<=$B$4*$Q$31,K9>=$B$6),"SCALE",IF(Q9>=$B$5*$Q$31,"REDUCE / fix","Hold & watch"))))) -> REDUCE / fix | AC9: - | AD9: - | AE9: -
A10: Stockist_Reel | B10: LAL_1%_Client Data_Stockist | C10: META_CustomData_MOFU_STOCKIST_Leadgen | D10: active | E10: 191426.3 | F10: 474667 | G10: 284877 | H10: 2763 | I10: 199 | J10: 68 | K10: 23 | L10: =IFERROR(E10/I10,"n/a") -> 961.94121 | M10: =IFERROR(J10/I10,"n/a") -> 0.34170854 | N10: =IFERROR(E10/J10,"n/a") -> 2815.0926 | O10: =IFERROR(K10/I10,"n/a") -> 0.11557789 | P10: =IFERROR(K10/J10,"n/a") -> 0.33823529 | Q10: =IF(AND(K10>0,E10>0),E10/K10,"n/a") -> 8322.8826 | R10: =IFERROR(H10/F10,"n/a") -> 0.0058209229 | S10: =IFERROR(E10/H10,"n/a") -> 69.282048 | T10: =IFERROR(E10/F10*1000,"n/a") -> 403.28546 | U10: =IF(G10="","n/a",IFERROR(F10/G10,"n/a")) -> 1.6662173 | V10: =IFERROR(E10/$E$31,"n/a") -> 0.15745347 | W10: =IFERROR(K10/$K$31,"n/a") -> 0.2804878 | X10: =IFERROR(IF(AND(K10>0,E10>0),($Q$31)/(E10/K10),"n/a"),"n/a") -> 1.7814013 | Y10: =IF(I10=0,"n/a",((J10/I10)+1.96^2/(2*I10)-1.96*SQRT((J10/I10)*(1-(J10/I10))/I10+1.96^2/(4*I10^2)))/(1+1.96^2/I10)) -> 0.27936746 | Z10: =IF(I10=0,"n/a",((J10/I10)+1.96^2/(2*I10)+1.96*SQRT((J10/I10)*(1-(J10/I10))/I10+1.96^2/(4*I10^2)))/(1+1.96^2/I10)) -> 0.41004537 | AA10: =IF(I10>=100,"High",IF(I10>=40,"Medium","Low")) -> High | AB10: =IF(I10=0,"n/a (not a lead-gen ad)",IF(E10<$B$3,"Too early (low spend)",IF(K10=0,"Pause / fix — no meetings",IF(AND(Q10<=$B$4*$Q$31,K10>=$B$6),"SCALE",IF(Q10>=$B$5*$Q$31,"REDUCE / fix","Hold & watch"))))) -> SCALE | AC10: Above average | AD10: Below average – bottom 10% | AE10: Below average – bottom 10%
A11: Signature Store_SO | B11: HHI Pan India With Exclusions Signature Stores_FICO | C11: Andromeda_CBO_Signature Store_FICO_Daewoo_SO | D11: active | E11: 174808.13 | F11: 1008172 | G11: 428606 | H11: 6157 | I11: 361 | J11: 57 | K11: 4 | L11: =IFERROR(E11/I11,"n/a") -> 484.23305 | M11: =IFERROR(J11/I11,"n/a") -> 0.15789474 | N11: =IFERROR(E11/J11,"n/a") -> 3066.8093 | O11: =IFERROR(K11/I11,"n/a") -> 0.011080332 | P11: =IFERROR(K11/J11,"n/a") -> 0.070175439 | Q11: =IF(AND(K11>0,E11>0),E11/K11,"n/a") -> 43702.033 | R11: =IFERROR(H11/F11,"n/a") -> 0.0061070928 | S11: =IFERROR(E11/H11,"n/a") -> 28.39177 | T11: =IFERROR(E11/F11*1000,"n/a") -> 173.39118 | U11: =IF(G11="","n/a",IFERROR(F11/G11,"n/a")) -> 2.3522116 | V11: =IFERROR(E11/$E$31,"n/a") -> 0.14378456 | W11: =IFERROR(K11/$K$31,"n/a") -> 0.048780488 | X11: =IFERROR(IF(AND(K11>0,E11>0),($Q$31)/(E11/K11),"n/a"),"n/a") -> 0.33926096 | Y11: =IF(I11=0,"n/a",((J11/I11)+1.96^2/(2*I11)-1.96*SQRT((J11/I11)*(1-(J11/I11))/I11+1.96^2/(4*I11^2)))/(1+1.96^2/I11)) -> 0.12390677 | Z11: =IF(I11=0,"n/a",((J11/I11)+1.96^2/(2*I11)+1.96*SQRT((J11/I11)*(1-(J11/I11))/I11+1.96^2/(4*I11^2)))/(1+1.96^2/I11)) -> 0.1990871 | AA11: =IF(I11>=100,"High",IF(I11>=40,"Medium","Low")) -> High | AB11: =IF(I11=0,"n/a (not a lead-gen ad)",IF(E11<$B$3,"Too early (low spend)",IF(K11=0,"Pause / fix — no meetings",IF(AND(Q11<=$B$4*$Q$31,K11>=$B$6),"SCALE",IF(Q11>=$B$5*$Q$31,"REDUCE / fix","Hold & watch"))))) -> REDUCE / fix | AC11: - | AD11: - | AE11: -
A12: Reel – V1_Signature_Store | B12: LAL_1%_Client Data_Signature Store FICO | C12: META_CustomData_MOFU_Leadgen – Signature FICO | D12: active | E12: 142745.49 | F12: 285327 | G12: 188498 | H12: 2229 | I12: 95 | J12: 30 | K12: 7 | L12: =IFERROR(E12/I12,"n/a") -> 1502.5841 | M12: =IFERROR(J12/I12,"n/a") -> 0.31578947 | N12: =IFERROR(E12/J12,"n/a") -> 4758.183 | O12: =IFERROR(K12/I12,"n/a") -> 0.073684211 | P12: =IFERROR(K12/J12,"n/a") -> 0.23333333 | Q12: =IF(AND(K12>0,E12>0),E12/K12,"n/a") -> 20392.213 | R12: =IFERROR(H12/F12,"n/a") -> 0.0078120893 | S12: =IFERROR(E12/H12,"n/a") -> 64.040148 | T12: =IFERROR(E12/F12*1000,"n/a") -> 500.28735 | U12: =IF(G12="","n/a",IFERROR(F12/G12,"n/a")) -> 1.5136871 | V12: =IFERROR(E12/$E$31,"n/a") -> 0.11741214 | W12: =IFERROR(K12/$K$31,"n/a") -> 0.085365854 | X12: =IFERROR(IF(AND(K12>0,E12>0),($Q$31)/(E12/K12),"n/a"),"n/a") -> 0.72706153 | Y12: =IF(I12=0,"n/a",((J12/I12)+1.96^2/(2*I12)-1.96*SQRT((J12/I12)*(1-(J12/I12))/I12+1.96^2/(4*I12^2)))/(1+1.96^2/I12)) -> 0.23103088 | Z12: =IF(I12=0,"n/a",((J12/I12)+1.96^2/(2*I12)+1.96*SQRT((J12/I12)*(1-(J12/I12))/I12+1.96^2/(4*I12^2)))/(1+1.96^2/I12)) -> 0.4148672 | AA12: =IF(I12>=100,"High",IF(I12>=40,"Medium","Low")) -> Medium | AB12: =IF(I12=0,"n/a (not a lead-gen ad)",IF(E12<$B$3,"Too early (low spend)",IF(K12=0,"Pause / fix — no meetings",IF(AND(Q12<=$B$4*$Q$31,K12>=$B$6),"SCALE",IF(Q12>=$B$5*$Q$31,"REDUCE / fix","Hold & watch"))))) -> Hold & watch | AC12: Above average | AD12: Below average – bottom 10% | AE12: Below average – bottom 10%
A13: Stockist_IMG_3.5_Limited_All Large_SO | B13: LAL_1%_Client Data_Stockist | C13: META_CustomData_MOFU_STOCKIST_Leadgen | D13: active | E13: 139358.65 | F13: 381741 | G13: 166773 | H13: 2243 | I13: 126 | J13: 47 | K13: 12 | L13: =IFERROR(E13/I13,"n/a") -> 1106.021 | M13: =IFERROR(J13/I13,"n/a") -> 0.37301587 | N13: =IFERROR(E13/J13,"n/a") -> 2965.0777 | O13: =IFERROR(K13/I13,"n/a") -> 0.095238095 | P13: =IFERROR(K13/J13,"n/a") -> 0.25531915 | Q13: =IF(AND(K13>0,E13>0),E13/K13,"n/a") -> 11613.221 | R13: =IFERROR(H13/F13,"n/a") -> 0.0058757115 | S13: =IFERROR(E13/H13,"n/a") -> 62.130473 | T13: =IFERROR(E13/F13*1000,"n/a") -> 365.06073 | U13: =IF(G13="","n/a",IFERROR(F13/G13,"n/a")) -> 2.2889856 | V13: =IFERROR(E13/$E$31,"n/a") -> 0.11462637 | W13: =IFERROR(K13/$K$31,"n/a") -> 0.14634146 | X13: =IFERROR(IF(AND(K13>0,E13>0),($Q$31)/(E13/K13),"n/a"),"n/a") -> 1.2766823 | Y13: =IF(I13=0,"n/a",((J13/I13)+1.96^2/(2*I13)-1.96*SQRT((J13/I13)*(1-(J13/I13))/I13+1.96^2/(4*I13^2)))/(1+1.96^2/I13)) -> 0.29350388 | Z13: =IF(I13=0,"n/a",((J13/I13)+1.96^2/(2*I13)+1.96*SQRT((J13/I13)*(1-(J13/I13))/I13+1.96^2/(4*I13^2)))/(1+1.96^2/I13)) -> 0.46004197 | AA13: =IF(I13>=100,"High",IF(I13>=40,"Medium","Low")) -> High | AB13: =IF(I13=0,"n/a (not a lead-gen ad)",IF(E13<$B$3,"Too early (low spend)",IF(K13=0,"Pause / fix — no meetings",IF(AND(Q13<=$B$4*$Q$31,K13>=$B$6),"SCALE",IF(Q13>=$B$5*$Q$31,"REDUCE / fix","Hold & watch"))))) -> Hold & watch | AC13: - | AD13: - | AE13: -
A14: Signature_Store_160_Glass_SO | B14: Business Interest Signature Stores_FICO | C14: Andromeda_CBO_Signature Store_FICO_Daewoo_SO | D14: active | E14: 115776.82 | F14: 924764 | G14: 527548 | H14: 3622 | I14: 170 | J14: 42 | K14: 8 | L14: =IFERROR(E14/I14,"n/a") -> 681.04012 | M14: =IFERROR(J14/I14,"n/a") -> 0.24705882 | N14: =IFERROR(E14/J14,"n/a") -> 2756.591 | O14: =IFERROR(K14/I14,"n/a") -> 0.047058824 | P14: =IFERROR(K14/J14,"n/a") -> 0.19047619 | Q14: =IF(AND(K14>0,E14>0),E14/K14,"n/a") -> 14472.103 | R14: =IFERROR(H14/F14,"n/a") -> 0.003916675 | S14: =IFERROR(E14/H14,"n/a") -> 31.964887 | T14: =IFERROR(E14/F14*1000,"n/a") -> 125.19607 | U14: =IF(G14="","n/a",IFERROR(F14/G14,"n/a")) -> 1.7529476 | V14: =IFERROR(E14/$E$31,"n/a") -> 0.095229662 | W14: =IFERROR(K14/$K$31,"n/a") -> 0.097560976 | X14: =IFERROR(IF(AND(K14>0,E14>0),($Q$31)/(E14/K14),"n/a"),"n/a") -> 1.024481 | Y14: =IF(I14=0,"n/a",((J14/I14)+1.96^2/(2*I14)-1.96*SQRT((J14/I14)*(1-(J14/I14))/I14+1.96^2/(4*I14^2)))/(1+1.96^2/I14)) -> 0.18829016 | Z14: =IF(I14=0,"n/a",((J14/I14)+1.96^2/(2*I14)+1.96*SQRT((J14/I14)*(1-(J14/I14))/I14+1.96^2/(4*I14^2)))/(1+1.96^2/I14)) -> 0.31700662 | AA14: =IF(I14>=100,"High",IF(I14>=40,"Medium","Low")) -> High | AB14: =IF(I14=0,"n/a (not a lead-gen ad)",IF(E14<$B$3,"Too early (low spend)",IF(K14=0,"Pause / fix — no meetings",IF(AND(Q14<=$B$4*$Q$31,K14>=$B$6),"SCALE",IF(Q14>=$B$5*$Q$31,"REDUCE / fix","Hold & watch"))))) -> Hold & watch | AC14: - | AD14: - | AE14: -
A15: Signature Store_SO | B15: Business Interest Signature Stores_FICO | C15: Andromeda_CBO_Signature Store_FICO_Daewoo_SO | D15: active | E15: 94722.89 | F15: 587574 | G15: 320523 | H15: 3342 | I15: 154 | J15: 30 | K15: 6 | L15: =IFERROR(E15/I15,"n/a") -> 615.0837 | M15: =IFERROR(J15/I15,"n/a") -> 0.19480519 | N15: =IFERROR(E15/J15,"n/a") -> 3157.4297 | O15: =IFERROR(K15/I15,"n/a") -> 0.038961039 | P15: =IFERROR(K15/J15,"n/a") -> 0.2 | Q15: =IF(AND(K15>0,E15>0),E15/K15,"n/a") -> 15787.148 | R15: =IFERROR(H15/F15,"n/a") -> 0.0056877942 | S15: =IFERROR(E15/H15,"n/a") -> 28.343175 | T15: =IFERROR(E15/F15*1000,"n/a") -> 161.21015 | U15: =IF(G15="","n/a",IFERROR(F15/G15,"n/a")) -> 1.8331727 | V15: =IFERROR(E15/$E$31,"n/a") -> 0.077912217 | W15: =IFERROR(K15/$K$31,"n/a") -> 0.073170732 | X15: =IFERROR(IF(AND(K15>0,E15>0),($Q$31)/(E15/K15),"n/a"),"n/a") -> 0.93914323 | Y15: =IF(I15=0,"n/a",((J15/I15)+1.96^2/(2*I15)-1.96*SQRT((J15/I15)*(1-(J15/I15))/I15+1.96^2/(4*I15^2)))/(1+1.96^2/I15)) -> 0.14000138 | Z15: =IF(I15=0,"n/a",((J15/I15)+1.96^2/(2*I15)+1.96*SQRT((J15/I15)*(1-(J15/I15))/I15+1.96^2/(4*I15^2)))/(1+1.96^2/I15)) -> 0.26446486 | AA15: =IF(I15>=100,"High",IF(I15>=40,"Medium","Low")) -> High | AB15: =IF(I15=0,"n/a (not a lead-gen ad)",IF(E15<$B$3,"Too early (low spend)",IF(K15=0,"Pause / fix — no meetings",IF(AND(Q15<=$B$4*$Q$31,K15>=$B$6),"SCALE",IF(Q15>=$B$5*$Q$31,"REDUCE / fix","Hold & watch"))))) -> Hold & watch | AC15: - | AD15: - | AE15: -
A16: Signature_Store_OCT_SO | B16: LAL_1%_Client Data_Signature Store FICO | C16: META_CustomData_MOFU_Leadgen – Signature FICO | D16: active | E16: 51377.85 | F16: 105467 | G16: 53954 | H16: 552 | I16: 44 | J16: 16 | K16: 2 | L16: =IFERROR(E16/I16,"n/a") -> 1167.6784 | M16: =IFERROR(J16/I16,"n/a") -> 0.36363636 | N16: =IFERROR(E16/J16,"n/a") -> 3211.1156 | O16: =IFERROR(K16/I16,"n/a") -> 0.045454545 | P16: =IFERROR(K16/J16,"n/a") -> 0.125 | Q16: =IF(AND(K16>0,E16>0),E16/K16,"n/a") -> 25688.925 | R16: =IFERROR(H16/F16,"n/a") -> 0.0052338646 | S16: =IFERROR(E16/H16,"n/a") -> 93.075815 | T16: =IFERROR(E16/F16*1000,"n/a") -> 487.14622 | U16: =IF(G16="","n/a",IFERROR(F16/G16,"n/a")) -> 1.9547578 | V16: =IFERROR(E16/$E$31,"n/a") -> 0.042259714 | W16: =IFERROR(K16/$K$31,"n/a") -> 0.024390244 | X16: =IFERROR(IF(AND(K16>0,E16>0),($Q$31)/(E16/K16),"n/a"),"n/a") -> 0.57715119 | Y16: =IF(I16=0,"n/a",((J16/I16)+1.96^2/(2*I16)-1.96*SQRT((J16/I16)*(1-(J16/I16))/I16+1.96^2/(4*I16^2)))/(1+1.96^2/I16)) -> 0.23783334 | Z16: =IF(I16=0,"n/a",((J16/I16)+1.96^2/(2*I16)+1.96*SQRT((J16/I16)*(1-(J16/I16))/I16+1.96^2/(4*I16^2)))/(1+1.96^2/I16)) -> 0.51133893 | AA16: =IF(I16>=100,"High",IF(I16>=40,"Medium","Low")) -> Medium | AB16: =IF(I16=0,"n/a (not a lead-gen ad)",IF(E16<$B$3,"Too early (low spend)",IF(K16=0,"Pause / fix — no meetings",IF(AND(Q16<=$B$4*$Q$31,K16>=$B$6),"SCALE",IF(Q16>=$B$5*$Q$31,"REDUCE / fix","Hold & watch"))))) -> REDUCE / fix | AC16: - | AD16: - | AE16: -
A17: Reel – V1_Signature_Store_FICO | B17: HHI Pan India With Exclusions Signature Stores_FICO | C17: Andromeda_CBO_Signature Store_FICO_Daewoo_SO | D17: active | E17: 22638.41 | F17: 66997 | G17: 46060 | H17: 538 | I17: 48 | J17: 9 | K17: 1 | L17: =IFERROR(E17/I17,"n/a") -> 471.63354 | M17: =IFERROR(J17/I17,"n/a") -> 0.1875 | N17: =IFERROR(E17/J17,"n/a") -> 2515.3789 | O17: =IFERROR(K17/I17,"n/a") -> 0.020833333 | P17: =IFERROR(K17/J17,"n/a") -> 0.11111111 | Q17: =IF(AND(K17>0,E17>0),E17/K17,"n/a") -> 22638.41 | R17: =IFERROR(H17/F17,"n/a") -> 0.0080302103 | S17: =IFERROR(E17/H17,"n/a") -> 42.078829 | T17: =IFERROR(E17/F17*1000,"n/a") -> 337.90185 | U17: =IF(G17="","n/a",IFERROR(F17/G17,"n/a")) -> 1.4545593 | V17: =IFERROR(E17/$E$31,"n/a") -> 0.018620723 | W17: =IFERROR(K17/$K$31,"n/a") -> 0.012195122 | X17: =IFERROR(IF(AND(K17>0,E17>0),($Q$31)/(E17/K17),"n/a"),"n/a") -> 0.65492203 | Y17: =IF(I17=0,"n/a",((J17/I17)+1.96^2/(2*I17)-1.96*SQRT((J17/I17)*(1-(J17/I17))/I17+1.96^2/(4*I17^2)))/(1+1.96^2/I17)) -> 0.10191276 | Z17: =IF(I17=0,"n/a",((J17/I17)+1.96^2/(2*I17)+1.96*SQRT((J17/I17)*(1-(J17/I17))/I17+1.96^2/(4*I17^2)))/(1+1.96^2/I17)) -> 0.31940139 | AA17: =IF(I17>=100,"High",IF(I17>=40,"Medium","Low")) -> Medium | AB17: =IF(I17=0,"n/a (not a lead-gen ad)",IF(E17<$B$3,"Too early (low spend)",IF(K17=0,"Pause / fix — no meetings",IF(AND(Q17<=$B$4*$Q$31,K17>=$B$6),"SCALE",IF(Q17>=$B$5*$Q$31,"REDUCE / fix","Hold & watch"))))) -> Too early (low spend) | AC17: Average | AD17: Below average – bottom 10% | AE17: Below average – bottom 10%
A18: Reel – V1_Signature_Store_FICO | B18: Business Interest Signature Stores_FICO | C18: Andromeda_CBO_Signature Store_FICO_Daewoo_SO | D18: active | E18: 18325.06 | F18: 64699 | G18: 43290 | H18: 532 | I18: 24 | J18: 4 | K18: 2 | L18: =IFERROR(E18/I18,"n/a") -> 763.54417 | M18: =IFERROR(J18/I18,"n/a") -> 0.16666667 | N18: =IFERROR(E18/J18,"n/a") -> 4581.265 | O18: =IFERROR(K18/I18,"n/a") -> 0.083333333 | P18: =IFERROR(K18/J18,"n/a") -> 0.5 | Q18: =IF(AND(K18>0,E18>0),E18/K18,"n/a") -> 9162.53 | R18: =IFERROR(H18/F18,"n/a") -> 0.0082226928 | S18: =IFERROR(E18/H18,"n/a") -> 34.445602 | T18: =IFERROR(E18/F18*1000,"n/a") -> 283.2356 | U18: =IF(G18="","n/a",IFERROR(F18/G18,"n/a")) -> 1.4945484 | V18: =IFERROR(E18/$E$31,"n/a") -> 0.015072873 | W18: =IFERROR(K18/$K$31,"n/a") -> 0.024390244 | X18: =IFERROR(IF(AND(K18>0,E18>0),($Q$31)/(E18/K18),"n/a"),"n/a") -> 1.618155 | Y18: =IF(I18=0,"n/a",((J18/I18)+1.96^2/(2*I18)-1.96*SQRT((J18/I18)*(1-(J18/I18))/I18+1.96^2/(4*I18^2)))/(1+1.96^2/I18)) -> 0.06678568 | Z18: =IF(I18=0,"n/a",((J18/I18)+1.96^2/(2*I18)+1.96*SQRT((J18/I18)*(1-(J18/I18))/I18+1.96^2/(4*I18^2)))/(1+1.96^2/I18)) -> 0.3585347 | AA18: =IF(I18>=100,"High",IF(I18>=40,"Medium","Low")) -> Low | AB18: =IF(I18=0,"n/a (not a lead-gen ad)",IF(E18<$B$3,"Too early (low spend)",IF(K18=0,"Pause / fix — no meetings",IF(AND(Q18<=$B$4*$Q$31,K18>=$B$6),"SCALE",IF(Q18>=$B$5*$Q$31,"REDUCE / fix","Hold & watch"))))) -> Too early (low spend) | AC18: Above average | AD18: Below average – bottom 20% | AE18: Below average – bottom 10%
A19: Signature_Store_OCT_SO | B19: HHI Pan India With Exclusions Signature Stores_FICO | C19: Andromeda_CBO_Signature Store_FICO_Daewoo_SO | D19: active | E19: 16371.59 | F19: 63960 | G19: 44687 | H19: 382 | I19: 30 | J19: 9 | K19: 0 | L19: =IFERROR(E19/I19,"n/a") -> 545.71967 | M19: =IFERROR(J19/I19,"n/a") -> 0.3 | N19: =IFERROR(E19/J19,"n/a") -> 1819.0656 | O19: =IFERROR(K19/I19,"n/a") -> 0 | P19: =IFERROR(K19/J19,"n/a") -> 0 | Q19: =IF(AND(K19>0,E19>0),E19/K19,"n/a") -> n/a | R19: =IFERROR(H19/F19,"n/a") -> 0.0059724828 | S19: =IFERROR(E19/H19,"n/a") -> 42.857565 | T19: =IFERROR(E19/F19*1000,"n/a") -> 255.96607 | U19: =IF(G19="","n/a",IFERROR(F19/G19,"n/a")) -> 1.4312887 | V19: =IFERROR(E19/$E$31,"n/a") -> 0.013466089 | W19: =IFERROR(K19/$K$31,"n/a") -> 0 | X19: =IFERROR(IF(AND(K19>0,E19>0),($Q$31)/(E19/K19),"n/a"),"n/a") -> n/a | Y19: =IF(I19=0,"n/a",((J19/I19)+1.96^2/(2*I19)-1.96*SQRT((J19/I19)*(1-(J19/I19))/I19+1.96^2/(4*I19^2)))/(1+1.96^2/I19)) -> 0.16664563 | Z19: =IF(I19=0,"n/a",((J19/I19)+1.96^2/(2*I19)+1.96*SQRT((J19/I19)*(1-(J19/I19))/I19+1.96^2/(4*I19^2)))/(1+1.96^2/I19)) -> 0.47876121 | AA19: =IF(I19>=100,"High",IF(I19>=40,"Medium","Low")) -> Low | AB19: =IF(I19=0,"n/a (not a lead-gen ad)",IF(E19<$B$3,"Too early (low spend)",IF(K19=0,"Pause / fix — no meetings",IF(AND(Q19<=$B$4*$Q$31,K19>=$B$6),"SCALE",IF(Q19>=$B$5*$Q$31,"REDUCE / fix","Hold & watch"))))) -> Too early (low spend) | AC19: - | AD19: - | AE19: -
A20: Stockist_IMG_3.5_Limited_All Large_SO | B20: Client Custom Data_Stockist | C20: META_CustomData_MOFU_STOCKIST_Leadgen | D20: active | E20: 7962.14 | F20: 6301 | G20: 2549 | H20: 60 | I20: 15 | J20: 11 | K20: 6 | L20: =IFERROR(E20/I20,"n/a") -> 530.80933 | M20: =IFERROR(J20/I20,"n/a") -> 0.73333333 | N20: =IFERROR(E20/J20,"n/a") -> 723.83091 | O20: =IFERROR(K20/I20,"n/a") -> 0.4 | P20: =IFERROR(K20/J20,"n/a") -> 0.54545455 | Q20: =IF(AND(K20>0,E20>0),E20/K20,"n/a") -> 1327.0233 | R20: =IFERROR(H20/F20,"n/a") -> 0.009522298 | S20: =IFERROR(E20/H20,"n/a") -> 132.70233 | T20: =IFERROR(E20/F20*1000,"n/a") -> 1263.6312 | U20: =IF(G20="","n/a",IFERROR(F20/G20,"n/a")) -> 2.4719498 | V20: =IFERROR(E20/$E$31,"n/a") -> 0.0065490821 | W20: =IFERROR(K20/$K$31,"n/a") -> 0.073170732 | X20: =IFERROR(IF(AND(K20>0,E20>0),($Q$31)/(E20/K20),"n/a"),"n/a") -> 11.17267 | Y20: =IF(I20=0,"n/a",((J20/I20)+1.96^2/(2*I20)-1.96*SQRT((J20/I20)*(1-(J20/I20))/I20+1.96^2/(4*I20^2)))/(1+1.96^2/I20)) -> 0.4804911 | Z20: =IF(I20=0,"n/a",((J20/I20)+1.96^2/(2*I20)+1.96*SQRT((J20/I20)*(1-(J20/I20))/I20+1.96^2/(4*I20^2)))/(1+1.96^2/I20)) -> 0.89102724 | AA20: =IF(I20>=100,"High",IF(I20>=40,"Medium","Low")) -> Low | AB20: =IF(I20=0,"n/a (not a lead-gen ad)",IF(E20<$B$3,"Too early (low spend)",IF(K20=0,"Pause / fix — no meetings",IF(AND(Q20<=$B$4*$Q$31,K20>=$B$6),"SCALE",IF(Q20>=$B$5*$Q$31,"REDUCE / fix","Hold & watch"))))) -> Too early (low spend) | AC20: - | AD20: - | AE20: -
... A30: Stockist 33 Billion | B30: Socials Pages_SO | C30: META_RMKT_Socials Pages_CBO_SO | D30: active | E30: 55.16 | F30: 172 | G30: 136 | H30: 2 | I30: 0 | J30: 0 | K30: 0 | L30: =IFERROR(E30/I30,"n/a") -> n/a | M30: =IFERROR(J30/I30,"n/a") -> n/a | N30: =IFERROR(E30/J30,"n/a") -> n/a | O30: =IFERROR(K30/I30,"n/a") -> n/a | P30: =IFERROR(K30/J30,"n/a") -> n/a | Q30: =IF(AND(K30>0,E30>0),E30/K30,"n/a") -> n/a | R30: =IFERROR(H30/F30,"n/a") -> 0.011627907 | S30: =IFERROR(E30/H30,"n/a") -> 27.58 | T30: =IFERROR(E30/F30*1000,"n/a") -> 320.69767 | U30: =IF(G30="","n/a",IFERROR(F30/G30,"n/a")) -> 1.2647059 | V30: =IFERROR(E30/$E$31,"n/a") -> 4.5370638e-05 | W30: =IFERROR(K30/$K$31,"n/a") -> 0 | X30: =IFERROR(IF(AND(K30>0,E30>0),($Q$31)/(E30/K30),"n/a"),"n/a") -> n/a | Y30: =IF(I30=0,"n/a",((J30/I30)+1.96^2/(2*I30)-1.96*SQRT((J30/I30)*(1-(J30/I30))/I30+1.96^2/(4*I30^2)))/(1+1.96^2/I30)) -> n/a | Z30: =IF(I30=0,"n/a",((J30/I30)+1.96^2/(2*I30)+1.96*SQRT((J30/I30)*(1-(J30/I30))/I30+1.96^2/(4*I30^2)))/(1+1.96^2/I30)) -> n/a | AA30: =IF(I30>=100,"High",IF(I30>=40,"Medium","Low")) -> Low | AB30: =IF(I30=0,"n/a (not a lead-gen ad)",IF(E30<$B$3,"Too early (low spend)",IF(K30=0,"Pause / fix — no meetings",IF(AND(Q30<=$B$4*$Q$31,K30>=$B$6),"SCALE",IF(Q30>=$B$5*$Q$31,"REDUCE / fix","Hold & watch"))))) -> n/a (not a lead-gen ad) | AC30: - | AD30: - | AE30: -
A31: TOTAL (ads with spend) | E31: =SUM(E9:E30) -> 1215764.3 | F31: =SUM(F9:F30) -> 5860053 | H31: =SUM(H9:H30) -> 30870 | I31: =SUM(I9:I30) -> 1693 | J31: =SUM(J9:J30) -> 417 | K31: =SUM(K9:K30) -> 82 | L31: =IFERROR(E31/I31,"n/a") -> 718.11239 | M31: =IFERROR(J31/I31,"n/a") -> 0.24630833 | N31: =IFERROR(E31/J31,"n/a") -> 2915.5018 | O31: =IFERROR(K31/I31,"n/a") -> 0.048434731 | P31: =IFERROR(K31/J31,"n/a") -> 0.19664269 | Q31: =IF(AND(K31>0,E31>0),E31/K31,"n/a") -> 14826.394 | R31: =IFERROR(H31/F31,"n/a") -> 0.0052678704 | S31: =IFERROR(E31/H31,"n/a") -> 39.383358 | T31: =IFERROR(E31/F31*1000,"n/a") -> 207.46643 | U31: ="n/a" -> n/a | V31: =IFERROR(E31/$E$31,"n/a") -> 1 | W31: =IFERROR(K31/$K$31,"n/a") -> 1 | X31: 1

Sheet Lead_Quality
A1: Lead quality & contactability — why leads do or don't convert
A2: Qualified = CRM Qualified flag. Unreachable = DNP / Not Reachable / Invalid number.
A4: Campaign | B4: Leads | C4: Qualified | D4: Open / not yet worked | E4: Unreachable | F4: Junk | G4: Not interested / Lost | H4: Qualified % | I4: Open % | J4: Unreachable % | K4: Junk % | L4: Not interested % | M4: Reachable-and-engaged %
A5: Andromeda_CBO_Signature Store_FICO_Daewoo_SO | B5: =SUM(C5:G5) -> 1208 | C5: 243 | D5: 213 | E5: 464 | F5: 125 | G5: 163 | H5: =IFERROR(C5/B5,0) -> 0.20115894 | I5: =IFERROR(D5/B5,0) -> 0.1763245 | J5: =IFERROR(E5/B5,0) -> 0.38410596 | K5: =IFERROR(F5/B5,0) -> 0.10347682 | L5: =IFERROR(G5/B5,0) -> 0.13493377 | M5: =IFERROR((C5+D5)/B5,0) -> 0.37748344
A6: META_CustomData_MOFU_STOCKIST_Leadgen | B6: =SUM(C6:G6) -> 340 | C6: 126 | D6: 46 | E6: 131 | F6: 10 | G6: 27 | H6: =IFERROR(C6/B6,0) -> 0.37058824 | I6: =IFERROR(D6/B6,0) -> 0.13529412 | J6: =IFERROR(E6/B6,0) -> 0.38529412 | K6: =IFERROR(F6/B6,0) -> 0.029411765 | L6: =IFERROR(G6/B6,0) -> 0.079411765 | M6: =IFERROR((C6+D6)/B6,0) -> 0.50588235
A7: META_CustomData_MOFU_Leadgen – Signature FICO | B7: =SUM(C7:G7) -> 139 | C7: 46 | D7: 20 | E7: 49 | F7: 5 | G7: 19 | H7: =IFERROR(C7/B7,0) -> 0.33093525 | I7: =IFERROR(D7/B7,0) -> 0.14388489 | J7: =IFERROR(E7/B7,0) -> 0.35251799 | K7: =IFERROR(F7/B7,0) -> 0.035971223 | L7: =IFERROR(G7/B7,0) -> 0.13669065 | M7: =IFERROR((C7+D7)/B7,0) -> 0.47482014
A8: META_RMKT_Socials Pages_CBO_SO | B8: =SUM(C8:G8) -> 6 | C8: 2 | D8: 2 | E8: 2 | F8: 0 | G8: 0 | H8: =IFERROR(C8/B8,0) -> 0.33333333 | I8: =IFERROR(D8/B8,0) -> 0.33333333 | J8: =IFERROR(E8/B8,0) -> 0.33333333 | K8: =IFERROR(F8/B8,0) -> 0 | L8: =IFERROR(G8/B8,0) -> 0 | M8: =IFERROR((C8+D8)/B8,0) -> 0.66666667
A9: TOTAL | B9: =SUM(B5:B8) -> 1693 | C9: =SUM(C5:C8) -> 417 | D9: =SUM(D5:D8) -> 281 | E9: =SUM(E5:E8) -> 646 | F9: =SUM(F5:F8) -> 140 | G9: =SUM(G5:G8) -> 209 | H9: =IFERROR(C9/B9,0) -> 0.24630833 | I9: =IFERROR(D9/B9,0) -> 0.16597755 | J9: =IFERROR(E9/B9,0) -> 0.38157118 | K9: =IFERROR(F9/B9,0) -> 0.082693444 | L9: =IFERROR(G9/B9,0) -> 0.1234495 | M9: =IFERROR((C9+D9)/B9,0) -> 0.41228588
A11: By ad set × ad
A12: Ad set | B12: Ad | C12: Campaign | D12: Leads | E12: Qualified | F12: Open / not yet worked | G12: Unreachable | H12: Junk | I12: Not interested / Lost | J12: Qualified % | K12: Open % | L12: Unreachable % | M12: Junk % | N12: Not interested % | O12: Reachable-and-engaged %
A13: HHI Pan India With Exclusions Signature Stores_FICO | B13: Signature_Store_160_Glass_SO | C13: Andromeda_CBO_Signature Store_FICO_Daewoo_SO | D13: =SUM(E13:I13) -> 421 | E13: 92 | F13: 74 | G13: 177 | H13: 30 | I13: 48 | J13: =IFERROR(E13/D13,0) -> 0.21852732 | K13: =IFERROR(F13/D13,0) -> 0.17577197 | L13: =IFERROR(G13/D13,0) -> 0.42042755 | M13: =IFERROR(H13/D13,0) -> 0.071258907 | N13: =IFERROR(I13/D13,0) -> 0.11401425 | O13: =IFERROR((E13+F13)/D13,0) -> 0.39429929
A14: HHI Pan India With Exclusions Signature Stores_FICO | B14: Signature Store_SO | C14: Andromeda_CBO_Signature Store_FICO_Daewoo_SO | D14: =SUM(E14:I14) -> 361 | E14: 57 | F14: 79 | G14: 149 | H14: 34 | I14: 42 | J14: =IFERROR(E14/D14,0) -> 0.15789474 | K14: =IFERROR(F14/D14,0) -> 0.21883657 | L14: =IFERROR(G14/D14,0) -> 0.41274238 | M14: =IFERROR(H14/D14,0) -> 0.094182825 | N14: =IFERROR(I14/D14,0) -> 0.11634349 | O14: =IFERROR((E14+F14)/D14,0) -> 0.3767313
A15: LAL_1%_Client Data_Stockist | B15: Stockist_Reel | C15: META_CustomData_MOFU_STOCKIST_Leadgen | D15: =SUM(E15:I15) -> 199 | E15: 68 | F15: 27 | G15: 82 | H15: 4 | I15: 18 | J15: =IFERROR(E15/D15,0) -> 0.34170854 | K15: =IFERROR(F15/D15,0) -> 0.13567839 | L15: =IFERROR(G15/D15,0) -> 0.4120603 | M15: =IFERROR(H15/D15,0) -> 0.020100503 | N15: =IFERROR(I15/D15,0) -> 0.090452261 | O15: =IFERROR((E15+F15)/D15,0) -> 0.47738693
A16: Business Interest Signature Stores_FICO | B16: Signature_Store_160_Glass_SO | C16: Andromeda_CBO_Signature Store_FICO_Daewoo_SO | D16: =SUM(E16:I16) -> 170 | E16: 42 | F16: 22 | G16: 54 | H16: 20 | I16: 32 | J16: =IFERROR(E16/D16,0) -> 0.24705882 | K16: =IFERROR(F16/D16,0) -> 0.12941176 | L16: =IFERROR(G16/D16,0) -> 0.31764706 | M16: =IFERROR(H16/D16,0) -> 0.11764706 | N16: =IFERROR(I16/D16,0) -> 0.18823529 | O16: =IFERROR((E16+F16)/D16,0) -> 0.37647059
A17: Business Interest Signature Stores_FICO | B17: Signature Store_SO | C17: Andromeda_CBO_Signature Store_FICO_Daewoo_SO | D17: =SUM(E17:I17) -> 154 | E17: 30 | F17: 16 | G17: 44 | H17: 34 | I17: 30 | J17: =IFERROR(E17/D17,0) -> 0.19480519 | K17: =IFERROR(F17/D17,0) -> 0.1038961 | L17: =IFERROR(G17/D17,0) -> 0.28571429 | M17: =IFERROR(H17/D17,0) -> 0.22077922 | N17: =IFERROR(I17/D17,0) -> 0.19480519 | O17: =IFERROR((E17+F17)/D17,0) -> 0.2987013
A18: LAL_1%_Client Data_Stockist | B18: Stockist_IMG_3.5_Limited_All Large_SO | C18: META_CustomData_MOFU_STOCKIST_Leadgen | D18: =SUM(E18:I18) -> 126 | E18: 47 | F18: 17 | G18: 47 | H18: 6 | I18: 9 | J18: =IFERROR(E18/D18,0) -> 0.37301587 | K18: =IFERROR(F18/D18,0) -> 0.13492063 | L18: =IFERROR(G18/D18,0) -> 0.37301587 | M18: =IFERROR(H18/D18,0) -> 0.047619048 | N18: =IFERROR(I18/D18,0) -> 0.071428571 | O18: =IFERROR((E18+F18)/D18,0) -> 0.50793651
A19: LAL_1%_Client Data_Signature Store FICO | B19: Reel – V1_Signature_Store | C19: META_CustomData_MOFU_Leadgen – Signature FICO | D19: =SUM(E19:I19) -> 95 | E19: 30 | F19: 13 | G19: 32 | H19: 5 | I19: 15 | J19: =IFERROR(E19/D19,0) -> 0.31578947 | K19: =IFERROR(F19/D19,0) -> 0.13684211 | L19: =IFERROR(G19/D19,0) -> 0.33684211 | M19: =IFERROR(H19/D19,0) -> 0.052631579 | N19: =IFERROR(I19/D19,0) -> 0.15789474 | O19: =IFERROR((E19+F19)/D19,0) -> 0.45263158
A20: HHI Pan India With Exclusions Signature Stores_FICO | B20: Reel – V1_Signature_Store_FICO | C20: Andromeda_CBO_Signature Store_FICO_Daewoo_SO | D20: =SUM(E20:I20) -> 48 | E20: 9 | F20: 12 | G20: 18 | H20: 3 | I20: 6 | J20: =IFERROR(E20/D20,0) -> 0.1875 | K20: =IFERROR(F20/D20,0) -> 0.25 | L20: =IFERROR(G20/D20,0) -> 0.375 | M20: =IFERROR(H20/D20,0) -> 0.0625 | N20: =IFERROR(I20/D20,0) -> 0.125 | O20: =IFERROR((E20+F20)/D20,0) -> 0.4375
A21: LAL_1%_Client Data_Signature Store FICO | B21: Signature_Store_OCT_SO | C21: META_CustomData_MOFU_Leadgen – Signature FICO | D21: =SUM(E21:I21) -> 44 | E21: 16 | F21: 7 | G21: 17 | H21: 0 | I21: 4 | J21: =IFERROR(E21/D21,0) -> 0.36363636 | K21: =IFERROR(F21/D21,0) -> 0.15909091 | L21: =IFERROR(G21/D21,0) -> 0.38636364 | M21: =IFERROR(H21/D21,0) -> 0 | N21: =IFERROR(I21/D21,0) -> 0.090909091 | O21: =IFERROR((E21+F21)/D21,0) -> 0.52272727
A22: HHI Pan India With Exclusions Signature Stores_FICO | B22: Signature_Store_OCT_SO | C22: Andromeda_CBO_Signature Store_FICO_Daewoo_SO | D22: =SUM(E22:I22) -> 30 | E22: 9 | F22: 7 | G22: 10 | H22: 2 | I22: 2 | J22: =IFERROR(E22/D22,0) -> 0.3 | K22: =IFERROR(F22/D22,0) -> 0.23333333 | L22: =IFERROR(G22/D22,0) -> 0.33333333 | M22: =IFERROR(H22/D22,0) -> 0.066666667 | N22: =IFERROR(I22/D22,0) -> 0.066666667 | O22: =IFERROR((E22+F22)/D22,0) -> 0.53333333
A23: Business Interest Signature Stores_FICO | B23: Reel – V1_Signature_Store_FICO | C23: Andromeda_CBO_Signature Store_FICO_Daewoo_SO | D23: =SUM(E23:I23) -> 24 | E23: 4 | F23: 3 | G23: 12 | H23: 2 | I23: 3 | J23: =IFERROR(E23/D23,0) -> 0.16666667 | K23: =IFERROR(F23/D23,0) -> 0.125 | L23: =IFERROR(G23/D23,0) -> 0.5 | M23: =IFERROR(H23/D23,0) -> 0.083333333 | N23: =IFERROR(I23/D23,0) -> 0.125 | O23: =IFERROR((E23+F23)/D23,0) -> 0.29166667
A24: Client Custom Data_Stockist | B24: Stockist_IMG_3.5_Limited_All Large_SO | C24: META_CustomData_MOFU_STOCKIST_Leadgen | D24: =SUM(E24:I24) -> 15 | E24: 11 | F24: 2 | G24: 2 | H24: 0 | I24: 0 | J24: =IFERROR(E24/D24,0) -> 0.73333333 | K24: =IFERROR(F24/D24,0) -> 0.13333333 | L24: =IFERROR(G24/D24,0) -> 0.13333333 | M24: =IFERROR(H24/D24,0) -> 0 | N24: =IFERROR(I24/D24,0) -> 0 | O24: =IFERROR((E24+F24)/D24,0) -> 0.86666667
A25: Socials Pages_SO | B25: Stockist_Reel | C25: META_RMKT_Socials Pages_CBO_SO | D25: =SUM(E25:I25) -> 6 | E25: 2 | F25: 2 | G25: 2 | H25: 0 | I25: 0 | J25: =IFERROR(E25/D25,0) -> 0.33333333 | K25: =IFERROR(F25/D25,0) -> 0.33333333 | L25: =IFERROR(G25/D25,0) -> 0.33333333 | M25: =IFERROR(H25/D25,0) -> 0 | N25: =IFERROR(I25/D25,0) -> 0 | O25: =IFERROR((E25+F25)/D25,0) -> 0.66666667
A26: TOTAL | D26: =SUM(D13:D25) -> 1693 | E26: =SUM(E13:E25) -> 417 | F26: =SUM(F13:F25) -> 281 | G26: =SUM(G13:G25) -> 646 | H26: =SUM(H13:H25) -> 140 | I26: =SUM(I13:I25) -> 209 | J26: =IFERROR(E26/D26,0) -> 0.24630833 | K26: =IFERROR(F26/D26,0) -> 0.16597755 | L26: =IFERROR(G26/D26,0) -> 0.38157118 | M26: =IFERROR(H26/D26,0) -> 0.082693444 | N26: =IFERROR(I26/D26,0) -> 0.1234495 | O26: =IFERROR((E26+F26)/D26,0) -> 0.41228588
A28: Raw CRM status counts
A29: Lead status | B29: Leads | C29: % of leads
A30: DNP | B30: 579 | C30: =B30/SUM($B$30:$B$49) -> 0.34199646
A31: Qualified | B31: 275 | C31: =B31/SUM($B$30:$B$49) -> 0.16243355
A32: Not Interested | B32: 167 | C32: =B32/SUM($B$30:$B$49) -> 0.098641465
A33: Junk Lead | B33: 140 | C33: =B33/SUM($B$30:$B$49) -> 0.082693444
A34: Call Back Requested | B34: 98 | C34: =B34/SUM($B$30:$B$49) -> 0.057885411
A35: Attempt 1 | B35: 92 | C35: =B35/SUM($B$30:$B$49) -> 0.054341406
A36: Meeting Scheduled | B36: 71 | C36: =B36/SUM($B$30:$B$49) -> 0.041937389
A37: Not Reachable | B37: 61 | C37: =B37/SUM($B$30:$B$49) -> 0.036030715
A38: New Lead | B38: 55 | C38: =B38/SUM($B$30:$B$49) -> 0.03248671
A39: Interested | B39: 46 | C39: =B39/SUM($B$30:$B$49) -> 0.027170703
A40: Lost | B40: 42 | C40: =B40/SUM($B$30:$B$49) -> 0.024808033
A41: Details Shared | B41: 21 | C41: =B41/SUM($B$30:$B$49) -> 0.012404017
... A49: Attempt 3 | B49: 1 | C49: =B49/SUM($B$30:$B$49) -> 0.00059066745

Sheet Trends
A1: Daily trend by lead-creation date — volume, quality and maturity
A2: 'Open %' = leads sales has not worked yet; recent days look worse than they will end up.
A4: Lead date | B4: Leads | C4: Qualified | D4: Qualified % | E4: Open (not yet worked) | F4: Open % | G4: Unreachable | H4: Unreachable % | I4: 7-day rolling leads (avg/day) | J4: 7-day rolling qualified % | K4: Status of data
A5: 46296 | B5: 33 | C5: 9 | D5: =C5/B5 -> 0.27272727 | E5: 0 | F5: =E5/B5 -> 0 | G5: 14 | H5: =G5/B5 -> 0.42424242 | I5: =AVERAGE(B5:B5) -> 33 | J5: =SUM(C5:C5)/SUM(B5:B5) -> 0.27272727 | K5: =IF(F5>0.3,"Immature — too fresh",IF(F5>0.15,"Maturing","Mature")) -> Mature
A6: 46297 | B6: 19 | C6: 8 | D6: =C6/B6 -> 0.42105263 | E6: 2 | F6: =E6/B6 -> 0.10526316 | G6: 2 | H6: =G6/B6 -> 0.10526316 | I6: =AVERAGE(B5:B6) -> 26 | J6: =SUM(C5:C6)/SUM(B5:B6) -> 0.32692308 | K6: =IF(F6>0.3,"Immature — too fresh",IF(F6>0.15,"Maturing","Mature")) -> Mature
A7: 46298 | B7: 23 | C7: 8 | D7: =C7/B7 -> 0.34782609 | E7: 1 | F7: =E7/B7 -> 0.043478261 | G7: 7 | H7: =G7/B7 -> 0.30434783 | I7: =AVERAGE(B5:B7) -> 25 | J7: =SUM(C5:C7)/SUM(B5:B7) -> 0.33333333 | K7: =IF(F7>0.3,"Immature — too fresh",IF(F7>0.15,"Maturing","Mature")) -> Mature
A8: 46299 | B8: 42 | C8: 17 | D8: =C8/B8 -> 0.4047619 | E8: 4 | F8: =E8/B8 -> 0.095238095 | G8: 11 | H8: =G8/B8 -> 0.26190476 | I8: =AVERAGE(B5:B8) -> 29.25 | J8: =SUM(C5:C8)/SUM(B5:B8) -> 0.35897436 | K8: =IF(F8>0.3,"Immature — too fresh",IF(F8>0.15,"Maturing","Mature")) -> Mature
A9: 46300 | B9: 40 | C9: 16 | D9: =C9/B9 -> 0.4 | E9: 4 | F9: =E9/B9 -> 0.1 | G9: 9 | H9: =G9/B9 -> 0.225 | I9: =AVERAGE(B5:B9) -> 31.4 | J9: =SUM(C5:C9)/SUM(B5:B9) -> 0.36942675 | K9: =IF(F9>0.3,"Immature — too fresh",IF(F9>0.15,"Maturing","Mature")) -> Mature
A10: 46301 | B10: 34 | C10: 11 | D10: =C10/B10 -> 0.32352941 | E10: 3 | F10: =E10/B10 -> 0.088235294 | G10: 10 | H10: =G10/B10 -> 0.29411765 | I10: =AVERAGE(B5:B10) -> 31.833333 | J10: =SUM(C5:C10)/SUM(B5:B10) -> 0.36125654 | K10: =IF(F10>0.3,"Immature — too fresh",IF(F10>0.15,"Maturing","Mature")) -> Mature
A11: 46302 | B11: 39 | C11: 14 | D11: =C11/B11 -> 0.35897436 | E11: 9 | F11: =E11/B11 -> 0.23076923 | G11: 11 | H11: =G11/B11 -> 0.28205128 | I11: =AVERAGE(B5:B11) -> 32.857143 | J11: =SUM(C5:C11)/SUM(B5:B11) -> 0.36086957 | K11: =IF(F11>0.3,"Immature — too fresh",IF(F11>0.15,"Maturing","Mature")) -> Maturing
A12: 46303 | B12: 28 | C12: 12 | D12: =C12/B12 -> 0.42857143 | E12: 1 | F12: =E12/B12 -> 0.035714286 | G12: 9 | H12: =G12/B12 -> 0.32142857 | I12: =AVERAGE(B6:B12) -> 32.142857 | J12: =SUM(C6:C12)/SUM(B6:B12) -> 0.38222222 | K12: =IF(F12>0.3,"Immature — too fresh",IF(F12>0.15,"Maturing","Mature")) -> Mature
A13: 46304 | B13: 35 | C13: 14 | D13: =C13/B13 -> 0.4 | E13: 5 | F13: =E13/B13 -> 0.14285714 | G13: 5 | H13: =G13/B13 -> 0.14285714 | I13: =AVERAGE(B7:B13) -> 34.428571 | J13: =SUM(C7:C13)/SUM(B7:B13) -> 0.38174274 | K13: =IF(F13>0.3,"Immature — too fresh",IF(F13>0.15,"Maturing","Mature")) -> Mature
A14: 46305 | B14: 23 | C14: 6 | D14: =C14/B14 -> 0.26086957 | E14: 4 | F14: =E14/B14 -> 0.17391304 | G14: 6 | H14: =G14/B14 -> 0.26086957 | I14: =AVERAGE(B8:B14) -> 34.428571 | J14: =SUM(C8:C14)/SUM(B8:B14) -> 0.37344398 | K14: =IF(F14>0.3,"Immature — too fresh",IF(F14>0.15,"Maturing","Mature")) -> Maturing
A15: 46306 | B15: 35 | C15: 9 | D15: =C15/B15 -> 0.25714286 | E15: 0 | F15: =E15/B15 -> 0 | G15: 13 | H15: =G15/B15 -> 0.37142857 | I15: =AVERAGE(B9:B15) -> 33.428571 | J15: =SUM(C9:C15)/SUM(B9:B15) -> 0.35042735 | K15: =IF(F15>0.3,"Immature — too fresh",IF(F15>0.15,"Maturing","Mature")) -> Mature
A16: 46307 | B16: 21 | C16: 5 | D16: =C16/B16 -> 0.23809524 | E16: 1 | F16: =E16/B16 -> 0.047619048 | G16: 7 | H16: =G16/B16 -> 0.33333333 | I16: =AVERAGE(B10:B16) -> 30.714286 | J16: =SUM(C10:C16)/SUM(B10:B16) -> 0.33023256 | K16: =IF(F16>0.3,"Immature — too fresh",IF(F16>0.15,"Maturing","Mature")) -> Mature
A17: 46308 | B17: 41 | C17: 16 | D17: =C17/B17 -> 0.3902439 | E17: 1 | F17: =E17/B17 -> 0.024390244 | G17: 16 | H17: =G17/B17 -> 0.3902439 | I17: =AVERAGE(B11:B17) -> 31.714286 | J17: =SUM(C11:C17)/SUM(B11:B17) -> 0.34234234 | K17: =IF(F17>0.3,"Immature — too fresh",IF(F17>0.15,"Maturing","Mature")) -> Mature
A18: 46309 | B18: 37 | C18: 9 | D18: =C18/B18 -> 0.24324324 | E18: 5 | F18: =E18/B18 -> 0.13513514 | G18: 15 | H18: =G18/B18 -> 0.40540541 | I18: =AVERAGE(B12:B18) -> 31.428571 | J18: =SUM(C12:C18)/SUM(B12:B18) -> 0.32272727 | K18: =IF(F18>0.3,"Immature — too fresh",IF(F18>0.15,"Maturing","Mature")) -> Mature
A19: 46310 | B19: 48 | C19: 13 | D19: =C19/B19 -> 0.27083333 | E19: 3 | F19: =E19/B19 -> 0.0625 | G19: 18 | H19: =G19/B19 -> 0.375 | I19: =AVERAGE(B13:B19) -> 34.285714 | J19: =SUM(C13:C19)/SUM(B13:B19) -> 0.3 | K19: =IF(F19>0.3,"Immature — too fresh",IF(F19>0.15,"Maturing","Mature")) -> Mature
A20: 46311 | B20: 47 | C20: 12 | D20: =C20/B20 -> 0.25531915 | E20: 2 | F20: =E20/B20 -> 0.042553191 | G20: 24 | H20: =G20/B20 -> 0.5106383 | I20: =AVERAGE(B14:B20) -> 36 | J20: =SUM(C14:C20)/SUM(B14:B20) -> 0.27777778 | K20: =IF(F20>0.3,"Immature — too fresh",IF(F20>0.15,"Maturing","Mature")) -> Mature
A21: 46312 | B21: 57 | C21: 18 | D21: =C21/B21 -> 0.31578947 | E21: 6 | F21: =E21/B21 -> 0.10526316 | G21: 22 | H21: =G21/B21 -> 0.38596491 | I21: =AVERAGE(B15:B21) -> 40.857143 | J21: =SUM(C15:C21)/SUM(B15:B21) -> 0.28671329 | K21: =IF(F21>0.3,"Immature — too fresh",IF(F21>0.15,"Maturing","Mature")) -> Mature
A22: 46313 | B22: 146 | C22: 36 | D22: =C22/B22 -> 0.24657534 | E22: 16 | F22: =E22/B22 -> 0.10958904 | G22: 67 | H22: =G22/B22 -> 0.45890411 | I22: =AVERAGE(B16:B22) -> 56.714286 | J22: =SUM(C16:C22)/SUM(B16:B22) -> 0.27455919 | K22: =IF(F22>0.3,"Immature — too fresh",IF(F22>0.15,"Maturing","Mature")) -> Mature
... A32: 46323 | B32: 127 | C32: 15 | D32: =C32/B32 -> 0.11811024 | E32: 100 | F32: =E32/B32 -> 0.78740157 | G32: 0 | H32: =G32/B32 -> 0 | I32: =AVERAGE(B26:B32) -> 96.142857 | J32: =SUM(C26:C32)/SUM(B26:B32) -> 0.17533432 | K32: =IF(F32>0.3,"Immature — too fresh",IF(F32>0.15,"Maturing","Mature")) -> Immature — too fresh
A35: Qualified rate by lead period — only leads up to day 25 (≥3 days old) so immature leads don't distort
A36: Period (lead date) | B36: Leads | C36: Qualified | D36: Qualified % | E36: Unreachable % | F36: Junk %
A37: 1–6 Oct | B37: 191 | C37: 69 | D37: =C37/B37 -> 0.36125654 | E37: 0.27748691 | F37: 0.12565445
A38: 7–12 Oct | B38: 181 | C38: 60 | D38: =C38/B38 -> 0.33149171 | E38: 0.28176796 | F38: 0.077348066
A39: 13–18 Oct | B39: 376 | C39: 104 | D39: =C39/B39 -> 0.27659574 | E39: 0.43085106 | F39: 0.1037234
A40: 19–25 Oct | B40: 679 | C40: 150 | D40: =C40/B40 -> 0.22091311 | E40: 0.5287187 | F40: 0.088365243
A43: Ad set mix shift — first half (days 1–12) vs second half (days 13–25), mature leads only
A44: Ad set | B44: Leads 1–12 | C44: Qualified % 1–12 | D44: Unreachable % 1–12 | E44: Leads 13–25 | F44: Qualified % 13–25 | G44: Unreachable % 13–25
A45: HHI Pan India With Exclusions Signature Stores_FICO | B45: 0 | E45: 665 | F45: 0.21203008 | G45: 0.51428571
A46: Business Interest Signature Stores_FICO | B46: 183 | C46: 0.28415301 | D46: 0.24043716 | E46: 138 | F46: 0.15942029 | G46: 0.46376812
A47: LAL_1%_Client Data_Stockist | B47: 129 | C47: 0.41860465 | D47: 0.34108527 | E47: 171 | F47: 0.33918129 | G47: 0.46783626
A48: LAL_1%_Client Data_Signature Store FICO | B48: 53 | C48: 0.32075472 | D48: 0.28301887 | E48: 71 | F48: 0.36619718 | G48: 0.45070423
A49: Client Custom Data_Stockist | B49: 7 | C49: 0.85714286 | D49: 0.14285714 | E49: 6 | F49: 0.83333333 | G49: 0.16666667
A50: Socials Pages_SO | B50: 0 | E50: 4 | F50: 0.5 | G50: 0.5
A51: ALL | B51: 372 | C51: 0.34677419 | D51: 0.27956989 | E51: 1055 | F51: 0.24075829 | G51: 0.49383886

Sheet Budget_Scenarios
A1: Budget pacing & reallocation scenario
A2: Blue cells are inputs. Scenario uses MTD average efficiency — real marginal returns will be lower, hence the haircut.
A4: Campaign | B4: Daily budget in export (₹) | C4: MTD spend (₹) | D4: Avg spend/day (₹, ÷28) | E4: Budget utilisation | F4: Read-out
A5: Andromeda_CBO_Signature Store_FICO_Daewoo_SO | B5: 45288.51 | C5: 672858.87 | D5: =C5/28 -> 24030.674 | E5: =IFERROR(D5/B5,"n/a") -> 0.53061304 | F5: =IF(ISNUMBER(E5),IF(E5<0.75,"Under-delivering vs current budget — budget raised recently, or limited by audience/bid",IF(E5>1.1,"Over budget average (budget lowered, or CBO shifted)","Spending ≈ budget")),"n/a") -> Under-delivering vs current budget — budget raised recently, or limited by audience/bid
