Workbook
Name AsOf: Settings!$B$16
Name CampList: Campaign_Master!$A$2:$A$33
Name CampTypes: Campaign_Master!$B$2:$B$33
Name DaysNew: Settings!$B$22
Name DaysOld: Settings!$B$21
Name fAdSet: Fact_Data!$D$2:$D$3642
Name fCalls: Fact_Data!$S$2:$S$3642
Name fCampaign: Fact_Data!$C$2:$C$3642
Name fClicks: Fact_Data!$W$2:$W$3642
Name fConn: Fact_Data!$T$2:$T$3642
Name fContacted: Fact_Data!$Q$2:$Q$3642
Name fImpr: Fact_Data!$V$2:$V$3642
Name fLeads: Fact_Data!$O$2:$O$3642
Name fLost: Fact_Data!$R$2:$R$3642
Name fMeta: Fact_Data!$X$2:$X$3642
Name fQual: Fact_Data!$P$2:$P$3642
Name fRT: Fact_Data!$A$2:$A$3642
Name fSpend: Fact_Data!$U$2:$U$3642
Name fStatus: Fact_Data!$G$2:$G$3642
Name fType: Fact_Data!$B$2:$B$3642
Name ldCamp: Lead_Data!$I$2:$I$3628
Name ldDate: Lead_Data!$C$2:$C$3628
Name ldQual: Lead_Data!$G$2:$G$3628
Name ldStatus: Lead_Data!$F$2:$F$3628
Name ldType: Lead_Data!$H$2:$H$3628
Name LFLStart: Settings!$B$17
Name QualityStatuses: Settings!$A$4:$A$10
Name Slicer_Campaign: #N/A
Name Slicer_Campaign_Type: #N/A
Name Slicer_Lead_Month: #N/A
Name Slicer_Lead_Status: #N/A
Name Slicer_Lead_Week: #N/A
Name WinEnd: Settings!$B$15
Name WinStart: Settings!$B$14
Name fCLeads: Fact_Data!$Y$2:$Y$3642
Name fCQual: Fact_Data!$Z$2:$Z$3642
Name MetaCamps: Meta_Campaigns!$A$2:$A$29
Name Slicer_Campaign: #N/A
Name Slicer_Campaign_Type: #N/A
Name Slicer_Lead_Month: #N/A
Name Slicer_Lead_Status: #N/A
Name Slicer_Lead_Week: #N/A

Sheet Master Dashboard
B1: NATUF | Lead Quality: Old Campaigns vs New Campaigns - MASTER DASHBOARD
B2: 01-Oct-2026 to 31-Oct-2026 | CRM status as of 31-Oct-2026 | Quality Lead = Won, Token Received, Qualified, Meeting Scheduled, Meeting Conducted, Follow-Up, Details Shared | Old/New set on the Campaign_Master tab (New = Oct26 campaigns)
B4: ="QUALITY: "&TEXT(D13,"0.0%")&" of New-campaign leads are Quality leads vs "&TEXT(C13,"0.0%")&" for Old ("&TEXT((D13-C13)*100,"+0.0;-0.0;0.0")&" pp). COST: INR "&TEXT(D14,"#,##0")&" per Quality Lead for New vs INR "&TEXT(C14,"#,##0")&" for Old (cost metrics use only campaigns with Meta spend data). NOTE: New campaigns (with Meta spend data) went live "&TEXT(LFLStart,"dd-mmm")&" ("&DaysNew&" days in market vs "&DaysOld&" for Old); average lead age is "&TEXT(AsOf-AVERAGEIFS(ldDate,ldType,"New"),"0.0")&" days for New vs "&TEXT(AsOf-AVERAGEIFS(ldDate,ldType,"Old"),"0.0")&" for Old, so New statuses are still maturing." -> QUALITY: 15.0% of New-campaign leads are Quality leads vs 16.1% for Old (-1.1 pp). COST: INR 2,215 per Quality Lead for New vs INR 6,288 for Old (cost metrics use only campaigns with Meta spend data). NOTE: New campaigns (with Meta spend data) went live 08-Oct (24 days in market vs 31 for Old); average lead age is 10.5 days for New vs 17.4 for Old, so New statuses are still maturing.
B6: 1. OLD vs NEW - AT A GLANCE - NATUF
B7: Metric | C7: Old campaigns | D7: New campaigns | E7: New vs Old
B8: Ad spend (INR) | C8: =SUMIFS(fSpend,fType,"Old") -> 1301546.3 | D8: =SUMIFS(fSpend,fType,"New") -> 345559.94 | E8: =IFERROR(D8/C8-1,"-") -> -0.73450047
B9: Leads in CRM | C9: =SUMIFS(fLeads,fType,"Old") -> 1285 | D9: =SUMIFS(fLeads,fType,"New") -> 2342 | E9: =IFERROR(D9/C9-1,"-") -> 0.82256809
B10: New Leads (untouched - status = New Lead) | C10: =SUMIFS(fLeads,fType,"Old",fStatus,"New Lead") -> 227 | D10: =SUMIFS(fLeads,fType,"New",fStatus,"New Lead") -> 352 | E10: =IFERROR(D10/C10-1,"-") -> 0.55066079
B11: Cost per lead (INR) [campaigns with spend data] | C11: =IFERROR(C8/SUMIFS(fCLeads,fType,"Old"),0) -> 1012.8765 | D11: =IFERROR(D8/SUMIFS(fCLeads,fType,"New"),0) -> 358.0932 | E11: =IFERROR(D11/C11-1,"-") -> -0.64645917
B12: QUALITY LEADS | C12: =SUMIFS(fQual,fType,"Old") -> 207 | D12: =SUMIFS(fQual,fType,"New") -> 351 | E12: =IFERROR(D12/C12-1,"-") -> 0.69565217
B13: QUALITY % (quality leads / all leads) | C13: =IFERROR(C12/C9,0) -> 0.16108949 | D13: =IFERROR(D12/D9,0) -> 0.1498719 | E13: =IFERROR((D13-C13)*100,"-") -> -1.121759
B14: COST PER QUALITY LEAD (INR) [campaigns with spend data] | C14: =IFERROR(C8/SUMIFS(fCQual,fType,"Old"),0) -> 6287.6633 | D14: =IFERROR(D8/SUMIFS(fCQual,fType,"New"),0) -> 2215.1278 | E14: =IFERROR(D14/C14-1,"-") -> -0.64770254
B15: Green = New is better, red = New is worse. Rates in percentage points (pp), volumes and costs in % change. Cost per lead / per quality lead divide spend by the leads of campaigns that have Meta spend data (the EBG - In House campaigns have 1,377 CRM leads but no spend in the exports, so they are excluded from cost ratios only).
B18: 2. QUALITY PARAMETERS - Old vs New (count and % of that group's leads)
B19: Quality parameter (CRM status) | C19: Old - Quality Count | D19: Old - Quality % | E19: New - Quality Count | F19: New - Quality % | G19: New vs Old (pp)
B20: =Settings!$A$4 -> Won | C20: =SUMIFS(fLeads,fType,"Old",fStatus,$B20) -> 0 | D20: =IFERROR(C20/C$9,0) -> 0 | E20: =SUMIFS(fLeads,fType,"New",fStatus,$B20) -> 0 | F20: =IFERROR(E20/D$9,0) -> 0 | G20: =(F20-D20)*100 -> 0
B21: =Settings!$A$5 -> Token Received | C21: =SUMIFS(fLeads,fType,"Old",fStatus,$B21) -> 0 | D21: =IFERROR(C21/C$9,0) -> 0 | E21: =SUMIFS(fLeads,fType,"New",fStatus,$B21) -> 0 | F21: =IFERROR(E21/D$9,0) -> 0 | G21: =(F21-D21)*100 -> 0
B22: =Settings!$A$6 -> Qualified | C22: =SUMIFS(fLeads,fType,"Old",fStatus,$B22) -> 14 | D22: =IFERROR(C22/C$9,0) -> 0.010894942 | E22: =SUMIFS(fLeads,fType,"New",fStatus,$B22) -> 20 | F22: =IFERROR(E22/D$9,0) -> 0.0085397096 | G22: =(F22-D22)*100 -> -0.2355232
B23: =Settings!$A$7 -> Meeting Scheduled | C23: =SUMIFS(fLeads,fType,"Old",fStatus,$B23) -> 18 | D23: =IFERROR(C23/C$9,0) -> 0.014007782 | E23: =SUMIFS(fLeads,fType,"New",fStatus,$B23) -> 14 | F23: =IFERROR(E23/D$9,0) -> 0.0059777968 | G23: =(F23-D23)*100 -> -0.80299853
B24: =Settings!$A$8 -> Meeting Conducted | C24: =SUMIFS(fLeads,fType,"Old",fStatus,$B24) -> 36 | D24: =IFERROR(C24/C$9,0) -> 0.028015564 | E24: =SUMIFS(fLeads,fType,"New",fStatus,$B24) -> 15 | F24: =IFERROR(E24/D$9,0) -> 0.0064047822 | G24: =(F24-D24)*100 -> -2.1610782
B25: =Settings!$A$9 -> Follow-Up | C25: =SUMIFS(fLeads,fType,"Old",fStatus,$B25) -> 19 | D25: =IFERROR(C25/C$9,0) -> 0.014785992 | E25: =SUMIFS(fLeads,fType,"New",fStatus,$B25) -> 17 | F25: =IFERROR(E25/D$9,0) -> 0.0072587532 | G25: =(F25-D25)*100 -> -0.7527239
B26: =Settings!$A$10 -> Details Shared | C26: =SUMIFS(fLeads,fType,"Old",fStatus,$B26) -> 120 | D26: =IFERROR(C26/C$9,0) -> 0.093385214 | E26: =SUMIFS(fLeads,fType,"New",fStatus,$B26) -> 285 | F26: =IFERROR(E26/D$9,0) -> 0.12169086 | G26: =(F26-D26)*100 -> 2.8305649
B27: TOTAL QUALITY LEADS | C27: =SUM(C20:C26) -> 207 | D27: =IFERROR(C27/C$9,0) -> 0.16108949 | E27: =SUM(E20:E26) -> 351 | F27: =IFERROR(E27/D$9,0) -> 0.1498719 | G27: =(F27-D27)*100 -> -1.121759
B32: 3. CAMPAIGN WISE - quality and cost (Old campaigns first, then New; sorted by spend)
B33: Campaign Name | C33: Campaign Type (Old / New) | D33: Ad Spend (INR) | E33: Leads | F33: Quality Count | G33: Quality % | H33: Cost per Lead (INR) | I33: Cost per Quality Lead (INR) | J33: =Settings!$A$4 -> Won | K33: =Settings!$A$5 -> Token Received | L33: =Settings!$A$6 -> Qualified | M33: =Settings!$A$7 -> Meeting Scheduled | N33: =Settings!$A$8 -> Meeting Conducted | O33: =Settings!$A$9 -> Follow-Up | P33: =Settings!$A$10 -> Details Shared
B34: E_Karan_Natuf_All_07072026 | C34: =IFERROR(INDEX(CampTypes,MATCH($B34,CampList,0)),"Unattributed") -> Old | D34: =IF(COUNTIF(MetaCamps,$B34)=0,"n/a",SUMIFS(fSpend,fCampaign,$B34)) -> 277596.99 | E34: =SUMIFS(fLeads,fCampaign,$B34) -> 229 | F34: =SUMIFS(fQual,fCampaign,$B34) -> 21 | G34: =IFERROR(F34/E34,0) -> 0.091703057 | H34: =IF(OR(E34=0,COUNTIF(MetaCamps,$B34)=0),"-",D34/E34) -> 1212.2139 | I34: =IF(OR(F34=0,COUNTIF(MetaCamps,$B34)=0),"-",D34/F34) -> 13218.904 | J34: =SUMIFS(fLeads,fCampaign,$B34,fStatus,J$33) -> 0 | K34: =SUMIFS(fLeads,fCampaign,$B34,fStatus,K$33) -> 0 | L34: =SUMIFS(fLeads,fCampaign,$B34,fStatus,L$33) -> 0 | M34: =SUMIFS(fLeads,fCampaign,$B34,fStatus,M$33) -> 3 | N34: =SUMIFS(fLeads,fCampaign,$B34,fStatus,N$33) -> 2 | O34: =SUMIFS(fLeads,fCampaign,$B34,fStatus,O$33) -> 3 | P34: =SUMIFS(fLeads,fCampaign,$B34,fStatus,P$33) -> 13
B35: E_Natuf_Generic_13082026 | C35: =IFERROR(INDEX(CampTypes,MATCH($B35,CampList,0)),"Unattributed") -> Old | D35: =IF(COUNTIF(MetaCamps,$B35)=0,"n/a",SUMIFS(fSpend,fCampaign,$B35)) -> 233578.47 | E35: =SUMIFS(fLeads,fCampaign,$B35) -> 210 | F35: =SUMIFS(fQual,fCampaign,$B35) -> 40 | G35: =IFERROR(F35/E35,0) -> 0.19047619 | H35: =IF(OR(E35=0,COUNTIF(MetaCamps,$B35)=0),"-",D35/E35) -> 1112.2784 | I35: =IF(OR(F35=0,COUNTIF(MetaCamps,$B35)=0),"-",D35/F35) -> 5839.4618 | J35: =SUMIFS(fLeads,fCampaign,$B35,fStatus,J$33) -> 0 | K35: =SUMIFS(fLeads,fCampaign,$B35,fStatus,K$33) -> 0 | L35: =SUMIFS(fLeads,fCampaign,$B35,fStatus,L$33) -> 1 | M35: =SUMIFS(fLeads,fCampaign,$B35,fStatus,M$33) -> 2 | N35: =SUMIFS(fLeads,fCampaign,$B35,fStatus,N$33) -> 14 | O35: =SUMIFS(fLeads,fCampaign,$B35,fStatus,O$33) -> 3 | P35: =SUMIFS(fLeads,fCampaign,$B35,fStatus,P$33) -> 20
B36: E_Suresh_Natuf_Kiosk_07072026 | C36: =IFERROR(INDEX(CampTypes,MATCH($B36,CampList,0)),"Unattributed") -> Old | D36: =IF(COUNTIF(MetaCamps,$B36)=0,"n/a",SUMIFS(fSpend,fCampaign,$B36)) -> 232416.42 | E36: =SUMIFS(fLeads,fCampaign,$B36) -> 313 | F36: =SUMIFS(fQual,fCampaign,$B36) -> 68 | G36: =IFERROR(F36/E36,0) -> 0.2172524 | H36: =IF(OR(E36=0,COUNTIF(MetaCamps,$B36)=0),"-",D36/E36) -> 742.54447 | I36: =IF(OR(F36=0,COUNTIF(MetaCamps,$B36)=0),"-",D36/F36) -> 3417.8885 | J36: =SUMIFS(fLeads,fCampaign,$B36,fStatus,J$33) -> 0 | K36: =SUMIFS(fLeads,fCampaign,$B36,fStatus,K$33) -> 0 | L36: =SUMIFS(fLeads,fCampaign,$B36,fStatus,L$33) -> 6 | M36: =SUMIFS(fLeads,fCampaign,$B36,fStatus,M$33) -> 9 | N36: =SUMIFS(fLeads,fCampaign,$B36,fStatus,N$33) -> 8 | O36: =SUMIFS(fLeads,fCampaign,$B36,fStatus,O$33) -> 4 | P36: =SUMIFS(fLeads,fCampaign,$B36,fStatus,P$33) -> 41
B37: natuf_Kiosk_14072026_Hindi | C37: =IFERROR(INDEX(CampTypes,MATCH($B37,CampList,0)),"Unattributed") -> Old | D37: =IF(COUNTIF(MetaCamps,$B37)=0,"n/a",SUMIFS(fSpend,fCampaign,$B37)) -> 180149.88 | E37: =SUMIFS(fLeads,fCampaign,$B37) -> 382 | F37: =SUMIFS(fQual,fCampaign,$B37) -> 42 | G37: =IFERROR(F37/E37,0) -> 0.10994764 | H37: =IF(OR(E37=0,COUNTIF(MetaCamps,$B37)=0),"-",D37/E37) -> 471.59654 | I37: =IF(OR(F37=0,COUNTIF(MetaCamps,$B37)=0),"-",D37/F37) -> 4289.2829 | J37: =SUMIFS(fLeads,fCampaign,$B37,fStatus,J$33) -> 0 | K37: =SUMIFS(fLeads,fCampaign,$B37,fStatus,K$33) -> 0 | L37: =SUMIFS(fLeads,fCampaign,$B37,fStatus,L$33) -> 3 | M37: =SUMIFS(fLeads,fCampaign,$B37,fStatus,M$33) -> 2 | N37: =SUMIFS(fLeads,fCampaign,$B37,fStatus,N$33) -> 4 | O37: =SUMIFS(fLeads,fCampaign,$B37,fStatus,O$33) -> 8 | P37: =SUMIFS(fLeads,fCampaign,$B37,fStatus,P$33) -> 25
B38: E_Selva_Natuf_All_07072026 | C38: =IFERROR(INDEX(CampTypes,MATCH($B38,CampList,0)),"Unattributed") -> Old | D38: =IF(COUNTIF(MetaCamps,$B38)=0,"n/a",SUMIFS(fSpend,fCampaign,$B38)) -> 80349.25 | E38: =SUMIFS(fLeads,fCampaign,$B38) -> 46 | F38: =SUMIFS(fQual,fCampaign,$B38) -> 14 | G38: =IFERROR(F38/E38,0) -> 0.30434783 | H38: =IF(OR(E38=0,COUNTIF(MetaCamps,$B38)=0),"-",D38/E38) -> 1746.7228 | I38: =IF(OR(F38=0,COUNTIF(MetaCamps,$B38)=0),"-",D38/F38) -> 5739.2321 | J38: =SUMIFS(fLeads,fCampaign,$B38,fStatus,J$33) -> 0 | K38: =SUMIFS(fLeads,fCampaign,$B38,fStatus,K$33) -> 0 | L38: =SUMIFS(fLeads,fCampaign,$B38,fStatus,L$33) -> 2 | M38: =SUMIFS(fLeads,fCampaign,$B38,fStatus,M$33) -> 1 | N38: =SUMIFS(fLeads,fCampaign,$B38,fStatus,N$33) -> 3 | O38: =SUMIFS(fLeads,fCampaign,$B38,fStatus,O$33) -> 1 | P38: =SUMIFS(fLeads,fCampaign,$B38,fStatus,P$33) -> 7
B39: E_Natuf_MF_05092026 | C39: =IFERROR(INDEX(CampTypes,MATCH($B39,CampList,0)),"Unattributed") -> Old | D39: =IF(COUNTIF(MetaCamps,$B39)=0,"n/a",SUMIFS(fSpend,fCampaign,$B39)) -> 79772.24 | E39: =SUMIFS(fLeads,fCampaign,$B39) -> 26 | F39: =SUMIFS(fQual,fCampaign,$B39) -> 1 | G39: =IFERROR(F39/E39,0) -> 0.038461538 | H39: =IF(OR(E39=0,COUNTIF(MetaCamps,$B39)=0),"-",D39/E39) -> 3068.1631 | I39: =IF(OR(F39=0,COUNTIF(MetaCamps,$B39)=0),"-",D39/F39) -> 79772.24 | J39: =SUMIFS(fLeads,fCampaign,$B39,fStatus,J$33) -> 0 | K39: =SUMIFS(fLeads,fCampaign,$B39,fStatus,K$33) -> 0 | L39: =SUMIFS(fLeads,fCampaign,$B39,fStatus,L$33) -> 0 | M39: =SUMIFS(fLeads,fCampaign,$B39,fStatus,M$33) -> 0 | N39: =SUMIFS(fLeads,fCampaign,$B39,fStatus,N$33) -> 0 | O39: =SUMIFS(fLeads,fCampaign,$B39,fStatus,O$33) -> 0 | P39: =SUMIFS(fLeads,fCampaign,$B39,fStatus,P$33) -> 1
B40: E_Natuf_Generic_09092026 | C40: =IFERROR(INDEX(CampTypes,MATCH($B40,CampList,0)),"Unattributed") -> Old | D40: =IF(COUNTIF(MetaCamps,$B40)=0,"n/a",SUMIFS(fSpend,fCampaign,$B40)) -> 71194.81 | E40: =SUMIFS(fLeads,fCampaign,$B40) -> 8 | F40: =SUMIFS(fQual,fCampaign,$B40) -> 2 | G40: =IFERROR(F40/E40,0) -> 0.25 | H40: =IF(OR(E40=0,COUNTIF(MetaCamps,$B40)=0),"-",D40/E40) -> 8899.3512 | I40: =IF(OR(F40=0,COUNTIF(MetaCamps,$B40)=0),"-",D40/F40) -> 35597.405 | J40: =SUMIFS(fLeads,fCampaign,$B40,fStatus,J$33) -> 0 | K40: =SUMIFS(fLeads,fCampaign,$B40,fStatus,K$33) -> 0 | L40: =SUMIFS(fLeads,fCampaign,$B40,fStatus,L$33) -> 0 | M40: =SUMIFS(fLeads,fCampaign,$B40,fStatus,M$33) -> 0 | N40: =SUMIFS(fLeads,fCampaign,$B40,fStatus,N$33) -> 1 | O40: =SUMIFS(fLeads,fCampaign,$B40,fStatus,O$33) -> 0 | P40: =SUMIFS(fLeads,fCampaign,$B40,fStatus,P$33) -> 1
B41: E_Karan_Natuf_Kiosk_07072026 | C41: =IFERROR(INDEX(CampTypes,MATCH($B41,CampList,0)),"Unattributed") -> Old | D41: =IF(COUNTIF(MetaCamps,$B41)=0,"n/a",SUMIFS(fSpend,fCampaign,$B41)) -> 54540.16 | E41: =SUMIFS(fLeads,fCampaign,$B41) -> 24 | F41: =SUMIFS(fQual,fCampaign,$B41) -> 6 | G41: =IFERROR(F41/E41,0) -> 0.25 | H41: =IF(OR(E41=0,COUNTIF(MetaCamps,$B41)=0),"-",D41/E41) -> 2272.5067 | I41: =IF(OR(F41=0,COUNTIF(MetaCamps,$B41)=0),"-",D41/F41) -> 9090.0267 | J41: =SUMIFS(fLeads,fCampaign,$B41,fStatus,J$33) -> 0 | K41: =SUMIFS(fLeads,fCampaign,$B41,fStatus,K$33) -> 0 | L41: =SUMIFS(fLeads,fCampaign,$B41,fStatus,L$33) -> 1 | M41: =SUMIFS(fLeads,fCampaign,$B41,fStatus,M$33) -> 0 | N41: =SUMIFS(fLeads,fCampaign,$B41,fStatus,N$33) -> 3 | O41: =SUMIFS(fLeads,fCampaign,$B41,fStatus,O$33) -> 0 | P41: =SUMIFS(fLeads,fCampaign,$B41,fStatus,P$33) -> 2
B42: E_Natuf_Foco_10092026 | C42: =IFERROR(INDEX(CampTypes,MATCH($B42,CampList,0)),"Unattributed") -> Old | D42: =IF(COUNTIF(MetaCamps,$B42)=0,"n/a",SUMIFS(fSpend,fCampaign,$B42)) -> 46413.52 | E42: =SUMIFS(fLeads,fCampaign,$B42) -> 32 | F42: =SUMIFS(fQual,fCampaign,$B42) -> 7 | G42: =IFERROR(F42/E42,0) -> 0.21875 | H42: =IF(OR(E42=0,COUNTIF(MetaCamps,$B42)=0),"-",D42/E42) -> 1450.4225 | I42: =IF(OR(F42=0,COUNTIF(MetaCamps,$B42)=0),"-",D42/F42) -> 6630.5029 | J42: =SUMIFS(fLeads,fCampaign,$B42,fStatus,J$33) -> 0 | K42: =SUMIFS(fLeads,fCampaign,$B42,fStatus,K$33) -> 0 | L42: =SUMIFS(fLeads,fCampaign,$B42,fStatus,L$33) -> 0 | M42: =SUMIFS(fLeads,fCampaign,$B42,fStatus,M$33) -> 1 | N42: =SUMIFS(fLeads,fCampaign,$B42,fStatus,N$33) -> 1 | O42: =SUMIFS(fLeads,fCampaign,$B42,fStatus,O$33) -> 0 | P42: =SUMIFS(fLeads,fCampaign,$B42,fStatus,P$33) -> 5
B43: E_Natuf_Amazon_29092026 | C43: =IFERROR(INDEX(CampTypes,MATCH($B43,CampList,0)),"Unattributed") -> Old | D43: =IF(COUNTIF(MetaCamps,$B43)=0,"n/a",SUMIFS(fSpend,fCampaign,$B43)) -> 39121.71 | E43: =SUMIFS(fLeads,fCampaign,$B43) -> 15 | F43: =SUMIFS(fQual,fCampaign,$B43) -> 6 | G43: =IFERROR(F43/E43,0) -> 0.4 | H43: =IF(OR(E43=0,COUNTIF(MetaCamps,$B43)=0),"-",D43/E43) -> 2608.114 | I43: =IF(OR(F43=0,COUNTIF(MetaCamps,$B43)=0),"-",D43/F43) -> 6520.285 | J43: =SUMIFS(fLeads,fCampaign,$B43,fStatus,J$33) -> 0 | K43: =SUMIFS(fLeads,fCampaign,$B43,fStatus,K$33) -> 0 | L43: =SUMIFS(fLeads,fCampaign,$B43,fStatus,L$33) -> 1 | M43: =SUMIFS(fLeads,fCampaign,$B43,fStatus,M$33) -> 0 | N43: =SUMIFS(fLeads,fCampaign,$B43,fStatus,N$33) -> 0 | O43: =SUMIFS(fLeads,fCampaign,$B43,fStatus,O$33) -> 0 | P43: =SUMIFS(fLeads,fCampaign,$B43,fStatus,P$33) -> 5
B44: E_Natuf_Web_23092026 | C44: =IFERROR(INDEX(CampTypes,MATCH($B44,CampList,0)),"Unattributed") -> Old | D44: =IF(COUNTIF(MetaCamps,$B44)=0,"n/a",SUMIFS(fSpend,fCampaign,$B44)) -> 6412.86 | E44: =SUMIFS(fLeads,fCampaign,$B44) -> 0 | F44: =SUMIFS(fQual,fCampaign,$B44) -> 0 | G44: =IFERROR(F44/E44,0) -> 0 | H44: =IF(OR(E44=0,COUNTIF(MetaCamps,$B44)=0),"-",D44/E44) -> - | I44: =IF(OR(F44=0,COUNTIF(MetaCamps,$B44)=0),"-",D44/F44) -> - | J44: =SUMIFS(fLeads,fCampaign,$B44,fStatus,J$33) -> 0 | K44: =SUMIFS(fLeads,fCampaign,$B44,fStatus,K$33) -> 0 | L44: =SUMIFS(fLeads,fCampaign,$B44,fStatus,L$33) -> 0 | M44: =SUMIFS(fLeads,fCampaign,$B44,fStatus,M$33) -> 0 | N44: =SUMIFS(fLeads,fCampaign,$B44,fStatus,N$33) -> 0 | O44: =SUMIFS(fLeads,fCampaign,$B44,fStatus,O$33) -> 0 | P44: =SUMIFS(fLeads,fCampaign,$B44,fStatus,P$33) -> 0
B45: ABO | Natuf | Leads | Unit Franchise | India | Oct26 | V1 | C45: =IFERROR(INDEX(CampTypes,MATCH($B45,CampList,0)),"Unattributed") -> New | D45: =IF(COUNTIF(MetaCamps,$B45)=0,"n/a",SUMIFS(fSpend,fCampaign,$B45)) -> 264151.59 | E45: =SUMIFS(fLeads,fCampaign,$B45) -> 817 | F45: =SUMIFS(fQual,fCampaign,$B45) -> 149 | G45: =IFERROR(F45/E45,0) -> 0.18237454 | H45: =IF(OR(E45=0,COUNTIF(MetaCamps,$B45)=0),"-",D45/E45) -> 323.31896 | I45: =IF(OR(F45=0,COUNTIF(MetaCamps,$B45)=0),"-",D45/F45) -> 1772.8295 | J45: =SUMIFS(fLeads,fCampaign,$B45,fStatus,J$33) -> 0 | K45: =SUMIFS(fLeads,fCampaign,$B45,fStatus,K$33) -> 0 | L45: =SUMIFS(fLeads,fCampaign,$B45,fStatus,L$33) -> 14 | M45: =SUMIFS(fLeads,fCampaign,$B45,fStatus,M$33) -> 4 | N45: =SUMIFS(fLeads,fCampaign,$B45,fStatus,N$33) -> 5 | O45: =SUMIFS(fLeads,fCampaign,$B45,fStatus,O$33) -> 2 | P45: =SUMIFS(fLeads,fCampaign,$B45,fStatus,P$33) -> 124
... B50: EBG - In House | ABO | Natuf | Leads | Master Franchise | India | Oct26 | V1 | C50: =IFERROR(INDEX(CampTypes,MATCH($B50,CampList,0)),"Unattributed") -> New | D50: =IF(COUNTIF(MetaCamps,$B50)=0,"n/a",SUMIFS(fSpend,fCampaign,$B50)) -> n/a | E50: =SUMIFS(fLeads,fCampaign,$B50) -> 42 | F50: =SUMIFS(fQual,fCampaign,$B50) -> 0 | G50: =IFERROR(F50/E50,0) -> 0 | H50: =IF(OR(E50=0,COUNTIF(MetaCamps,$B50)=0),"-",D50/E50) -> - | I50: =IF(OR(F50=0,COUNTIF(MetaCamps,$B50)=0),"-",D50/F50) -> - | J50: =SUMIFS(fLeads,fCampaign,$B50,fStatus,J$33) -> 0 | K50: =SUMIFS(fLeads,fCampaign,$B50,fStatus,K$33) -> 0 | L50: =SUMIFS(fLeads,fCampaign,$B50,fStatus,L$33) -> 0 | M50: =SUMIFS(fLeads,fCampaign,$B50,fStatus,M$33) -> 0 | N50: =SUMIFS(fLeads,fCampaign,$B50,fStatus,N$33) -> 0 | O50: =SUMIFS(fLeads,fCampaign,$B50,fStatus,O$33) -> 0 | P50: =SUMIFS(fLeads,fCampaign,$B50,fStatus,P$33) -> 0
B52: TOTAL - OLD CAMPAIGNS | D52: =SUMIFS(fSpend,fType,"Old") -> 1301546.3 | E52: =SUMIFS(fLeads,fType,"Old") -> 1285 | F52: =SUMIFS(fQual,fType,"Old") -> 207 | G52: =IFERROR(F52/E52,0) -> 0.16108949 | H52: =IF(SUMIFS(fCLeads,fType,"Old")=0,"-",D52/SUMIFS(fCLeads,fType,"Old")) -> 1012.8765 | I52: =IF(SUMIFS(fCQual,fType,"Old")=0,"-",D52/SUMIFS(fCQual,fType,"Old")) -> 6287.6633 | J52: =SUMIFS(fLeads,fType,"Old",fStatus,J$33) -> 0 | K52: =SUMIFS(fLeads,fType,"Old",fStatus,K$33) -> 0 | L52: =SUMIFS(fLeads,fType,"Old",fStatus,L$33) -> 14 | M52: =SUMIFS(fLeads,fType,"Old",fStatus,M$33) -> 18 | N52: =SUMIFS(fLeads,fType,"Old",fStatus,N$33) -> 36 | O52: =SUMIFS(fLeads,fType,"Old",fStatus,O$33) -> 19 | P52: =SUMIFS(fLeads,fType,"Old",fStatus,P$33) -> 120
B53: TOTAL - NEW CAMPAIGNS | D53: =SUMIFS(fSpend,fType,"New") -> 345559.94 | E53: =SUMIFS(fLeads,fType,"New") -> 2342 | F53: =SUMIFS(fQual,fType,"New") -> 351 | G53: =IFERROR(F53/E53,0) -> 0.1498719 | H53: =IF(SUMIFS(fCLeads,fType,"New")=0,"-",D53/SUMIFS(fCLeads,fType,"New")) -> 358.0932 | I53: =IF(SUMIFS(fCQual,fType,"New")=0,"-",D53/SUMIFS(fCQual,fType,"New")) -> 2215.1278 | J53: =SUMIFS(fLeads,fType,"New",fStatus,J$33) -> 0 | K53: =SUMIFS(fLeads,fType,"New",fStatus,K$33) -> 0 | L53: =SUMIFS(fLeads,fType,"New",fStatus,L$33) -> 20 | M53: =SUMIFS(fLeads,fType,"New",fStatus,M$33) -> 14 | N53: =SUMIFS(fLeads,fType,"New",fStatus,N$33) -> 15 | O53: =SUMIFS(fLeads,fType,"New",fStatus,O$33) -> 17 | P53: =SUMIFS(fLeads,fType,"New",fStatus,P$33) -> 285
...

Sheet Master Pivot
B1: NATUF | Lead Quality: Old Campaigns vs New Campaigns - MASTER PIVOT (interactive)
B2: 01-Oct-2026 to 31-Oct-2026 | CRM status as of 31-Oct-2026 | Quality Lead = Won, Token Received, Qualified, Meeting Scheduled, Meeting Conducted, Follow-Up, Details Shared | Click any slicer button to filter every table (Ctrl+click = multi-select)
B3: Jump to > | C3: Headline | D3: Status funnel | E3: Campaign | F3: Quality table
B4: FILTERS (slicers) - click a button to filter the three pivot tables below; Ctrl+click = multi-select. Spend cannot be split by status / month / week, so it shows "-" when those are used. Cost per lead / per quality lead use only campaigns with Meta spend data (EBG - In House campaigns have no spend in the exports).
B24: 1. HEADLINE - Old vs New campaigns (all key metrics)
C25: Campaign Type
B26: Values | C26: Old | D26: New | E26: Grand Total
B27: Spend (₹) | C27: 1301546.3 | D27: 345559.94 | E27: 1647106.2
B28: Leads | C28: 1285 | D28: 2342 | E28: 3627
B29: Cost per Lead (₹) | C29: 1012.8765 | D29: 358.0932 | E29: 732.04722
B30: Contacted % | C30: 0.8233463 | D30: 0.84970111 | E30: 0.84036394
B31: Quality Leads | C31: 207 | D31: 351 | E31: 558
B32: Quality % | C32: 0.16108949 | D32: 0.1498719 | E32: 0.15384615
B33: Quality % of Contacted | C33: 0.19565217 | D33: 0.17638191 | E33: 0.18307087
B34: Cost per Quality Lead (₹) | C34: 6287.6633 | D34: 2215.1278 | E34: 4537.4828
B38: 2. LEAD STATUS FUNNEL - number of leads by status
B39: Record Type | C39: Lead
B41: Leads | C41: Campaign Type
B42: Lead Status | C42: Old | D42: New | E42: Grand Total
B43: Qualified | C43: 14 | D43: 20 | E43: 34
B44: Meeting Scheduled | C44: 18 | D44: 14 | E44: 32
B45: Meeting Conducted | C45: 36 | D45: 15 | E45: 51
B46: Follow-Up | C46: 19 | D46: 17 | E46: 36
B47: Details Shared | C47: 120 | D47: 285 | E47: 405
B48: Connected | C48: 217 | D48: 341 | E48: 558
B49: Attempt 1 | C49: 210 | D49: 639 | E49: 849
B50: Attempt 2 | C50: 117 | D50: 184 | E50: 301
B51: Attempt 3 | C51: 21 | D51: 56 | E51: 77
B52: Attempt 4 | C52: 25 | D52: 24 | E52: 49
B53: Attempt 5 | C53: 13 | D53: 20 | E53: 33
B54: New Lead | C54: 227 | D54: 352 | E54: 579
B55: Nurture | C55: 3 | D55: 5 | E55: 8
B56: Meeting Conducted but NOT QUALIFIED | C56: 1 | E56: 1
B57: Lost | C57: 243 | D57: 370 | E57: 613
B58: Negotiation | C58: 1 | E58: 1
B59: Grand Total | C59: 1285 | D59: 2342 | E59: 3627
B63: 3. LEAD STATUS FUNNEL - % of each campaign type's leads
B64: Record Type | C64: Lead
B66: Leads | C66: Campaign Type
B67: Lead Status | C67: Old | D67: New | E67: Grand Total
...

Sheet Executive Summary
A1: Natuf - Old vs New Campaigns: Lead Quality Comparison
A2: Period 01-Oct-2026 to 31-Oct-2026 | CRM status as of 31-Oct-2026 | Quality Lead = Won, Token Received, Qualified, Meeting Scheduled, Meeting Conducted, Follow-Up, Details Shared | All figures are live formulas on the Fact_Data / Lead_Data tabs
A4: KEY TAKEAWAYS
A5: SCALE - Old campaigns (window 31 days) spent ₹1,301,546 and generated 1,285 CRM leads. New campaigns (live 24 days, from 08-Oct) spent ₹345,560 on campaigns with Meta spend data and generated 2,342 CRM leads (1,377 of them from EBG - In House campaigns whose spend is not in the exports).
A6: COST - Cost per lead (campaigns with spend data): Old ₹1,013 vs New ₹358 (-65%). Cost per Quality Lead: Old ₹6,288 vs New ₹2,215 (-65%).
A7: QUALITY RATE - Quality leads are 16.1% of Old leads vs 15.0% of New leads (-1.1 pp). Counting only leads already worked (status other than 'New Lead'): Old 19.6% vs New 17.6%.
A8: LIKE-FOR-LIKE - 352 New-campaign leads (15.0%) are still un-actioned ('New Lead') vs 227 (17.7%) for Old. On leads created in the same window (08-Oct to 31-Oct), quality is 15.0% for New vs 13.7% for Old (+1.3 pp) - the fairest like-for-like view.
A9: DEEP FUNNEL - Won / Token / Qualified / Meeting Scheduled / Meeting Conducted: Old 68 (5.3% of leads) vs New 49 (2.1%). Lost: Old 18.9% vs New 15.8%.
A10: NOTE - ₹31,960 of spend sits on 2 campaign(s) with Meta spend but no CRM leads (web landing-page / WhatsApp-conversation campaigns: E_Natuf_Web_23092026, Natuf | ABO | WhatsApp | Unit Franchise | India | Oct26 | V1). It is kept in spend, so CPL / CPQL for that group are slightly overstated.
A11: DATA SCOPE - LeadData_October2026 holds 28,939 rows (28,937 unique leads, all brands); 3,627 belong to Natuf campaigns (used here). 35 Natuf-brand rows are excluded and 57 Natuf-campaign leads tagged to other brands are listed on XBrand_Leads - see Reconciliation / Notes.
A13: 1. HEADLINE KPIs (Old vs New)
A14: Metric | B14: Old | C14: New | D14: Total (all Natuf) | E14: New vs Old | F14: Definition
A15: Ad spend (INR) | B15: =SUMIFS(fSpend,fType,B$14) -> 1301546.3 | C15: =SUMIFS(fSpend,fType,C$14) -> 345559.94 | D15: =SUM(fSpend) -> 1647106.2 | E15: =IFERROR(C15/B15-1,"-") -> -0.73450047 | F15: Meta amount spent (campaign file = sum of ad sets).
A16: Impressions | B16: =SUMIFS(fImpr,fType,B$14) -> 1771115 | C16: =SUMIFS(fImpr,fType,C$14) -> 2355759 | D16: =SUM(fImpr) -> 4126874 | E16: =IFERROR(C16/B16-1,"-") -> 0.3300994 | F16: Meta impressions.
A17: Link clicks | B17: =SUMIFS(fClicks,fType,B$14) -> 20173 | C17: =SUMIFS(fClicks,fType,C$14) -> 14032 | D17: =SUM(fClicks) -> 34205 | E17: =IFERROR(C17/B17-1,"-") -> -0.30441679 | F17: Meta link clicks.
A18: CTR (link) | B18: =IFERROR(B17/B16,0) -> 0.01139 | C18: =IFERROR(C17/C16,0) -> 0.0059564667 | D18: =IFERROR(D17/D16,0) -> 0.0082883558 | E18: =IFERROR((C18-B18)*100,"-") -> -0.54335334 | F18: Link clicks / impressions.
A19: CPM (INR) | B19: =IFERROR(B15/B16*1000,0) -> 734.87397 | C19: =IFERROR(C15/C16*1000,0) -> 146.68731 | D19: =IFERROR(D15/D16*1000,0) -> 399.11716 | E19: =IFERROR(C19/B19-1,"-") -> -0.80039121 | F19: Spend per 1,000 impressions.
A20: CPC - link (INR) | B20: =IFERROR(B15/B17,0) -> 64.519224 | C20: =IFERROR(C15/C17,0) -> 24.626564 | D20: =IFERROR(D15/D17,0) -> 48.153961 | E20: =IFERROR(C20/B20-1,"-") -> -0.61830658 | F20: Spend per link click.
A21: Meta-reported results (lead forms + WhatsApp conversations) | B21: =SUMIFS(fMeta,fType,B$14) -> 1602 | C21: =SUMIFS(fMeta,fType,C$14) -> 2556 | D21: =SUM(fMeta) -> 4158 | E21: =IFERROR(C21/B21-1,"-") -> 0.59550562 | F21: Meta "Results": instant-form leads and WhatsApp conversations started. Web landing-page-views are excluded.
A22: Cost per Meta result (INR) | B22: =IFERROR(B15/B21,0) -> 812.45088 | C22: =IFERROR(C15/C21,0) -> 135.19559 | D22: =IFERROR(D15/D21,0) -> 396.12945 | E22: =IFERROR(C22/B22-1,"-") -> -0.83359536 | F22: Spend / Meta results (spend of the web landing-page campaign included in spend).
A23: CRM leads (Natuf campaigns) | B23: =SUMIFS(fLeads,fType,B$14) -> 1285 | C23: =SUMIFS(fLeads,fType,C$14) -> 2342 | D23: =SUM(fLeads) -> 3627 | E23: =IFERROR(C23/B23-1,"-") -> 0.82256809 | F23: Lead records in the CRM attributed to the campaigns (recovered via ad-set name where the CRM campaign was blank).
A24: CRM capture rate (CRM leads of Meta campaigns / Meta results) | B24: =IFERROR(SUMIFS(fCLeads,fType,B$14)/B21,0) -> 0.80212235 | C24: =IFERROR(SUMIFS(fCLeads,fType,C$14)/C21,0) -> 0.37754304 | D24: =IFERROR(SUM(fCLeads)/D21,0) -> 0.54112554 | E24: =IFERROR((C24-B24)*100,"-") -> -42.457931 | F24: How much of what Meta reports reached the CRM pipeline (leads of EBG - In House campaigns excluded: no Meta data).
A25: Cost per CRM lead - CPL (INR) | B25: =IFERROR(B15/SUMIFS(fCLeads,fType,B$14),0) -> 1012.8765 | C25: =IFERROR(C15/SUMIFS(fCLeads,fType,C$14),0) -> 358.0932 | D25: =IFERROR(D15/SUM(fCLeads),0) -> 732.04722 | E25: =IFERROR(C25/B25-1,"-") -> -0.64645917 | F25: Ad spend / CRM leads of campaigns that have Meta spend data.
A26: Contacted leads | B26: =SUMIFS(fContacted,fType,B$14) -> 1058 | C26: =SUMIFS(fContacted,fType,C$14) -> 1990 | D26: =SUM(fContacted) -> 3048 | E26: =IFERROR(C26/B26-1,"-") -> 0.88090737 | F26: Leads whose status is anything other than "New Lead".
A27: Contacted % | B27: =IFERROR(B26/B23,0) -> 0.8233463 | C27: =IFERROR(C26/C23,0) -> 0.84970111 | D27: =IFERROR(D26/D23,0) -> 0.84036394 | E27: =IFERROR((C27-B27)*100,"-") -> 2.6354807 | F27: Contacted / CRM leads (indicates sales follow-up speed).
A28: Calls per lead | B28: =IFERROR(SUMIFS(fCalls,fType,B$14)/B23,0) -> 2.9027237 | C28: =IFERROR(SUMIFS(fCalls,fType,C$14)/C23,0) -> 1.9355252 | D28: =IFERROR(SUM(fCalls)/D23,0) -> 2.2781913 | E28: =IFERROR(C28/B28-1,"-") -> -0.33320379 | F28: Total calls made / CRM leads.
A29: Call connect rate | B29: =IFERROR(SUMIFS(fConn,fType,B$14)/SUMIFS(fCalls,fType,B$14),0) -> 0.43485255 | C29: =IFERROR(SUMIFS(fConn,fType,C$14)/SUMIFS(fCalls,fType,C$14),0) -> 0.46878447 | D29: =IFERROR(SUM(fConn)/SUM(fCalls),0) -> 0.45346726 | E29: =IFERROR((C29-B29)*100,"-") -> 3.3931923 | F29: Connected calls / total calls.
A30: QUALITY LEADS | B30: =SUMIFS(fQual,fType,B$14) -> 207 | C30: =SUMIFS(fQual,fType,C$14) -> 351 | D30: =SUM(fQual) -> 558 | E30: =IFERROR(C30/B30-1,"-") -> 0.69565217 | F30: Status in {Won, Token Received, Qualified, Meeting Scheduled, Meeting Conducted, Follow-Up, Details Shared}.
A31: Quality % (of all leads) | B31: =IFERROR(B30/B23,0) -> 0.16108949 | C31: =IFERROR(C30/C23,0) -> 0.1498719 | D31: =IFERROR(D30/D23,0) -> 0.15384615 | E31: =IFERROR((C31-B31)*100,"-") -> -1.121759 | F31: Quality leads / CRM leads.
A32: Quality % of contacted leads | B32: =IFERROR(B30/B26,0) -> 0.19565217 | C32: =IFERROR(C30/C26,0) -> 0.17638191 | D32: =IFERROR(D30/D26,0) -> 0.18307087 | E32: =IFERROR((C32-B32)*100,"-") -> -1.9270264 | F32: Quality leads / contacted leads - removes the effect of leads not yet worked.
A33: COST PER QUALITY LEAD - CPQL (INR) | B33: =IFERROR(B15/SUMIFS(fCQual,fType,B$14),0) -> 6287.6633 | C33: =IFERROR(C15/SUMIFS(fCQual,fType,C$14),0) -> 2215.1278 | D33: =IFERROR(D15/SUM(fCQual),0) -> 4537.4828 | E33: =IFERROR(C33/B33-1,"-") -> -0.64770254 | F33: Ad spend / quality leads of campaigns that have Meta spend data.
A34: Lost leads | B34: =SUMIFS(fLost,fType,B$14) -> 243 | C34: =SUMIFS(fLost,fType,C$14) -> 370 | D34: =SUM(fLost) -> 613 | E34: =IFERROR(C34/B34-1,"-") -> 0.52263374 | F34: Status = Lost.
A35: Lost % | B35: =IFERROR(B34/B23,0) -> 0.18910506 | C35: =IFERROR(C34/C23,0) -> 0.15798463 | D35: =IFERROR(D34/D23,0) -> 0.1690102 | E35: =IFERROR((C35-B35)*100,"-") -> -3.112043 | F35: Lost / CRM leads.
A36: Un-actioned leads (status "New Lead") | B36: =COUNTIFS(ldType,B$14,ldStatus,"New Lead") -> 227 | C36: =COUNTIFS(ldType,C$14,ldStatus,"New Lead") -> 352 | D36: =COUNTIFS(ldStatus,"New Lead") -> 579 | E36: =IFERROR(C36/B36-1,"-") -> 0.55066079 | F36: Leads not yet touched by sales as of 31-Oct.
A37: Un-actioned % | B37: =IFERROR(B36/B23,0) -> 0.1766537 | C37: =IFERROR(C36/C23,0) -> 0.15029889 | D37: =IFERROR(D36/D23,0) -> 0.15963606 | E37: =IFERROR((C37-B37)*100,"-") -> -2.6354807 | F37: Higher = quality rate still immature.
A38: Days in market (in window) | B38: =DaysOld -> 31 | C38: =DaysNew -> 24 | D38: ="" | F38: Settings tab. Old: 01-Oct to 31-Oct; New (campaigns with Meta data): 08-Oct to 31-Oct.
A39: Avg daily ad spend (INR) | B39: =IFERROR(B15/B38,0) -> 41985.365 | C39: =IFERROR(C15/C38,0) -> 14398.331 | D39: ="" | E39: =IFERROR(C39/B39-1,"-") -> -0.6570631 | F39: Spend / days in market.
A40: Avg daily CRM leads | B40: =IFERROR(B23/B38,0) -> 41.451613 | C40: =IFERROR(C23/C38,0) -> 97.583333 | D40: ="" | E40: =IFERROR(C40/B40-1,"-") -> 1.3541505 | F40: CRM leads / days in market.
A41: Avg daily quality leads | B41: =IFERROR(B30/B38,0) -> 6.6774194 | C41: =IFERROR(C30/C38,0) -> 14.625 | D41: ="" | E41: =IFERROR(C41/B41-1,"-") -> 1.1902174 | F41: Quality leads / days in market (New is still maturing).
A42: New vs Old: relative change for volumes / costs, percentage-point (pp) change for rates. Green = New better, red = New worse (colour only on rate and cost metrics). "Total (all Natuf)" also contains Unattributed leads.
...

Sheet Reconciliation
A1: Reconciliation & Data Integrity Checks
A2: Source figures are computed directly from the raw files provided (pandas, independent of the workbook); report figures are live formulas on the workbook tabs. Status = OK when difference is zero.
A4: # | B4: Check | C4: Source file value | D4: Report value | E4: Difference | F4: Status | G4: Comment
A5: 1 | B5: CRM rows in LeadData_October2026.csv (all brands) = duplicate rows + in-scope + excluded + cross-brand + other-brand records | C5: 28939 | D5: =2+COUNTA(Lead_Data!A2:A3628)+COUNTA(Excluded_Leads!A2:A36)+COUNTA(XBrand_Leads!A2:A58)+25218 -> 28939 | E5: =ROUND(D5-C5,2) -> 0 | F5: =IF(ABS(E5)<=0.005,"OK","SEE NOTE") -> OK | G5: 28,939 rows: 2 duplicate Lead id rows removed + 3,627 Natuf-campaign leads + 35 excluded Natuf-brand rows + 57 cross-brand + 25,218 other-brand records
A6: 2 | B6: In-scope leads = Old + New + Unattributed | C6: 3627 | D6: =COUNTIF(ldType,"Old")+COUNTIF(ldType,"New")+COUNTIF(ldType,"Unattributed") -> 3627 | E6: =ROUND(D6-C6,2) -> 0 | F6: =IF(ABS(E6)<=0.005,"OK","SEE NOTE") -> OK | G6: Every in-scope lead is classified
A7: 3 | B7: Fact_Data lead rows = Lead_Data rows | C7: 3627 | D7: =COUNTIF(fRT,"Lead") -> 3627 | E7: =ROUND(D7-C7,2) -> 0 | F7: =IF(ABS(E7)<=0.005,"OK","SEE NOTE") -> OK | G7: Pivot source table vs lead list
A8: 4 | B8: Fact_Data quality leads = Lead_Data quality leads | C8: 558 | D8: =COUNTIF(ldQual,"Quality Lead") -> 558 | E8: =ROUND(D8-C8,2) -> 0 | F8: =IF(ABS(E8)<=0.005,"OK","SEE NOTE") -> OK | G8: Quality = status in the Settings list
A9: 5 | B9: Quality-status records among all Natuf-brand rows in the CRM file = in-scope + excluded | C9: 558 | D9: =COUNTIF(ldQual,"Quality Lead")+COUNTIF(Excluded_Leads!H2:H36,"Yes") -> 558 | E9: =ROUND(D9-C9,2) -> 0 | F9: =IF(ABS(E9)<=0.005,"OK","SEE NOTE") -> OK | G9: Every quality record of the brand is accounted for
A10: 6 | B10: Leads with no campaign tag kept as Unattributed | C10: 0 | D10: =COUNTIF(ldType,"Unattributed") -> 0 | E10: =ROUND(D10-C10,2) -> 0 | F10: =IF(ABS(E10)<=0.005,"OK","SEE NOTE") -> OK | G10: Paid / WhatsApp-API leads with campaign blank - shown as Unattributed, not forced into Old/New
A11: 7 | B11: Bulk / manual (Excel) uploads with no campaign - excluded | C11: 34 | D11: =COUNTIF(Excluded_Leads!I2:I36,"No campaign*") -> 34 | E11: =ROUND(D11-C11,2) -> 0 | F11: =IF(ABS(E11)<=0.005,"OK","SEE NOTE") -> OK | G11: Not campaign leads (lead source = Excel)
A12: 8 | B12: Ad spend: campaign file total (INR) | C12: 1647106.2 | D12: =SUM(fSpend) -> 1647106.2 | E12: =ROUND(D12-C12,2) -> 0 | F12: =IF(ABS(E12)<=0.005,"OK","SEE NOTE") -> OK | G12: Fact_Data spend rows (one per campaign) sum to the Meta campaign file
A13: 9 | B13: Ad spend: ad-set file total (INR) | C13: 1647106.2 | D13: =SUM(fSpend) -> 1647106.2 | E13: =ROUND(D13-C13,2) -> 0 | F13: =IF(ABS(E13)<=0.005,"OK","SEE NOTE") -> OK | G13: Campaign file = ad-set file = report
A14: 10 | B14: Ad spend: sum of ad sets mapped to campaigns vs campaign file (Campaign_Master total difference) | C14: 0 | D14: =Campaign_Master!J34 -> 0 | E14: =ROUND(D14-C14,2) -> 0 | F14: =IF(ABS(E14)<=0.005,"OK","SEE NOTE") -> OK | G14: Inferred ad-set to campaign mapping reproduces every campaign total exactly (spend, impressions, results)
A15: 11 | B15: Impressions: campaign file total | C15: 4126874 | D15: =SUM(fImpr) -> 4126874 | E15: =ROUND(D15-C15,2) -> 0 | F15: =IF(ABS(E15)<=0.005,"OK","SEE NOTE") -> OK
A16: 12 | B16: Link clicks: campaign file total | C16: 34205 | D16: =SUM(fClicks) -> 34205 | E16: =ROUND(D16-C16,2) -> 0 | F16: =IF(ABS(E16)<=0.005,"OK","SEE NOTE") -> OK | G16: Report uses campaign-file clicks (the ad-set export sums to 0 more in places)
A17: 13 | B17: Meta lead-type results (campaign file, excl. landing-page-view campaigns) | C17: 4158 | D17: =SUM(fMeta) -> 4158 | E17: =ROUND(D17-C17,2) -> 0 | F17: =IF(ABS(E17)<=0.005,"OK","SEE NOTE") -> OK | G17: Web campaigns report landing page views, not leads
A18: 14 | B18: Ad-level file spend (INR) vs campaign file | C18: 1647106.2 | D18: 1641571.9 | E18: =ROUND(D18-C18,2) -> -5534.4 | F18: INFO | G18: Ad-level export may miss deleted / archived ads and repeats ad names across ad sets - ad-level spend is NOT used; spend is reported at campaign level
A19: 15 | B19: Dashboard grand-total leads = Lead_Data leads | C19: 3627 | D19: ='Master Dashboard'!E54 -> 3627 | E19: =ROUND(D19-C19,2) -> 0 | F19: =IF(ABS(E19)<=0.005,"OK","SEE NOTE") -> OK | G19: Dashboard ties to the lead list
A20: 16 | B20: Leads created outside the reporting window (01-Oct to 31-Oct) | C20: 0 | D20: =COUNTIF(ldDate,"<"&WinStart)+COUNTIF(ldDate,">"&WinEnd) -> 0 | E20: =ROUND(D20-C20,2) -> 0 | F20: =IF(ABS(E20)<=0.005,"OK","SEE NOTE") -> OK | G20: Lead export covers exactly the window
A21: 17 | B21: Natuf-campaign leads tagged to OTHER brands in CRM (listed, not counted) | C21: 57 | D21: =COUNTA(XBrand_Leads!A2:A58) -> 57 | E21: =ROUND(D21-C21,2) -> 0 | F21: =IF(ABS(E21)<=0.005,"OK","SEE NOTE") -> OK | G21: Reported separately on XBrand_Leads; their status belongs to another brand pipeline
A23: LEAD FLOW - from raw file to report
B24: Rows in LeadData_October2026.csv (all brands) | C24: 28939
B25: less: duplicate Lead id rows (same lead exported twice) | C25: 2
B26: less: other brands' records (not a Natuf brand and not on a Natuf campaign) | C26: 25218
B27: less: Natuf-brand rows excluded (bulk upload / other-brand campaign) | C27: 35
B28: less: Natuf-campaign leads tagged to other brands (XBrand_Leads) | C28: 57
B29: Natuf-campaign leads used in the report (total) | C29: 3627
B30: of which Old campaigns | C30: 1285
B31: of which New campaigns | C31: 2342
B32: of which Unattributed | C32: 0
B33: memo: New-campaign leads from EBG - In House campaigns (no Meta spend data) | C33: 1377
B35: No separate Lead Center export was supplied for this period; LeadData_October2026.csv (CRM export, one row per Lead id) is the single lead source. The previous reports' Lead Center reconciliation and Performance-Report cross-checks are therefore not repeated.

Sheet Notes
B1: Notes, Definitions & Assumptions - Natuf
B3: HOW TO READ THIS WORKBOOK
B4: • Master Dashboard: the one-page management view (formula-driven): Old vs New headline KPIs, quality parameters, and a campaign-wise table with type, spend, leads, quality count, quality %, CPL and CPQL. Master Pivot: real PivotTables + slicers (Campaign Type, Campaign, Lead Status, Month, Week) plus the Campaign x Quality Parameter table at the bottom. Meta spend cannot be split by status / month / week, so spend shows as "-" when those slicers are used.
B5: • Executive Summary: takeaways, Old-vs-New KPI table, status funnel, same-age cohort and campaign scorecard - all live formulas.
B6: • Reconciliation: every figure tied back to the raw files. Campaign_Master: Old/New classification (editable). Data tabs: Fact_Data (pivot source), Lead_Data, Excluded_Leads, XBrand_Leads, Meta_* (raw Meta exports), Settings.
B7: DEFINITIONS
B8: • Quality Lead = lead whose CRM Status is one of: Won, Token Received, Qualified, Meeting Scheduled, Meeting Conducted, Follow-Up, Details Shared (editable on Settings). "Meeting Conducted but NOT QUALIFIED" is not a quality status.
B9: • Old / New: a campaign is NEW if its name carries 'Oct26' - the new October-2026 campaign structure (ABO campaigns in the Kustard ad account and the 'EBG - In House ... Oct26' campaigns in the In-House ad account). Every other campaign is Old. Editable on Campaign_Master.
B10: • CRM leads = lead records in the CRM (one row per Lead id). Contacted = status other than "New Lead". Quality % = Quality leads / CRM leads. CPL = ad spend / CRM leads. CPQL = ad spend / Quality leads.
B11: • Meta results = instant-form leads (leadgen) plus WhatsApp conversations started. Web landing-page campaigns report landing page views (not leads) - excluded from results but their spend is included in spend.
B12: DATA TREATMENT & FINDINGS
B13: • REPORTING WINDOW: the Meta exports (campaigns, ad sets, ads) and LeadData_October2026.csv cover 01-Oct-2026 to 31-Oct-2026 only (the CRM export was taken on 31-Oct, last lead created 31-Oct 12:56). September is not in the supplied files, so this report compares Old vs New on October data; it is not cumulative with the earlier 01-Sep to 18-Oct report.
... B23: • Phone numbers are masked and names / e-mails are not included in this workbook.

Sheet Campaign_Master
A1: Campaign | B1: Campaign Type (EDITABLE: Old / New) | C1: Basis for classification | D1: Meta delivery | E1: Result type | F1: Budget (INR/day) | G1: Earliest ad-set start | H1: Spend - campaign file (INR) | I1: Spend - sum of ad sets (INR) | J1: Difference | K1: CRM leads (in report) | L1: Quality leads | M1: Spend data
A2: GenY-Natuf-LeadGen-10032026 | B2: Old | C2: Old: all campaigns other than the Oct26 campaigns are Old | D2: inactive | F2: ad set budget | H2: =SUMIFS(Meta_Campaigns!$G$2:$G$29,Meta_Campaigns!$A$2:$A$29,A2) -> 0 | I2: =SUMIFS(Meta_AdSets!$G$2:$G$93,Meta_AdSets!$B$2:$B$93,A2) -> 0 | J2: =ROUND(H2-I2,2) -> 0 | K2: =SUMIFS(fLeads,fCampaign,A2) -> 0 | L2: =SUMIFS(fQual,fCampaign,A2) -> 0 | M2: =IF(COUNTIF(MetaCamps,A2)>0,"In Meta export","NOT in Meta export (spend n/a)") -> In Meta export
A3: E_Karan_Natuf_Kiosk_07072026 | B3: Old | C3: Old: all campaigns other than the Oct26 campaigns are Old | D3: inactive | E3: leadgen.other | F3: 5000 | G3: 46210 | H3: =SUMIFS(Meta_Campaigns!$G$2:$G$29,Meta_Campaigns!$A$2:$A$29,A3) -> 54540.16 | I3: =SUMIFS(Meta_AdSets!$G$2:$G$93,Meta_AdSets!$B$2:$B$93,A3) -> 54540.16 | J3: =ROUND(H3-I3,2) -> 0 | K3: =SUMIFS(fLeads,fCampaign,A3) -> 24 | L3: =SUMIFS(fQual,fCampaign,A3) -> 6 | M3: =IF(COUNTIF(MetaCamps,A3)>0,"In Meta export","NOT in Meta export (spend n/a)") -> In Meta export
A4: E_Suresh_Natuf_Kiosk_07072026 | B4: Old | C4: Old: all campaigns other than the Oct26 campaigns are Old | D4: inactive | E4: leadgen.other | F4: 10000 | G4: 46211 | H4: =SUMIFS(Meta_Campaigns!$G$2:$G$29,Meta_Campaigns!$A$2:$A$29,A4) -> 232416.42 | I4: =SUMIFS(Meta_AdSets!$G$2:$G$93,Meta_AdSets!$B$2:$B$93,A4) -> 232416.42 | J4: =ROUND(H4-I4,2) -> 0 | K4: =SUMIFS(fLeads,fCampaign,A4) -> 313 | L4: =SUMIFS(fQual,fCampaign,A4) -> 68 | M4: =IF(COUNTIF(MetaCamps,A4)>0,"In Meta export","NOT in Meta export (spend n/a)") -> In Meta export
A5: E_Aryan_Natuf_Kiosk_07072026 | B5: Old | C5: Old: all campaigns other than the Oct26 campaigns are Old | D5: inactive | F5: 12000 | H5: =SUMIFS(Meta_Campaigns!$G$2:$G$29,Meta_Campaigns!$A$2:$A$29,A5) -> 0 | I5: =SUMIFS(Meta_AdSets!$G$2:$G$93,Meta_AdSets!$B$2:$B$93,A5) -> 0 | J5: =ROUND(H5-I5,2) -> 0 | K5: =SUMIFS(fLeads,fCampaign,A5) -> 0 | L5: =SUMIFS(fQual,fCampaign,A5) -> 0 | M5: =IF(COUNTIF(MetaCamps,A5)>0,"In Meta export","NOT in Meta export (spend n/a)") -> In Meta export
A6: E_Selva_Natuf_Kiosk_07072026 | B6: Old | C6: Old: all campaigns other than the Oct26 campaigns are Old | D6: inactive | F6: 3000 | H6: =SUMIFS(Meta_Campaigns!$G$2:$G$29,Meta_Campaigns!$A$2:$A$29,A6) -> 0 | I6: =SUMIFS(Meta_AdSets!$G$2:$G$93,Meta_AdSets!$B$2:$B$93,A6) -> 0 | J6: =ROUND(H6-I6,2) -> 0 | K6: =SUMIFS(fLeads,fCampaign,A6) -> 0 | L6: =SUMIFS(fQual,fCampaign,A6) -> 0 | M6: =IF(COUNTIF(MetaCamps,A6)>0,"In Meta export","NOT in Meta export (spend n/a)") -> In Meta export
A7: E_Karan_Natuf_All_07072026 | B7: Old | C7: Old: all campaigns other than the Oct26 campaigns are Old | D7: inactive | E7: leadgen.other | F7: 15000 | G7: 46210 | H7: =SUMIFS(Meta_Campaigns!$G$2:$G$29,Meta_Campaigns!$A$2:$A$29,A7) -> 277596.99 | I7: =SUMIFS(Meta_AdSets!$G$2:$G$93,Meta_AdSets!$B$2:$B$93,A7) -> 277596.99 | J7: =ROUND(H7-I7,2) -> 0 | K7: =SUMIFS(fLeads,fCampaign,A7) -> 229 | L7: =SUMIFS(fQual,fCampaign,A7) -> 21 | M7: =IF(COUNTIF(MetaCamps,A7)>0,"In Meta export","NOT in Meta export (spend n/a)") -> In Meta export
A8: E_Aryan_Natuf_All_07072026 | B8: Old | C8: Old: all campaigns other than the Oct26 campaigns are Old | D8: inactive | F8: 5000 | H8: =SUMIFS(Meta_Campaigns!$G$2:$G$29,Meta_Campaigns!$A$2:$A$29,A8) -> 0 | I8: =SUMIFS(Meta_AdSets!$G$2:$G$93,Meta_AdSets!$B$2:$B$93,A8) -> 0 | J8: =ROUND(H8-I8,2) -> 0 | K8: =SUMIFS(fLeads,fCampaign,A8) -> 0 | L8: =SUMIFS(fQual,fCampaign,A8) -> 0 | M8: =IF(COUNTIF(MetaCamps,A8)>0,"In Meta export","NOT in Meta export (spend n/a)") -> In Meta export
A9: E_Selva_Natuf_All_07072026 | B9: Old | C9: Old: all campaigns other than the Oct26 campaigns are Old | D9: inactive | E9: leadgen.other | F9: 10000 | G9: 46211 | H9: =SUMIFS(Meta_Campaigns!$G$2:$G$29,Meta_Campaigns!$A$2:$A$29,A9) -> 80349.25 | I9: =SUMIFS(Meta_AdSets!$G$2:$G$93,Meta_AdSets!$B$2:$B$93,A9) -> 80349.25 | J9: =ROUND(H9-I9,2) -> 0 | K9: =SUMIFS(fLeads,fCampaign,A9) -> 46 | L9: =SUMIFS(fQual,fCampaign,A9) -> 14 | M9: =IF(COUNTIF(MetaCamps,A9)>0,"In Meta export","NOT in Meta export (spend n/a)") -> In Meta export
A10: E_Suresh_Natuf_All_07072026 | B10: Old | C10: Old: all campaigns other than the Oct26 campaigns are Old | D10: inactive | F10: 3000 | H10: =SUMIFS(Meta_Campaigns!$G$2:$G$29,Meta_Campaigns!$A$2:$A$29,A10) -> 0 | I10: =SUMIFS(Meta_AdSets!$G$2:$G$93,Meta_AdSets!$B$2:$B$93,A10) -> 0 | J10: =ROUND(H10-I10,2) -> 0 | K10: =SUMIFS(fLeads,fCampaign,A10) -> 0 | L10: =SUMIFS(fQual,fCampaign,A10) -> 0 | M10: =IF(COUNTIF(MetaCamps,A10)>0,"In Meta export","NOT in Meta export (spend n/a)") -> In Meta export
A11: E_Natuf_Kiosk_07072026- WC-Priyanka | B11: Old | C11: Old: all campaigns other than the Oct26 campaigns are Old | D11: inactive | F11: 2000 | H11: =SUMIFS(Meta_Campaigns!$G$2:$G$29,Meta_Campaigns!$A$2:$A$29,A11) -> 0 | I11: =SUMIFS(Meta_AdSets!$G$2:$G$93,Meta_AdSets!$B$2:$B$93,A11) -> 0 | J11: =ROUND(H11-I11,2) -> 0 | K11: =SUMIFS(fLeads,fCampaign,A11) -> 0 | L11: =SUMIFS(fQual,fCampaign,A11) -> 0 | M11: =IF(COUNTIF(MetaCamps,A11)>0,"In Meta export","NOT in Meta export (spend n/a)") -> In Meta export
A12: natuf_Kiosk_14072026_Hindi | B12: Old | C12: Old: all campaigns other than the Oct26 campaigns are Old | D12: inactive | E12: leadgen.other | F12: 10000 | G12: 46217 | H12: =SUMIFS(Meta_Campaigns!$G$2:$G$29,Meta_Campaigns!$A$2:$A$29,A12) -> 180149.88 | I12: =SUMIFS(Meta_AdSets!$G$2:$G$93,Meta_AdSets!$B$2:$B$93,A12) -> 180149.88 | J12: =ROUND(H12-I12,2) -> 0 | K12: =SUMIFS(fLeads,fCampaign,A12) -> 382 | L12: =SUMIFS(fQual,fCampaign,A12) -> 42 | M12: =IF(COUNTIF(MetaCamps,A12)>0,"In Meta export","NOT in Meta export (spend n/a)") -> In Meta export
A13: natuf_Kiosk_14072026 – WC | B13: Old | C13: Old: all campaigns other than the Oct26 campaigns are Old | D13: inactive | F13: 1000 | H13: =SUMIFS(Meta_Campaigns!$G$2:$G$29,Meta_Campaigns!$A$2:$A$29,A13) -> 0 | I13: =SUMIFS(Meta_AdSets!$G$2:$G$93,Meta_AdSets!$B$2:$B$93,A13) -> 0 | J13: =ROUND(H13-I13,2) -> 0 | K13: =SUMIFS(fLeads,fCampaign,A13) -> 0 | L13: =SUMIFS(fQual,fCampaign,A13) -> 0 | M13: =IF(COUNTIF(MetaCamps,A13)>0,"In Meta export","NOT in Meta export (spend n/a)") -> In Meta export
A14: E_Natuf_Kiosk_07072026- WC – Telugu | B14: Old | C14: Old: all campaigns other than the Oct26 campaigns are Old | D14: inactive | F14: 1000 | H14: =SUMIFS(Meta_Campaigns!$G$2:$G$29,Meta_Campaigns!$A$2:$A$29,A14) -> 0 | I14: =SUMIFS(Meta_AdSets!$G$2:$G$93,Meta_AdSets!$B$2:$B$93,A14) -> 0 | J14: =ROUND(H14-I14,2) -> 0 | K14: =SUMIFS(fLeads,fCampaign,A14) -> 0 | L14: =SUMIFS(fQual,fCampaign,A14) -> 0 | M14: =IF(COUNTIF(MetaCamps,A14)>0,"In Meta export","NOT in Meta export (spend n/a)") -> In Meta export
A15: Natuf_Carpo_Gift_Usha | B15: Old | C15: Old: all campaigns other than the Oct26 campaigns are Old | D15: inactive | F15: 2000 | H15: =SUMIFS(Meta_Campaigns!$G$2:$G$29,Meta_Campaigns!$A$2:$A$29,A15) -> 0 | I15: =SUMIFS(Meta_AdSets!$G$2:$G$93,Meta_AdSets!$B$2:$B$93,A15) -> 0 | J15: =ROUND(H15-I15,2) -> 0 | K15: =SUMIFS(fLeads,fCampaign,A15) -> 0 | L15: =SUMIFS(fQual,fCampaign,A15) -> 0 | M15: =IF(COUNTIF(MetaCamps,A15)>0,"In Meta export","NOT in Meta export (spend n/a)") -> In Meta export
A16: E_Natuf_Kiosk_10082026 | B16: Old | C16: Old: all campaigns other than the Oct26 campaigns are Old | D16: inactive | F16: 5000 | H16: =SUMIFS(Meta_Campaigns!$G$2:$G$29,Meta_Campaigns!$A$2:$A$29,A16) -> 0 | I16: =SUMIFS(Meta_AdSets!$G$2:$G$93,Meta_AdSets!$B$2:$B$93,A16) -> 0 | J16: =ROUND(H16-I16,2) -> 0 | K16: =SUMIFS(fLeads,fCampaign,A16) -> 0 | L16: =SUMIFS(fQual,fCampaign,A16) -> 0 | M16: =IF(COUNTIF(MetaCamps,A16)>0,"In Meta export","NOT in Meta export (spend n/a)") -> In Meta export
A17: E_Natuf_Generic_13082026 | B17: Old | C17: Old: all campaigns other than the Oct26 campaigns are Old | D17: inactive | E17: leadgen.other | F17: ad set budget | G17: 46247 | H17: =SUMIFS(Meta_Campaigns!$G$2:$G$29,Meta_Campaigns!$A$2:$A$29,A17) -> 233578.47 | I17: =SUMIFS(Meta_AdSets!$G$2:$G$93,Meta_AdSets!$B$2:$B$93,A17) -> 233578.47 | J17: =ROUND(H17-I17,2) -> 0 | K17: =SUMIFS(fLeads,fCampaign,A17) -> 210 | L17: =SUMIFS(fQual,fCampaign,A17) -> 40 | M17: =IF(COUNTIF(MetaCamps,A17)>0,"In Meta export","NOT in Meta export (spend n/a)") -> In Meta export
A18: E_Natuf_MF_05092026 | B18: Old | C18: Old: all campaigns other than the Oct26 campaigns are Old | D18: inactive | E18: leadgen.other | F18: 5000 | G18: 46270 | H18: =SUMIFS(Meta_Campaigns!$G$2:$G$29,Meta_Campaigns!$A$2:$A$29,A18) -> 79772.24 | I18: =SUMIFS(Meta_AdSets!$G$2:$G$93,Meta_AdSets!$B$2:$B$93,A18) -> 79772.24 | J18: =ROUND(H18-I18,2) -> 0 | K18: =SUMIFS(fLeads,fCampaign,A18) -> 26 | L18: =SUMIFS(fQual,fCampaign,A18) -> 1 | M18: =IF(COUNTIF(MetaCamps,A18)>0,"In Meta export","NOT in Meta export (spend n/a)") -> In Meta export
A19: E_Natuf_Generic_09092026 | B19: Old | C19: Old: all campaigns other than the Oct26 campaigns are Old | D19: inactive | E19: leadgen.other | F19: ad set budget | G19: 46275 | H19: =SUMIFS(Meta_Campaigns!$G$2:$G$29,Meta_Campaigns!$A$2:$A$29,A19) -> 71194.81 | I19: =SUMIFS(Meta_AdSets!$G$2:$G$93,Meta_AdSets!$B$2:$B$93,A19) -> 71194.81 | J19: =ROUND(H19-I19,2) -> 0 | K19: =SUMIFS(fLeads,fCampaign,A19) -> 8 | L19: =SUMIFS(fQual,fCampaign,A19) -> 2 | M19: =IF(COUNTIF(MetaCamps,A19)>0,"In Meta export","NOT in Meta export (spend n/a)") -> In Meta export
A20: E_Natuf_Foco_10092026 | B20: Old | C20: Old: all campaigns other than the Oct26 campaigns are Old | D20: inactive | E20: leadgen.other | F20: ad set budget | G20: 46276 | H20: =SUMIFS(Meta_Campaigns!$G$2:$G$29,Meta_Campaigns!$A$2:$A$29,A20) -> 46413.52 | I20: =SUMIFS(Meta_AdSets!$G$2:$G$93,Meta_AdSets!$B$2:$B$93,A20) -> 46413.52 | J20: =ROUND(H20-I20,2) -> 0 | K20: =SUMIFS(fLeads,fCampaign,A20) -> 32 | L20: =SUMIFS(fQual,fCampaign,A20) -> 7 | M20: =IF(COUNTIF(MetaCamps,A20)>0,"In Meta export","NOT in Meta export (spend n/a)") -> In Meta export
A21: E_Natuf_Web_23092026 | B21: Old | C21: Old: all campaigns other than the Oct26 campaigns are Old | D21: inactive | E21: omni_landing_page_view | F21: 500 | G21: 46288 | H21: =SUMIFS(Meta_Campaigns!$G$2:$G$29,Meta_Campaigns!$A$2:$A$29,A21) -> 6412.86 | I21: =SUMIFS(Meta_AdSets!$G$2:$G$93,Meta_AdSets!$B$2:$B$93,A21) -> 6412.86 | J21: =ROUND(H21-I21,2) -> 0 | K21: =SUMIFS(fLeads,fCampaign,A21) -> 0 | L21: =SUMIFS(fQual,fCampaign,A21) -> 0 | M21: =IF(COUNTIF(MetaCamps,A21)>0,"In Meta export","NOT in Meta export (spend n/a)") -> In Meta export
A22: E_Natuf_Amazon_29092026 | B22: Old | C22: Old: all campaigns other than the Oct26 campaigns are Old | D22: inactive | E22: leadgen.other | F22: 5000 | G22: 46294 | H22: =SUMIFS(Meta_Campaigns!$G$2:$G$29,Meta_Campaigns!$A$2:$A$29,A22) -> 39121.71 | I22: =SUMIFS(Meta_AdSets!$G$2:$G$93,Meta_AdSets!$B$2:$B$93,A22) -> 39121.71 | J22: =ROUND(H22-I22,2) -> 0 | K22: =SUMIFS(fLeads,fCampaign,A22) -> 15 | L22: =SUMIFS(fQual,fCampaign,A22) -> 6 | M22: =IF(COUNTIF(MetaCamps,A22)>0,"In Meta export","NOT in Meta export (spend n/a)") -> In Meta export
A23: ABO | Natuf | Leads | Unit Franchise | India | Oct26 | V1 | B23: New | C23: New: campaign name carries 'Oct26' (new Oct-2026 campaign structure, as defined by the business) | D23: active | E23: leadgen.other | F23: ad set budget | G23: 46303 | H23: =SUMIFS(Meta_Campaigns!$G$2:$G$29,Meta_Campaigns!$A$2:$A$29,A23) -> 264151.59 | I23: =SUMIFS(Meta_AdSets!$G$2:$G$93,Meta_AdSets!$B$2:$B$93,A23) -> 264151.59 | J23: =ROUND(H23-I23,2) -> 0 | K23: =SUMIFS(fLeads,fCampaign,A23) -> 817 | L23: =SUMIFS(fQual,fCampaign,A23) -> 149 | M23: =IF(COUNTIF(MetaCamps,A23)>0,"In Meta export","NOT in Meta export (spend n/a)") -> In Meta export
A24: EBG - In House | ABO | Natuf Website | Leads | Unit Franchise | India | Oct26 | V1 - Copy | B24: New | C24: New: campaign name carries 'Oct26' (new Oct-2026 campaign structure, as defined by the business) | D24: inactive | F24: ad set budget | H24: =SUMIFS(Meta_Campaigns!$G$2:$G$29,Meta_Campaigns!$A$2:$A$29,A24) -> 0 | I24: =SUMIFS(Meta_AdSets!$G$2:$G$93,Meta_AdSets!$B$2:$B$93,A24) -> 0 | J24: =ROUND(H24-I24,2) -> 0 | K24: =SUMIFS(fLeads,fCampaign,A24) -> 0 | L24: =SUMIFS(fQual,fCampaign,A24) -> 0 | M24: =IF(COUNTIF(MetaCamps,A24)>0,"In Meta export","NOT in Meta export (spend n/a)") -> In Meta export
A25: Natuf | ABO | WhatsApp | Unit Franchise | India | Oct26 | V1 | B25: New | C25: New: campaign name carries 'Oct26' (new Oct-2026 campaign structure, as defined by the business) | D25: active | E25: onsite_conversion.messaging_conversation_started_7d | F25: ad set budget | G25: 46312 | H25: =SUMIFS(Meta_Campaigns!$G$2:$G$29,Meta_Campaigns!$A$2:$A$29,A25) -> 25546.72 | I25: =SUMIFS(Meta_AdSets!$G$2:$G$93,Meta_AdSets!$B$2:$B$93,A25) -> 25546.72 | J25: =ROUND(H25-I25,2) -> 0 | K25: =SUMIFS(fLeads,fCampaign,A25) -> 0 | L25: =SUMIFS(fQual,fCampaign,A25) -> 0 | M25: =IF(COUNTIF(MetaCamps,A25)>0,"In Meta export","NOT in Meta export (spend n/a)") -> In Meta export
A26: ABO | Natuf | Leads | Master Franchise | India | Oct26 | V1 | B26: New | C26: New: campaign name carries 'Oct26' (new Oct-2026 campaign structure, as defined by the business) | D26: active | E26: leadgen.other | F26: ad set budget | G26: 46314 | H26: =SUMIFS(Meta_Campaigns!$G$2:$G$29,Meta_Campaigns!$A$2:$A$29,A26) -> 55861.63 | I26: =SUMIFS(Meta_AdSets!$G$2:$G$93,Meta_AdSets!$B$2:$B$93,A26) -> 55861.63 | J26: =ROUND(H26-I26,2) -> 0 | K26: =SUMIFS(fLeads,fCampaign,A26) -> 148 | L26: =SUMIFS(fQual,fCampaign,A26) -> 7 | M26: =IF(COUNTIF(MetaCamps,A26)>0,"In Meta export","NOT in Meta export (spend n/a)") -> In Meta export
A27: GenY-Natuf-LeadGen-09-04-26 | B27: Old | C27: Old: all campaigns other than the Oct26 campaigns are Old | D27: inactive | F27: ad set budget | H27: =SUMIFS(Meta_Campaigns!$G$2:$G$29,Meta_Campaigns!$A$2:$A$29,A27) -> 0 | I27: =SUMIFS(Meta_AdSets!$G$2:$G$93,Meta_AdSets!$B$2:$B$93,A27) -> 0 | J27: =ROUND(H27-I27,2) -> 0 | K27: =SUMIFS(fLeads,fCampaign,A27) -> 0 | L27: =SUMIFS(fQual,fCampaign,A27) -> 0 | M27: =IF(COUNTIF(MetaCamps,A27)>0,"In Meta export","NOT in Meta export (spend n/a)") -> In Meta export
A28: GenY-Natuf-LeadGen-09-04-26 –IF | B28: Old | C28: Old: all campaigns other than the Oct26 campaigns are Old | D28: inactive | F28: ad set budget | H28: =SUMIFS(Meta_Campaigns!$G$2:$G$29,Meta_Campaigns!$A$2:$A$29,A28) -> 0 | I28: =SUMIFS(Meta_AdSets!$G$2:$G$93,Meta_AdSets!$B$2:$B$93,A28) -> 0 | J28: =ROUND(H28-I28,2) -> 0 | K28: =SUMIFS(fLeads,fCampaign,A28) -> 0 | L28: =SUMIFS(fQual,fCampaign,A28) -> 0 | M28: =IF(COUNTIF(MetaCamps,A28)>0,"In Meta export","NOT in Meta export (spend n/a)") -> In Meta export
A29: GenY-Natuf-MasterFranchise-LeadGen-050526 | B29: Old | C29: Old: all campaigns other than the Oct26 campaigns are Old | D29: inactive | F29: ad set budget | H29: =SUMIFS(Meta_Campaigns!$G$2:$G$29,Meta_Campaigns!$A$2:$A$29,A29) -> 0 | I29: =SUMIFS(Meta_AdSets!$G$2:$G$93,Meta_AdSets!$B$2:$B$93,A29) -> 0 | J29: =ROUND(H29-I29,2) -> 0 | K29: =SUMIFS(fLeads,fCampaign,A29) -> 0 | L29: =SUMIFS(fQual,fCampaign,A29) -> 0 | M29: =IF(COUNTIF(MetaCamps,A29)>0,"In Meta export","NOT in Meta export (spend n/a)") -> In Meta export
A30: EBG - In House | ABO | Natuf | Leads | Master Franchise | India | Oct26 | V1 | B30: New | C30: New: campaign name carries 'Oct26' (new Oct-2026 campaign structure, as defined by the business) | D30: not in Meta export | H30: =SUMIFS(Meta_Campaigns!$G$2:$G$29,Meta_Campaigns!$A$2:$A$29,A30) -> 0 | I30: =SUMIFS(Meta_AdSets!$G$2:$G$93,Meta_AdSets!$B$2:$B$93,A30) -> 0 | J30: =ROUND(H30-I30,2) -> 0 | K30: =SUMIFS(fLeads,fCampaign,A30) -> 42 | L30: =SUMIFS(fQual,fCampaign,A30) -> 0 | M30: =IF(COUNTIF(MetaCamps,A30)>0,"In Meta export","NOT in Meta export (spend n/a)") -> NOT in Meta export (spend n/a)
A31: EBG - In House | ABO | Natuf | Leads | Unit Franchise | India | Oct26 | V1 | B31: New | C31: New: campaign name carries 'Oct26' (new Oct-2026 campaign structure, as defined by the business) | D31: not in Meta export | H31: =SUMIFS(Meta_Campaigns!$G$2:$G$29,Meta_Campaigns!$A$2:$A$29,A31) -> 0 | I31: =SUMIFS(Meta_AdSets!$G$2:$G$93,Meta_AdSets!$B$2:$B$93,A31) -> 0 | J31: =ROUND(H31-I31,2) -> 0 | K31: =SUMIFS(fLeads,fCampaign,A31) -> 1262 | L31: =SUMIFS(fQual,fCampaign,A31) -> 193 | M31: =IF(COUNTIF(MetaCamps,A31)>0,"In Meta export","NOT in Meta export (spend n/a)") -> NOT in Meta export (spend n/a)
A32: Natuf | In House | ABO | | WhatsApp | Unit Franchise | India | Oct26 | V1 | B32: New | C32: New: campaign name carries 'Oct26' (new Oct-2026 campaign structure, as defined by the business) | D32: not in Meta export | H32: =SUMIFS(Meta_Campaigns!$G$2:$G$29,Meta_Campaigns!$A$2:$A$29,A32) -> 0 | I32: =SUMIFS(Meta_AdSets!$G$2:$G$93,Meta_AdSets!$B$2:$B$93,A32) -> 0 | J32: =ROUND(H32-I32,2) -> 0 | K32: =SUMIFS(fLeads,fCampaign,A32) -> 73 | L32: =SUMIFS(fQual,fCampaign,A32) -> 2 | M32: =IF(COUNTIF(MetaCamps,A32)>0,"In Meta export","NOT in Meta export (spend n/a)") -> NOT in Meta export (spend n/a)
A33: (Unattributed) | B33: Unattributed | C33: No campaign tag in CRM (WhatsApp-API lead with blank campaign) - not forced into Old/New | D33: n/a | H33: =SUMIFS(Meta_Campaigns!$G$2:$G$29,Meta_Campaigns!$A$2:$A$29,A33) -> 0 | I33: =SUMIFS(Meta_AdSets!$G$2:$G$93,Meta_AdSets!$B$2:$B$93,A33) -> 0 | J33: =ROUND(H33-I33,2) -> 0 | K33: =SUMIFS(fLeads,fCampaign,A33) -> 0 | L33: =SUMIFS(fQual,fCampaign,A33) -> 0 | M33: =IF(COUNTIF(MetaCamps,A33)>0,"In Meta export","NOT in Meta export (spend n/a)") -> NOT in Meta export (spend n/a)
A34: TOTAL | H34: =SUM(H2:H33) -> 1647106.2 | I34: =SUM(I2:I33) -> 1647106.2 | J34: =SUM(J2:J33) -> 0 | K34: =SUM(K2:K33) -> 3627 | L34: =SUM(L2:L33) -> 558
A36: Rule: a campaign is NEW if its name carries 'Oct26' (the new Oct-2026 structure: 'ABO | ... | Oct26' in the Kustard ad account and 'EBG - In House | ... | Oct26' in the In-House ad account). All other campaigns are OLD. Change column B and press Data > Refresh All. EBG - In House campaigns have CRM leads but NO Meta spend in the exports provided, so their cost is shown as n/a.

Sheet Fact_Data
A1: Record Type | B1: Campaign Type | C1: Campaign | D1: Ad Set | E1: Ad | F1: CRM Brand | G1: Lead Status | H1: Lead Quality | I1: Lead Month | J1: Lead Week | K1: Team Manager | L1: Lead Source | M1: Attribution Method | N1: Lead ID | O1: Lead Count | P1: Quality Count | Q1: Contacted Count | R1: Lost Count | S1: Calls Count | T1: Connected Calls | U1: Spend INR | V1: Impressions | W1: Link Clicks | X1: Meta Results Count | Y1: Costed Lead Count | Z1: Costed Quality Count
