Workbook

Sheet Campaign Report
A1: DAEWOO × SHOOTORDER — CAMPAIGN, AD SET & AD-WISE PERFORMANCE REPORT
A2: MTD: 01 Oct 2026 – 28 Oct 2026 | FTD: 28 Oct 2026 | Currency: INR | Attribution: LeadChain (Meta raw Lead Ads export) — ground-truth Ad / Ad Set / Campaign join
A4: OCTOBER 2026 — PERFORMANCE SNAPSHOT (MTD 1–28 Oct · FTD 28 Oct)
A5: MTD SPEND | E5: MTD LEADS / RESULTS (META) | I5: BLENDED CPL (per CRM Lead) | M5: MTD IMPRESSIONS | Q5: MTD REACH | T5: MTD CTR | W5: MTD CPQL
A6: ="₹"&TEXT($J$30,"#,##0") | E6: =$E$30 | I6: =IFERROR("₹"&TEXT($J$30/Data_CRM!$J$6,"#,##0"),"n/a") | M6: =TEXT($K$30,"#,##0") | Q6: =TEXT($L$30,"#,##0") | T6: =IFERROR(TEXT($T$30/$K$30,"0.00%"),"n/a") | W6: =IFERROR("₹"&TEXT($J$30/$P$30,"#,##0"),"n/a")
A8: TOTAL CRM LEADS (MTD) | E8: QUALIFIED LEADS (CRM, MTD) | I8: MEETINGS SCHEDULED (total) | M8: FTD (28 OCT) — CRM LEADS | T8: UNIQUE LEADS (MeetingLeads file)
A9: =Data_CRM!$J$6 | E9: =SUM(Data_CRM!$F$2:$F$1694) | I9: =Data_MeetingScheduled!$J$2 | M9: =COUNTIFS(Data_CRM!$A$2:$A$1694,">="&Data_CRM!$J$4,Data_CRM!$A$2:$A$1694,"<="&Data_CRM!$J$5) | T9: 51
A11: ℹ DATA NOTES
A19: 1. CAMPAIGN-WISE PERFORMANCE — MTD (1 Oct – 28 Oct 2026)
A20: Reporting starts | B20: Reporting ends | C20: Campaign name | D20: Campaign delivery | E20: Results | F20: Result indicator | G20: Cost per result | H20: Ad set budget | I20: Ad set budget type | J20: Amount spent (INR) | K20: Impressions | L20: Reach | M20: Ends | N20: Attribution setting | O20: CRM Leads (LeadChain) | P20: Qualified Leads | Q20: Qualified Lead % | R20: Meetings Scheduled | S20: Meeting Scheduled % | T20: Link Clicks | U20: CTR | V20: CTR % | W20: CPQL | X20: CPQL %
A21: =INDEX(Data_Campaigns!$A$2:$A$15,MATCH($C21,Data_Campaigns!$C$2:$C$15,0)) | B21: =INDEX(Data_Campaigns!$B$2:$B$15,MATCH($C21,Data_Campaigns!$C$2:$C$15,0)) | C21: Andromeda_CBO_Signature Store_FICO_Daewoo_SO | D21: =INDEX(Data_Campaigns!$D$2:$D$15,MATCH($C21,Data_Campaigns!$C$2:$C$15,0)) | E21: =IF(INDEX(Data_Campaigns!$E$2:$E$15,MATCH($C21,Data_Campaigns!$C$2:$C$15,0))=0,"",INDEX(Data_Campaigns!$E$2:$E$15,MATCH($C21,Data_Campaigns!$C$2:$C$15,0))) | F21: =INDEX(Data_Campaigns!$F$2:$F$15,MATCH($C21,Data_Campaigns!$C$2:$C$15,0)) | G21: =IFERROR(IF($E21="","n/a",$J21/$E21),"n/a") | H21: =INDEX(Data_Campaigns!$H$2:$H$15,MATCH($C21,Data_Campaigns!$C$2:$C$15,0)) | I21: =INDEX(Data_Campaigns!$I$2:$I$15,MATCH($C21,Data_Campaigns!$C$2:$C$15,0)) | J21: =INDEX(Data_Campaigns!$J$2:$J$15,MATCH($C21,Data_Campaigns!$C$2:$C$15,0)) | K21: =INDEX(Data_Campaigns!$K$2:$K$15,MATCH($C21,Data_Campaigns!$C$2:$C$15,0)) | L21: =INDEX(Data_Campaigns!$L$2:$L$15,MATCH($C21,Data_Campaigns!$C$2:$C$15,0)) | M21: =INDEX(Data_Campaigns!$M$2:$M$15,MATCH($C21,Data_Campaigns!$C$2:$C$15,0)) | N21: =INDEX(Data_Campaigns!$N$2:$N$15,MATCH($C21,Data_Campaigns!$C$2:$C$15,0)) | O21: =COUNTIFS(Data_CRM!$B$2:$B$1694,$C21,Data_CRM!$A$2:$A$1694,">="&Data_CRM!$J$2,Data_CRM!$A$2:$A$1694,"<="&Data_CRM!$J$3) | P21: =SUMIFS(Data_CRM!$F$2:$F$1694,Data_CRM!$B$2:$B$1694,$C21,Data_CRM!$A$2:$A$1694,">="&Data_CRM!$J$2,Data_CRM!$A$2:$A$1694,"<="&Data_CRM!$J$3) | Q21: =IFERROR(IF($O21=0,"n/a",$P21/$O21),"n/a") | R21: =COUNTIF(Data_MeetingScheduled!$C$2:$C$200,$C21) | S21: =IFERROR(IF($O21=0,"n/a",$R21/$O21),"n/a") | T21: =INDEX(Data_Campaigns!$O$2:$O$15,MATCH($C21,Data_Campaigns!$C$2:$C$15,0)) | U21: =IFERROR($T21/$K21,"n/a") | V21: =IFERROR($T21/$K21,"n/a") | W21: =IFERROR($J21/$P21,"n/a") | X21: =IFERROR($P21/$O21,"n/a")
A22: =INDEX(Data_Campaigns!$A$2:$A$15,MATCH($C22,Data_Campaigns!$C$2:$C$15,0)) | B22: =INDEX(Data_Campaigns!$B$2:$B$15,MATCH($C22,Data_Campaigns!$C$2:$C$15,0)) | C22: META_CustomData_MOFU_STOCKIST_Leadgen | D22: =INDEX(Data_Campaigns!$D$2:$D$15,MATCH($C22,Data_Campaigns!$C$2:$C$15,0)) | E22: =IF(INDEX(Data_Campaigns!$E$2:$E$15,MATCH($C22,Data_Campaigns!$C$2:$C$15,0))=0,"",INDEX(Data_Campaigns!$E$2:$E$15,MATCH($C22,Data_Campaigns!$C$2:$C$15,0))) | F22: =INDEX(Data_Campaigns!$F$2:$F$15,MATCH($C22,Data_Campaigns!$C$2:$C$15,0)) | G22: =IFERROR(IF($E22="","n/a",$J22/$E22),"n/a") | H22: =INDEX(Data_Campaigns!$H$2:$H$15,MATCH($C22,Data_Campaigns!$C$2:$C$15,0)) | I22: =INDEX(Data_Campaigns!$I$2:$I$15,MATCH($C22,Data_Campaigns!$C$2:$C$15,0)) | J22: =INDEX(Data_Campaigns!$J$2:$J$15,MATCH($C22,Data_Campaigns!$C$2:$C$15,0)) | K22: =INDEX(Data_Campaigns!$K$2:$K$15,MATCH($C22,Data_Campaigns!$C$2:$C$15,0)) | L22: =INDEX(Data_Campaigns!$L$2:$L$15,MATCH($C22,Data_Campaigns!$C$2:$C$15,0)) | M22: =INDEX(Data_Campaigns!$M$2:$M$15,MATCH($C22,Data_Campaigns!$C$2:$C$15,0)) | N22: =INDEX(Data_Campaigns!$N$2:$N$15,MATCH($C22,Data_Campaigns!$C$2:$C$15,0)) | O22: =COUNTIFS(Data_CRM!$B$2:$B$1694,$C22,Data_CRM!$A$2:$A$1694,">="&Data_CRM!$J$2,Data_CRM!$A$2:$A$1694,"<="&Data_CRM!$J$3) | P22: =SUMIFS(Data_CRM!$F$2:$F$1694,Data_CRM!$B$2:$B$1694,$C22,Data_CRM!$A$2:$A$1694,">="&Data_CRM!$J$2,Data_CRM!$A$2:$A$1694,"<="&Data_CRM!$J$3) | Q22: =IFERROR(IF($O22=0,"n/a",$P22/$O22),"n/a") | R22: =COUNTIF(Data_MeetingScheduled!$C$2:$C$200,$C22) | S22: =IFERROR(IF($O22=0,"n/a",$R22/$O22),"n/a") | T22: =INDEX(Data_Campaigns!$O$2:$O$15,MATCH($C22,Data_Campaigns!$C$2:$C$15,0)) | U22: =IFERROR($T22/$K22,"n/a") | V22: =IFERROR($T22/$K22,"n/a") | W22: =IFERROR($J22/$P22,"n/a") | X22: =IFERROR($P22/$O22,"n/a")
A23: =INDEX(Data_Campaigns!$A$2:$A$15,MATCH($C23,Data_Campaigns!$C$2:$C$15,0)) | B23: =INDEX(Data_Campaigns!$B$2:$B$15,MATCH($C23,Data_Campaigns!$C$2:$C$15,0)) | C23: Andromeda_ABO_Stockist_Daewoo_SO | D23: =INDEX(Data_Campaigns!$D$2:$D$15,MATCH($C23,Data_Campaigns!$C$2:$C$15,0)) | E23: =IF(INDEX(Data_Campaigns!$E$2:$E$15,MATCH($C23,Data_Campaigns!$C$2:$C$15,0))=0,"",INDEX(Data_Campaigns!$E$2:$E$15,MATCH($C23,Data_Campaigns!$C$2:$C$15,0))) | F23: =INDEX(Data_Campaigns!$F$2:$F$15,MATCH($C23,Data_Campaigns!$C$2:$C$15,0)) | G23: =IFERROR(IF($E23="","n/a",$J23/$E23),"n/a") | H23: =INDEX(Data_Campaigns!$H$2:$H$15,MATCH($C23,Data_Campaigns!$C$2:$C$15,0)) | I23: =INDEX(Data_Campaigns!$I$2:$I$15,MATCH($C23,Data_Campaigns!$C$2:$C$15,0)) | J23: =INDEX(Data_Campaigns!$J$2:$J$15,MATCH($C23,Data_Campaigns!$C$2:$C$15,0)) | K23: =INDEX(Data_Campaigns!$K$2:$K$15,MATCH($C23,Data_Campaigns!$C$2:$C$15,0)) | L23: =INDEX(Data_Campaigns!$L$2:$L$15,MATCH($C23,Data_Campaigns!$C$2:$C$15,0)) | M23: =INDEX(Data_Campaigns!$M$2:$M$15,MATCH($C23,Data_Campaigns!$C$2:$C$15,0)) | N23: =INDEX(Data_Campaigns!$N$2:$N$15,MATCH($C23,Data_Campaigns!$C$2:$C$15,0)) | O23: =COUNTIFS(Data_CRM!$B$2:$B$1694,$C23,Data_CRM!$A$2:$A$1694,">="&Data_CRM!$J$2,Data_CRM!$A$2:$A$1694,"<="&Data_CRM!$J$3) | P23: =SUMIFS(Data_CRM!$F$2:$F$1694,Data_CRM!$B$2:$B$1694,$C23,Data_CRM!$A$2:$A$1694,">="&Data_CRM!$J$2,Data_CRM!$A$2:$A$1694,"<="&Data_CRM!$J$3) | Q23: =IFERROR(IF($O23=0,"n/a",$P23/$O23),"n/a") | R23: =COUNTIF(Data_MeetingScheduled!$C$2:$C$200,$C23) | S23: =IFERROR(IF($O23=0,"n/a",$R23/$O23),"n/a") | T23: =INDEX(Data_Campaigns!$O$2:$O$15,MATCH($C23,Data_Campaigns!$C$2:$C$15,0)) | U23: =IFERROR($T23/$K23,"n/a") | V23: =IFERROR($T23/$K23,"n/a") | W23: =IFERROR($J23/$P23,"n/a") | X23: =IFERROR($P23/$O23,"n/a")
A24: =INDEX(Data_Campaigns!$A$2:$A$15,MATCH($C24,Data_Campaigns!$C$2:$C$15,0)) | B24: =INDEX(Data_Campaigns!$B$2:$B$15,MATCH($C24,Data_Campaigns!$C$2:$C$15,0)) | C24: Andromeda_CBO__DDP_Daewoo_SO | D24: =INDEX(Data_Campaigns!$D$2:$D$15,MATCH($C24,Data_Campaigns!$C$2:$C$15,0)) | E24: =IF(INDEX(Data_Campaigns!$E$2:$E$15,MATCH($C24,Data_Campaigns!$C$2:$C$15,0))=0,"",INDEX(Data_Campaigns!$E$2:$E$15,MATCH($C24,Data_Campaigns!$C$2:$C$15,0))) | F24: =INDEX(Data_Campaigns!$F$2:$F$15,MATCH($C24,Data_Campaigns!$C$2:$C$15,0)) | G24: =IFERROR(IF($E24="","n/a",$J24/$E24),"n/a") | H24: =INDEX(Data_Campaigns!$H$2:$H$15,MATCH($C24,Data_Campaigns!$C$2:$C$15,0)) | I24: =INDEX(Data_Campaigns!$I$2:$I$15,MATCH($C24,Data_Campaigns!$C$2:$C$15,0)) | J24: =INDEX(Data_Campaigns!$J$2:$J$15,MATCH($C24,Data_Campaigns!$C$2:$C$15,0)) | K24: =INDEX(Data_Campaigns!$K$2:$K$15,MATCH($C24,Data_Campaigns!$C$2:$C$15,0)) | L24: =INDEX(Data_Campaigns!$L$2:$L$15,MATCH($C24,Data_Campaigns!$C$2:$C$15,0)) | M24: =INDEX(Data_Campaigns!$M$2:$M$15,MATCH($C24,Data_Campaigns!$C$2:$C$15,0)) | N24: =INDEX(Data_Campaigns!$N$2:$N$15,MATCH($C24,Data_Campaigns!$C$2:$C$15,0)) | O24: =COUNTIFS(Data_CRM!$B$2:$B$1694,$C24,Data_CRM!$A$2:$A$1694,">="&Data_CRM!$J$2,Data_CRM!$A$2:$A$1694,"<="&Data_CRM!$J$3) | P24: =SUMIFS(Data_CRM!$F$2:$F$1694,Data_CRM!$B$2:$B$1694,$C24,Data_CRM!$A$2:$A$1694,">="&Data_CRM!$J$2,Data_CRM!$A$2:$A$1694,"<="&Data_CRM!$J$3) | Q24: =IFERROR(IF($O24=0,"n/a",$P24/$O24),"n/a") | R24: =COUNTIF(Data_MeetingScheduled!$C$2:$C$200,$C24) | S24: =IFERROR(IF($O24=0,"n/a",$R24/$O24),"n/a") | T24: =INDEX(Data_Campaigns!$O$2:$O$15,MATCH($C24,Data_Campaigns!$C$2:$C$15,0)) | U24: =IFERROR($T24/$K24,"n/a") | V24: =IFERROR($T24/$K24,"n/a") | W24: =IFERROR($J24/$P24,"n/a") | X24: =IFERROR($P24/$O24,"n/a")
A25: =INDEX(Data_Campaigns!$A$2:$A$15,MATCH($C25,Data_Campaigns!$C$2:$C$15,0)) | B25: =INDEX(Data_Campaigns!$B$2:$B$15,MATCH($C25,Data_Campaigns!$C$2:$C$15,0)) | C25: META_CustomData_MOFU_Leadgen – DDP | D25: =INDEX(Data_Campaigns!$D$2:$D$15,MATCH($C25,Data_Campaigns!$C$2:$C$15,0)) | E25: =IF(INDEX(Data_Campaigns!$E$2:$E$15,MATCH($C25,Data_Campaigns!$C$2:$C$15,0))=0,"",INDEX(Data_Campaigns!$E$2:$E$15,MATCH($C25,Data_Campaigns!$C$2:$C$15,0))) | F25: =INDEX(Data_Campaigns!$F$2:$F$15,MATCH($C25,Data_Campaigns!$C$2:$C$15,0)) | G25: =IFERROR(IF($E25="","n/a",$J25/$E25),"n/a") | H25: =INDEX(Data_Campaigns!$H$2:$H$15,MATCH($C25,Data_Campaigns!$C$2:$C$15,0)) | I25: =INDEX(Data_Campaigns!$I$2:$I$15,MATCH($C25,Data_Campaigns!$C$2:$C$15,0)) | J25: =INDEX(Data_Campaigns!$J$2:$J$15,MATCH($C25,Data_Campaigns!$C$2:$C$15,0)) | K25: =INDEX(Data_Campaigns!$K$2:$K$15,MATCH($C25,Data_Campaigns!$C$2:$C$15,0)) | L25: =INDEX(Data_Campaigns!$L$2:$L$15,MATCH($C25,Data_Campaigns!$C$2:$C$15,0)) | M25: =INDEX(Data_Campaigns!$M$2:$M$15,MATCH($C25,Data_Campaigns!$C$2:$C$15,0)) | N25: =INDEX(Data_Campaigns!$N$2:$N$15,MATCH($C25,Data_Campaigns!$C$2:$C$15,0)) | O25: =COUNTIFS(Data_CRM!$B$2:$B$1694,$C25,Data_CRM!$A$2:$A$1694,">="&Data_CRM!$J$2,Data_CRM!$A$2:$A$1694,"<="&Data_CRM!$J$3) | P25: =SUMIFS(Data_CRM!$F$2:$F$1694,Data_CRM!$B$2:$B$1694,$C25,Data_CRM!$A$2:$A$1694,">="&Data_CRM!$J$2,Data_CRM!$A$2:$A$1694,"<="&Data_CRM!$J$3) | Q25: =IFERROR(IF($O25=0,"n/a",$P25/$O25),"n/a") | R25: =COUNTIF(Data_MeetingScheduled!$C$2:$C$200,$C25) | S25: =IFERROR(IF($O25=0,"n/a",$R25/$O25),"n/a") | T25: =INDEX(Data_Campaigns!$O$2:$O$15,MATCH($C25,Data_Campaigns!$C$2:$C$15,0)) | U25: =IFERROR($T25/$K25,"n/a") | V25: =IFERROR($T25/$K25,"n/a") | W25: =IFERROR($J25/$P25,"n/a") | X25: =IFERROR($P25/$O25,"n/a")
A26: =INDEX(Data_Campaigns!$A$2:$A$15,MATCH($C26,Data_Campaigns!$C$2:$C$15,0)) | B26: =INDEX(Data_Campaigns!$B$2:$B$15,MATCH($C26,Data_Campaigns!$C$2:$C$15,0)) | C26: META_CustomData_MOFU_Leadgen – Signature FICO | D26: =INDEX(Data_Campaigns!$D$2:$D$15,MATCH($C26,Data_Campaigns!$C$2:$C$15,0)) | E26: =IF(INDEX(Data_Campaigns!$E$2:$E$15,MATCH($C26,Data_Campaigns!$C$2:$C$15,0))=0,"",INDEX(Data_Campaigns!$E$2:$E$15,MATCH($C26,Data_Campaigns!$C$2:$C$15,0))) | F26: =INDEX(Data_Campaigns!$F$2:$F$15,MATCH($C26,Data_Campaigns!$C$2:$C$15,0)) | G26: =IFERROR(IF($E26="","n/a",$J26/$E26),"n/a") | H26: =INDEX(Data_Campaigns!$H$2:$H$15,MATCH($C26,Data_Campaigns!$C$2:$C$15,0)) | I26: =INDEX(Data_Campaigns!$I$2:$I$15,MATCH($C26,Data_Campaigns!$C$2:$C$15,0)) | J26: =INDEX(Data_Campaigns!$J$2:$J$15,MATCH($C26,Data_Campaigns!$C$2:$C$15,0)) | K26: =INDEX(Data_Campaigns!$K$2:$K$15,MATCH($C26,Data_Campaigns!$C$2:$C$15,0)) | L26: =INDEX(Data_Campaigns!$L$2:$L$15,MATCH($C26,Data_Campaigns!$C$2:$C$15,0)) | M26: =INDEX(Data_Campaigns!$M$2:$M$15,MATCH($C26,Data_Campaigns!$C$2:$C$15,0)) | N26: =INDEX(Data_Campaigns!$N$2:$N$15,MATCH($C26,Data_Campaigns!$C$2:$C$15,0)) | O26: =COUNTIFS(Data_CRM!$B$2:$B$1694,$C26,Data_CRM!$A$2:$A$1694,">="&Data_CRM!$J$2,Data_CRM!$A$2:$A$1694,"<="&Data_CRM!$J$3) | P26: =SUMIFS(Data_CRM!$F$2:$F$1694,Data_CRM!$B$2:$B$1694,$C26,Data_CRM!$A$2:$A$1694,">="&Data_CRM!$J$2,Data_CRM!$A$2:$A$1694,"<="&Data_CRM!$J$3) | Q26: =IFERROR(IF($O26=0,"n/a",$P26/$O26),"n/a") | R26: =COUNTIF(Data_MeetingScheduled!$C$2:$C$200,$C26) | S26: =IFERROR(IF($O26=0,"n/a",$R26/$O26),"n/a") | T26: =INDEX(Data_Campaigns!$O$2:$O$15,MATCH($C26,Data_Campaigns!$C$2:$C$15,0)) | U26: =IFERROR($T26/$K26,"n/a") | V26: =IFERROR($T26/$K26,"n/a") | W26: =IFERROR($J26/$P26,"n/a") | X26: =IFERROR($P26/$O26,"n/a")
A27: =INDEX(Data_Campaigns!$A$2:$A$15,MATCH($C27,Data_Campaigns!$C$2:$C$15,0)) | B27: =INDEX(Data_Campaigns!$B$2:$B$15,MATCH($C27,Data_Campaigns!$C$2:$C$15,0)) | C27: META_RMKT_Engage_ABO_SO | D27: =INDEX(Data_Campaigns!$D$2:$D$15,MATCH($C27,Data_Campaigns!$C$2:$C$15,0)) | E27: =IF(INDEX(Data_Campaigns!$E$2:$E$15,MATCH($C27,Data_Campaigns!$C$2:$C$15,0))=0,"",INDEX(Data_Campaigns!$E$2:$E$15,MATCH($C27,Data_Campaigns!$C$2:$C$15,0))) | F27: =INDEX(Data_Campaigns!$F$2:$F$15,MATCH($C27,Data_Campaigns!$C$2:$C$15,0)) | G27: =IFERROR(IF($E27="","n/a",$J27/$E27),"n/a") | H27: =INDEX(Data_Campaigns!$H$2:$H$15,MATCH($C27,Data_Campaigns!$C$2:$C$15,0)) | I27: =INDEX(Data_Campaigns!$I$2:$I$15,MATCH($C27,Data_Campaigns!$C$2:$C$15,0)) | J27: =INDEX(Data_Campaigns!$J$2:$J$15,MATCH($C27,Data_Campaigns!$C$2:$C$15,0)) | K27: =INDEX(Data_Campaigns!$K$2:$K$15,MATCH($C27,Data_Campaigns!$C$2:$C$15,0)) | L27: =INDEX(Data_Campaigns!$L$2:$L$15,MATCH($C27,Data_Campaigns!$C$2:$C$15,0)) | M27: =INDEX(Data_Campaigns!$M$2:$M$15,MATCH($C27,Data_Campaigns!$C$2:$C$15,0)) | N27: =INDEX(Data_Campaigns!$N$2:$N$15,MATCH($C27,Data_Campaigns!$C$2:$C$15,0)) | O27: =COUNTIFS(Data_CRM!$B$2:$B$1694,$C27,Data_CRM!$A$2:$A$1694,">="&Data_CRM!$J$2,Data_CRM!$A$2:$A$1694,"<="&Data_CRM!$J$3) | P27: =SUMIFS(Data_CRM!$F$2:$F$1694,Data_CRM!$B$2:$B$1694,$C27,Data_CRM!$A$2:$A$1694,">="&Data_CRM!$J$2,Data_CRM!$A$2:$A$1694,"<="&Data_CRM!$J$3) | Q27: =IFERROR(IF($O27=0,"n/a",$P27/$O27),"n/a") | R27: =COUNTIF(Data_MeetingScheduled!$C$2:$C$200,$C27) | S27: =IFERROR(IF($O27=0,"n/a",$R27/$O27),"n/a") | T27: =INDEX(Data_Campaigns!$O$2:$O$15,MATCH($C27,Data_Campaigns!$C$2:$C$15,0)) | U27: =IFERROR($T27/$K27,"n/a") | V27: =IFERROR($T27/$K27,"n/a") | W27: =IFERROR($J27/$P27,"n/a") | X27: =IFERROR($P27/$O27,"n/a")
A28: =INDEX(Data_Campaigns!$A$2:$A$15,MATCH($C28,Data_Campaigns!$C$2:$C$15,0)) | B28: =INDEX(Data_Campaigns!$B$2:$B$15,MATCH($C28,Data_Campaigns!$C$2:$C$15,0)) | C28: META_RMKT_Socials Pages_CBO_SO | D28: =INDEX(Data_Campaigns!$D$2:$D$15,MATCH($C28,Data_Campaigns!$C$2:$C$15,0)) | E28: =IF(INDEX(Data_Campaigns!$E$2:$E$15,MATCH($C28,Data_Campaigns!$C$2:$C$15,0))=0,"",INDEX(Data_Campaigns!$E$2:$E$15,MATCH($C28,Data_Campaigns!$C$2:$C$15,0))) | F28: =INDEX(Data_Campaigns!$F$2:$F$15,MATCH($C28,Data_Campaigns!$C$2:$C$15,0)) | G28: =IFERROR(IF($E28="","n/a",$J28/$E28),"n/a") | H28: =INDEX(Data_Campaigns!$H$2:$H$15,MATCH($C28,Data_Campaigns!$C$2:$C$15,0)) | I28: =INDEX(Data_Campaigns!$I$2:$I$15,MATCH($C28,Data_Campaigns!$C$2:$C$15,0)) | J28: =INDEX(Data_Campaigns!$J$2:$J$15,MATCH($C28,Data_Campaigns!$C$2:$C$15,0)) | K28: =INDEX(Data_Campaigns!$K$2:$K$15,MATCH($C28,Data_Campaigns!$C$2:$C$15,0)) | L28: =INDEX(Data_Campaigns!$L$2:$L$15,MATCH($C28,Data_Campaigns!$C$2:$C$15,0)) | M28: =INDEX(Data_Campaigns!$M$2:$M$15,MATCH($C28,Data_Campaigns!$C$2:$C$15,0)) | N28: =INDEX(Data_Campaigns!$N$2:$N$15,MATCH($C28,Data_Campaigns!$C$2:$C$15,0)) | O28: =COUNTIFS(Data_CRM!$B$2:$B$1694,$C28,Data_CRM!$A$2:$A$1694,">="&Data_CRM!$J$2,Data_CRM!$A$2:$A$1694,"<="&Data_CRM!$J$3) | P28: =SUMIFS(Data_CRM!$F$2:$F$1694,Data_CRM!$B$2:$B$1694,$C28,Data_CRM!$A$2:$A$1694,">="&Data_CRM!$J$2,Data_CRM!$A$2:$A$1694,"<="&Data_CRM!$J$3) | Q28: =IFERROR(IF($O28=0,"n/a",$P28/$O28),"n/a") | R28: =COUNTIF(Data_MeetingScheduled!$C$2:$C$200,$C28) | S28: =IFERROR(IF($O28=0,"n/a",$R28/$O28),"n/a") | T28: =INDEX(Data_Campaigns!$O$2:$O$15,MATCH($C28,Data_Campaigns!$C$2:$C$15,0)) | U28: =IFERROR($T28/$K28,"n/a") | V28: =IFERROR($T28/$K28,"n/a") | W28: =IFERROR($J28/$P28,"n/a") | X28: =IFERROR($P28/$O28,"n/a")
A29: =INDEX(Data_Campaigns!$A$2:$A$15,MATCH($C29,Data_Campaigns!$C$2:$C$15,0)) | B29: =INDEX(Data_Campaigns!$B$2:$B$15,MATCH($C29,Data_Campaigns!$C$2:$C$15,0)) | C29: CRM Custom List_CBO_SO | D29: =INDEX(Data_Campaigns!$D$2:$D$15,MATCH($C29,Data_Campaigns!$C$2:$C$15,0)) | E29: =IF(INDEX(Data_Campaigns!$E$2:$E$15,MATCH($C29,Data_Campaigns!$C$2:$C$15,0))=0,"",INDEX(Data_Campaigns!$E$2:$E$15,MATCH($C29,Data_Campaigns!$C$2:$C$15,0))) | F29: =INDEX(Data_Campaigns!$F$2:$F$15,MATCH($C29,Data_Campaigns!$C$2:$C$15,0)) | G29: =IFERROR(IF($E29="","n/a",$J29/$E29),"n/a") | H29: =INDEX(Data_Campaigns!$H$2:$H$15,MATCH($C29,Data_Campaigns!$C$2:$C$15,0)) | I29: =INDEX(Data_Campaigns!$I$2:$I$15,MATCH($C29,Data_Campaigns!$C$2:$C$15,0)) | J29: =INDEX(Data_Campaigns!$J$2:$J$15,MATCH($C29,Data_Campaigns!$C$2:$C$15,0)) | K29: =INDEX(Data_Campaigns!$K$2:$K$15,MATCH($C29,Data_Campaigns!$C$2:$C$15,0)) | L29: =INDEX(Data_Campaigns!$L$2:$L$15,MATCH($C29,Data_Campaigns!$C$2:$C$15,0)) | M29: =INDEX(Data_Campaigns!$M$2:$M$15,MATCH($C29,Data_Campaigns!$C$2:$C$15,0)) | N29: =INDEX(Data_Campaigns!$N$2:$N$15,MATCH($C29,Data_Campaigns!$C$2:$C$15,0)) | O29: =COUNTIFS(Data_CRM!$B$2:$B$1694,$C29,Data_CRM!$A$2:$A$1694,">="&Data_CRM!$J$2,Data_CRM!$A$2:$A$1694,"<="&Data_CRM!$J$3) | P29: =SUMIFS(Data_CRM!$F$2:$F$1694,Data_CRM!$B$2:$B$1694,$C29,Data_CRM!$A$2:$A$1694,">="&Data_CRM!$J$2,Data_CRM!$A$2:$A$1694,"<="&Data_CRM!$J$3) | Q29: =IFERROR(IF($O29=0,"n/a",$P29/$O29),"n/a") | R29: =COUNTIF(Data_MeetingScheduled!$C$2:$C$200,$C29) | S29: =IFERROR(IF($O29=0,"n/a",$R29/$O29),"n/a") | T29: =INDEX(Data_Campaigns!$O$2:$O$15,MATCH($C29,Data_Campaigns!$C$2:$C$15,0)) | U29: =IFERROR($T29/$K29,"n/a") | V29: =IFERROR($T29/$K29,"n/a") | W29: =IFERROR($J29/$P29,"n/a") | X29: =IFERROR($P29/$O29,"n/a")
C30: TOTAL / BLENDED AVERAGE | E30: =SUM(E21:E29) | G30: =IFERROR($J30/$E30,"n/a") | J30: =SUM(J21:J29) | K30: =SUM(K21:K29) | L30: =SUM(L21:L29) | O30: =SUM(O21:O29) | P30: =SUM(P21:P29) | Q30: =IFERROR($P30/$O30,"n/a") | R30: =SUM(R21:R29) | S30: =IFERROR($R30/$O30,"n/a") | T30: =SUM(T21:T29) | U30: =IFERROR($T30/$K30,"n/a") | V30: =IFERROR($T30/$K30,"n/a") | W30: =IFERROR($J30/$P30,"n/a") | X30: =IFERROR($P30/$O30,"n/a")
A31: Total Meeting Scheduled — LeadModule + MeetingDetails, 1–28 Oct 2026, deduplicated by email (see Data Notes) | R31: =Data_MeetingScheduled!$J$2
A35: 2. CAMPAIGN-WISE PERFORMANCE — FTD 28 Oct 2026 (CRM lead data, LeadChain-mapped)
A37: Campaign name | B37: CRM Leads (FTD) | C37: Qualified Leads (FTD) | D37: Qualified Lead % (FTD) | E37: Meetings Scheduled (FTD) | F37: Meeting Scheduled % (FTD)
A38: Andromeda_CBO_Signature Store_FICO_Daewoo_SO | B38: =COUNTIFS(Data_CRM!$B$2:$B$1694,$A38,Data_CRM!$A$2:$A$1694,">="&Data_CRM!$J$4,Data_CRM!$A$2:$A$1694,"<="&Data_CRM!$J$5) | C38: =SUMIFS(Data_CRM!$F$2:$F$1694,Data_CRM!$B$2:$B$1694,$A38,Data_CRM!$A$2:$A$1694,">="&Data_CRM!$J$4,Data_CRM!$A$2:$A$1694,"<="&Data_CRM!$J$5) | D38: =IFERROR(IF($B38=0,"n/a",$C38/$B38),"n/a") | E38: =COUNTIFS(Data_MeetingScheduled!$C$2:$C$200,$A38,Data_MeetingScheduled!$G$2:$G$200,">="&Data_CRM!$J$4,Data_MeetingScheduled!$G$2:$G$200,"<="&Data_CRM!$J$5) | F38: =IFERROR(IF($B38=0,"n/a",$E38/$B38),"n/a")
A39: META_CustomData_MOFU_STOCKIST_Leadgen | B39: =COUNTIFS(Data_CRM!$B$2:$B$1694,$A39,Data_CRM!$A$2:$A$1694,">="&Data_CRM!$J$4,Data_CRM!$A$2:$A$1694,"<="&Data_CRM!$J$5) | C39: =SUMIFS(Data_CRM!$F$2:$F$1694,Data_CRM!$B$2:$B$1694,$A39,Data_CRM!$A$2:$A$1694,">="&Data_CRM!$J$4,Data_CRM!$A$2:$A$1694,"<="&Data_CRM!$J$5) | D39: =IFERROR(IF($B39=0,"n/a",$C39/$B39),"n/a") | E39: =COUNTIFS(Data_MeetingScheduled!$C$2:$C$200,$A39,Data_MeetingScheduled!$G$2:$G$200,">="&Data_CRM!$J$4,Data_MeetingScheduled!$G$2:$G$200,"<="&Data_CRM!$J$5) | F39: =IFERROR(IF($B39=0,"n/a",$E39/$B39),"n/a")
A40: Andromeda_ABO_Stockist_Daewoo_SO | B40: =COUNTIFS(Data_CRM!$B$2:$B$1694,$A40,Data_CRM!$A$2:$A$1694,">="&Data_CRM!$J$4,Data_CRM!$A$2:$A$1694,"<="&Data_CRM!$J$5) | C40: =SUMIFS(Data_CRM!$F$2:$F$1694,Data_CRM!$B$2:$B$1694,$A40,Data_CRM!$A$2:$A$1694,">="&Data_CRM!$J$4,Data_CRM!$A$2:$A$1694,"<="&Data_CRM!$J$5) | D40: =IFERROR(IF($B40=0,"n/a",$C40/$B40),"n/a") | E40: =COUNTIFS(Data_MeetingScheduled!$C$2:$C$200,$A40,Data_MeetingScheduled!$G$2:$G$200,">="&Data_CRM!$J$4,Data_MeetingScheduled!$G$2:$G$200,"<="&Data_CRM!$J$5) | F40: =IFERROR(IF($B40=0,"n/a",$E40/$B40),"n/a")
A41: Andromeda_CBO__DDP_Daewoo_SO | B41: =COUNTIFS(Data_CRM!$B$2:$B$1694,$A41,Data_CRM!$A$2:$A$1694,">="&Data_CRM!$J$4,Data_CRM!$A$2:$A$1694,"<="&Data_CRM!$J$5) | C41: =SUMIFS(Data_CRM!$F$2:$F$1694,Data_CRM!$B$2:$B$1694,$A41,Data_CRM!$A$2:$A$1694,">="&Data_CRM!$J$4,Data_CRM!$A$2:$A$1694,"<="&Data_CRM!$J$5) | D41: =IFERROR(IF($B41=0,"n/a",$C41/$B41),"n/a") | E41: =COUNTIFS(Data_MeetingScheduled!$C$2:$C$200,$A41,Data_MeetingScheduled!$G$2:$G$200,">="&Data_CRM!$J$4,Data_MeetingScheduled!$G$2:$G$200,"<="&Data_CRM!$J$5) | F41: =IFERROR(IF($B41=0,"n/a",$E41/$B41),"n/a")
A42: META_CustomData_MOFU_Leadgen – DDP | B42: =COUNTIFS(Data_CRM!$B$2:$B$1694,$A42,Data_CRM!$A$2:$A$1694,">="&Data_CRM!$J$4,Data_CRM!$A$2:$A$1694,"<="&Data_CRM!$J$5) | C42: =SUMIFS(Data_CRM!$F$2:$F$1694,Data_CRM!$B$2:$B$1694,$A42,Data_CRM!$A$2:$A$1694,">="&Data_CRM!$J$4,Data_CRM!$A$2:$A$1694,"<="&Data_CRM!$J$5) | D42: =IFERROR(IF($B42=0,"n/a",$C42/$B42),"n/a") | E42: =COUNTIFS(Data_MeetingScheduled!$C$2:$C$200,$A42,Data_MeetingScheduled!$G$2:$G$200,">="&Data_CRM!$J$4,Data_MeetingScheduled!$G$2:$G$200,"<="&Data_CRM!$J$5) | F42: =IFERROR(IF($B42=0,"n/a",$E42/$B42),"n/a")
A43: META_CustomData_MOFU_Leadgen – Signature FICO | B43: =COUNTIFS(Data_CRM!$B$2:$B$1694,$A43,Data_CRM!$A$2:$A$1694,">="&Data_CRM!$J$4,Data_CRM!$A$2:$A$1694,"<="&Data_CRM!$J$5) | C43: =SUMIFS(Data_CRM!$F$2:$F$1694,Data_CRM!$B$2:$B$1694,$A43,Data_CRM!$A$2:$A$1694,">="&Data_CRM!$J$4,Data_CRM!$A$2:$A$1694,"<="&Data_CRM!$J$5) | D43: =IFERROR(IF($B43=0,"n/a",$C43/$B43),"n/a") | E43: =COUNTIFS(Data_MeetingScheduled!$C$2:$C$200,$A43,Data_MeetingScheduled!$G$2:$G$200,">="&Data_CRM!$J$4,Data_MeetingScheduled!$G$2:$G$200,"<="&Data_CRM!$J$5) | F43: =IFERROR(IF($B43=0,"n/a",$E43/$B43),"n/a")
A44: META_RMKT_Engage_ABO_SO | B44: =COUNTIFS(Data_CRM!$B$2:$B$1694,$A44,Data_CRM!$A$2:$A$1694,">="&Data_CRM!$J$4,Data_CRM!$A$2:$A$1694,"<="&Data_CRM!$J$5) | C44: =SUMIFS(Data_CRM!$F$2:$F$1694,Data_CRM!$B$2:$B$1694,$A44,Data_CRM!$A$2:$A$1694,">="&Data_CRM!$J$4,Data_CRM!$A$2:$A$1694,"<="&Data_CRM!$J$5) | D44: =IFERROR(IF($B44=0,"n/a",$C44/$B44),"n/a") | E44: =COUNTIFS(Data_MeetingScheduled!$C$2:$C$200,$A44,Data_MeetingScheduled!$G$2:$G$200,">="&Data_CRM!$J$4,Data_MeetingScheduled!$G$2:$G$200,"<="&Data_CRM!$J$5) | F44: =IFERROR(IF($B44=0,"n/a",$E44/$B44),"n/a")
A45: META_RMKT_Socials Pages_CBO_SO | B45: =COUNTIFS(Data_CRM!$B$2:$B$1694,$A45,Data_CRM!$A$2:$A$1694,">="&Data_CRM!$J$4,Data_CRM!$A$2:$A$1694,"<="&Data_CRM!$J$5) | C45: =SUMIFS(Data_CRM!$F$2:$F$1694,Data_CRM!$B$2:$B$1694,$A45,Data_CRM!$A$2:$A$1694,">="&Data_CRM!$J$4,Data_CRM!$A$2:$A$1694,"<="&Data_CRM!$J$5) | D45: =IFERROR(IF($B45=0,"n/a",$C45/$B45),"n/a") | E45: =COUNTIFS(Data_MeetingScheduled!$C$2:$C$200,$A45,Data_MeetingScheduled!$G$2:$G$200,">="&Data_CRM!$J$4,Data_MeetingScheduled!$G$2:$G$200,"<="&Data_CRM!$J$5) | F45: =IFERROR(IF($B45=0,"n/a",$E45/$B45),"n/a")
A46: CRM Custom List_CBO_SO | B46: =COUNTIFS(Data_CRM!$B$2:$B$1694,$A46,Data_CRM!$A$2:$A$1694,">="&Data_CRM!$J$4,Data_CRM!$A$2:$A$1694,"<="&Data_CRM!$J$5) | C46: =SUMIFS(Data_CRM!$F$2:$F$1694,Data_CRM!$B$2:$B$1694,$A46,Data_CRM!$A$2:$A$1694,">="&Data_CRM!$J$4,Data_CRM!$A$2:$A$1694,"<="&Data_CRM!$J$5) | D46: =IFERROR(IF($B46=0,"n/a",$C46/$B46),"n/a") | E46: =COUNTIFS(Data_MeetingScheduled!$C$2:$C$200,$A46,Data_MeetingScheduled!$G$2:$G$200,">="&Data_CRM!$J$4,Data_MeetingScheduled!$G$2:$G$200,"<="&Data_CRM!$J$5) | F46: =IFERROR(IF($B46=0,"n/a",$E46/$B46),"n/a")
A47: Not mapped to a campaign (no LeadChain match) | B47: =COUNTIFS(Data_CRM!$B$2:$B$1694,"Not mapped to a campaign",Data_CRM!$A$2:$A$1694,">="&Data_CRM!$J$4,Data_CRM!$A$2:$A$1694,"<="&Data_CRM!$J$5) | C47: =SUMIFS(Data_CRM!$F$2:$F$1694,Data_CRM!$B$2:$B$1694,"Not mapped to a campaign",Data_CRM!$A$2:$A$1694,">="&Data_CRM!$J$4,Data_CRM!$A$2:$A$1694,"<="&Data_CRM!$J$5) | D47: =IFERROR(IF($B47=0,"n/a",$C47/$B47),"n/a") | E47: =COUNTIFS(Data_MeetingScheduled!$C$2:$C$200,"Not mapped to a campaign",Data_MeetingScheduled!$G$2:$G$200,">="&Data_CRM!$J$4,Data_MeetingScheduled!$G$2:$G$200,"<="&Data_CRM!$J$5) | F47: =IFERROR(IF($B47=0,"n/a",$E47/$B47),"n/a")
A48: TOTAL (FULL CRM EXPORT FOR THE FTD PERIOD) | B48: =COUNTIFS(Data_CRM!$A$2:$A$1694,">="&Data_CRM!$J$4,Data_CRM!$A$2:$A$1694,"<="&Data_CRM!$J$5) | C48: =SUMIFS(Data_CRM!$F$2:$F$1694,Data_CRM!$A$2:$A$1694,">="&Data_CRM!$J$4,Data_CRM!$A$2:$A$1694,"<="&Data_CRM!$J$5) | D48: =IFERROR($C48/$B48,"n/a") | E48: =COUNTIFS(Data_MeetingScheduled!$G$2:$G$200,">="&Data_CRM!$J$4,Data_MeetingScheduled!$G$2:$G$200,"<="&Data_CRM!$J$5) | F48: =IFERROR($E48/$B48,"n/a")
A50: 3. AD SET-WISE PERFORMANCE — MTD (1 Oct – 28 Oct 2026), grouped by parent campaign
A51: Parent Campaign | B51: Ad set name | C51: Ad set delivery | D51: Results | E51: Result indicator | F51: Cost per result | G51: Ad set budget | H51: Ad set budget type | I51: Amount spent (INR) | J51: Impressions | K51: Reach | L51: Ends | M51: Starts | N51: Attribution setting | O51: Bid type | P51: % of Campaign Spend | Q51: % of Campaign Results | R51: Meetings Scheduled | S51: Meeting Scheduled % | T51: Link Clicks | U51: CTR | V51: CTR % | W51: CRM Leads (LeadChain) | X51: Qualified Leads | Y51: CPQL | Z51: CPQL %
A52: Andromeda_CBO_Signature Store_FICO_Daewoo_SO | B52: Business Interest Signature Stores_FICO | C52: active | D52: 351 | E52: actions:leadgen.other | F52: =IFERROR($I52/$D52,"n/a") | G52: Using campaign budget | H52: 0 | I52: 229018.3 | J52: 1577811 | K52: 790322 | L52: Ongoing | M52: 2026-02-27 | N52: 7-day click or 1-day view | O52: ABSOLUTE_OCPM | P52: =IFERROR($I52/INDEX($J$21:$J$29,MATCH($A52,$C$21:$C$29,0)),"n/a") | Q52: =IFERROR(IF(INDEX($E$21:$E$29,MATCH($A52,$C$21:$C$29,0))="","n/a",$D52/INDEX($E$21:$E$29,MATCH($A52,$C$21:$C$29,0))),"n/a") | R52: =COUNTIFS(Data_MeetingScheduled!$C$2:$C$200,$A52,Data_MeetingScheduled!$D$2:$D$200,$B52) | S52: =IFERROR($R52/Data_MeetingScheduled!$J$2,"n/a") | T52: 7499 | U52: =IFERROR($T52/$J52,"n/a") | V52: =IFERROR($T52/$J52,"n/a") | W52: =COUNTIFS(Data_CRM!$B$2:$B$1694,$A52,Data_CRM!$C$2:$C$1694,$B52) | X52: =COUNTIFS(Data_CRM!$B$2:$B$1694,$A52,Data_CRM!$C$2:$C$1694,$B52,Data_CRM!$F$2:$F$1694,1) | Y52: =IFERROR($I52/$X52,"n/a") | Z52: =IFERROR(IF($W52=0,"n/a",$X52/$W52),"n/a")
A53: Andromeda_CBO_Signature Store_FICO_Daewoo_SO | B53: HHI Pan India With Exclusions Signature Stores_FICO | C53: active | D53: 868 | E53: actions:leadgen.other | F53: =IFERROR($I53/$D53,"n/a") | G53: Using campaign budget | H53: 0 | I53: 443840.57 | J53: 2999156 | K53: 1180535 | L53: Ongoing | M53: 2026-10-17 | N53: 7-day click or 1-day view | O53: ABSOLUTE_OCPM | P53: =IFERROR($I53/INDEX($J$21:$J$29,MATCH($A53,$C$21:$C$29,0)),"n/a") | Q53: =IFERROR(IF(INDEX($E$21:$E$29,MATCH($A53,$C$21:$C$29,0))="","n/a",$D53/INDEX($E$21:$E$29,MATCH($A53,$C$21:$C$29,0))),"n/a") | R53: =COUNTIFS(Data_MeetingScheduled!$C$2:$C$200,$A53,Data_MeetingScheduled!$D$2:$D$200,$B53) | S53: =IFERROR($R53/Data_MeetingScheduled!$J$2,"n/a") | T53: 15324 | U53: =IFERROR($T53/$J53,"n/a") | V53: =IFERROR($T53/$J53,"n/a") | W53: =COUNTIFS(Data_CRM!$B$2:$B$1694,$A53,Data_CRM!$C$2:$C$1694,$B53) | X53: =COUNTIFS(Data_CRM!$B$2:$B$1694,$A53,Data_CRM!$C$2:$C$1694,$B53,Data_CRM!$F$2:$F$1694,1) | Y53: =IFERROR($I53/$X53,"n/a") | Z53: =IFERROR(IF($W53=0,"n/a",$X53/$W53),"n/a")
A54: Subtotal — Andromeda_CBO_Signature Store_FICO_Daewoo_SO | D54: =SUM(D52:D53) | F54: =IFERROR($I54/$D54,"n/a") | I54: =SUM(I52:I53) | J54: =SUM(J52:J53) | K54: =SUM(K52:K53) | P54: =SUM(P52:P53) | R54: =SUM(R52:R53) | S54: =IFERROR($R54/Data_MeetingScheduled!$J$2,"n/a") | T54: =SUM(T52:T53) | U54: =IFERROR($T54/$J54,"n/a") | V54: =IFERROR($T54/$J54,"n/a") | W54: =SUM(W52:W53) | X54: =SUM(X52:X53) | Y54: =IFERROR($I54/$X54,"n/a") | Z54: =IFERROR(IF($W54=0,"n/a",$X54/$W54),"n/a")
A55: META_CustomData_MOFU_STOCKIST_Leadgen | B55: Client Custom Data_Stockist | C55: active | D55: 15 | E55: actions:leadgen.other | F55: =IFERROR($I55/$D55,"n/a") | G55: Using campaign budget | H55: 0 | I55: 7962.14 | J55: 6301 | K55: 2549 | L55: Ongoing | M55: 2026-03-11 | N55: 7-day click or 1-day view | O55: ABSOLUTE_OCPM | P55: =IFERROR($I55/INDEX($J$21:$J$29,MATCH($A55,$C$21:$C$29,0)),"n/a") | Q55: =IFERROR(IF(INDEX($E$21:$E$29,MATCH($A55,$C$21:$C$29,0))="","n/a",$D55/INDEX($E$21:$E$29,MATCH($A55,$C$21:$C$29,0))),"n/a") | R55: =COUNTIFS(Data_MeetingScheduled!$C$2:$C$200,$A55,Data_MeetingScheduled!$D$2:$D$200,$B55) | S55: =IFERROR($R55/Data_MeetingScheduled!$J$2,"n/a") | T55: 60 | U55: =IFERROR($T55/$J55,"n/a") | V55: =IFERROR($T55/$J55,"n/a") | W55: =COUNTIFS(Data_CRM!$B$2:$B$1694,$A55,Data_CRM!$C$2:$C$1694,$B55) | X55: =COUNTIFS(Data_CRM!$B$2:$B$1694,$A55,Data_CRM!$C$2:$C$1694,$B55,Data_CRM!$F$2:$F$1694,1) | Y55: =IFERROR($I55/$X55,"n/a") | Z55: =IFERROR(IF($W55=0,"n/a",$X55/$W55),"n/a")
...

Sheet Data_Campaigns
A1: Reporting starts | B1: Reporting ends | C1: Campaign name | D1: Campaign delivery | E1: Results | F1: Result indicator | G1: Cost per results | H1: Ad set budget | I1: Ad set budget type | J1: Amount spent (INR) | K1: Impressions | L1: Reach | M1: Ends | N1: Attribution setting | O1: Link clicks

Sheet Data_AdSets
A1: Reporting starts | B1: Reporting ends | C1: Ad set name | D1: Ad set delivery | E1: Results | F1: Result indicator | G1: Cost per results | H1: Ad set budget | I1: Ad set budget type | J1: Amount spent (INR) | K1: Impressions | L1: Reach | M1: Link clicks | N1: Ends | O1: Starts | P1: Attribution setting | Q1: Bid | R1: Bid type | S1: Last significant edit | T1: Parent Campaign

Sheet Data_Ads
A1: Reporting starts | B1: Reporting ends | C1: Ad name | D1: Ad delivery | E1: Results | F1: Result indicator | G1: Cost per results | H1: Ad set budget | I1: Ad set budget type | J1: Amount spent (INR) | K1: Impressions | L1: Reach | M1: Link clicks | N1: Ends | O1: Attribution setting | P1: Bid | Q1: Bid type | R1: Last significant edit | S1: Quality ranking | T1: Engagement rate ranking | U1: Conversion rate ranking | V1: Ad set name | W1: Parent Campaign | X1: Match Key

Sheet Data_CRM
A1: Lead Date | B1: Mapped Campaign (LeadChain) | C1: Mapped Ad Set (LeadChain) | D1: Mapped Ad (LeadChain) | E1: Lead Status | F1: Qualified (1/0) | G1: Meeting (1/0) | H1: Social Lead ID | I1: PARAMETERS

Sheet Data_MeetingScheduled
A1: Source File | B1: Email | C1: Mapped Campaign (LeadChain) | D1: Mapped Ad Set (LeadChain) | E1: Mapped Ad (LeadChain) | F1: Date / Created Time | G1: Meeting Date (value) | H1: Lead Status (source) | I1: PARAMETERS

Sheet Data_UnmappedMeetings
A1: Source File | B1: Email | C1: Date / Created Time | D1: Reason

Sheet Data_MeetingConducted
A1: Name | B1: Email | C1: Phone | D1: Mapped Campaign | E1: Mapped Ad Set | F1: Mapped Ad | G1: Created Time | H1: Team Head | I1: BDE | K1: NOTE: Not populated — no separate Meeting Conducted source this round. Under the reporting rule, Meeting Conducted and Meeting Follow-Up statuses are categorised as Meeting Scheduled (see Data_MeetingScheduled).
